Workbook

Sheet Participantes
A1: SIMULADO — Transcripción del lote 1 — participantes (datos de prueba; no son personas reales)
A2: Un código por persona (P01 a P25) sin relación con su nombre. El formulario sigue la rotación A–E y no se cambia. Edita solo las celdas amarillas. Marca «Transcrito» solo cuando termines de pasar toda su hoja a la pestaña Respuestas.
A3: participant_code | B3: form | C3: Estado | D3: age_range | E3: vive_en_juliaca | F3: tramite_12m | G3: Consentimiento firmado | H3: Fecha de aplicación | I3: Situaciones del formulario | J3: Frases transcritas | K3: En blanco | L3: Alerta | M3: Observaciones
A4: P01 | B4: A | C4: Transcrito | D4: 30–44 | E4: Sí | F4: Sí | G4: Sí | H4: 46298 | I4: =COUNTIF(Respuestas!$A$4:$A$283,A4) -> 12 | J4: =SUMPRODUCT((Respuestas!$A$4:$A$283=A4)*(LEN(TRIM(Respuestas!$D$4:$D$283))>0)) -> 12 | K4: =IF(C4="Transcrito",I4-J4,"") -> 0 | L4: =IF(AND(C4="Transcrito",G4<>"Sí"),"Falta consentimiento",IF(AND(C4="Transcrito",J4=0),"Sin frases",IF(AND(C4="Transcrito",D4=""),"Falta rango de edad",""))) | M4: Dato sintético de prueba
A5: P02 | B5: B | C5: Transcrito | D5: 45–59 | E5: Sí | F5: Sí | G5: Sí | H5: 46298 | I5: =COUNTIF(Respuestas!$A$4:$A$283,A5) -> 11 | J5: =SUMPRODUCT((Respuestas!$A$4:$A$283=A5)*(LEN(TRIM(Respuestas!$D$4:$D$283))>0)) -> 10 | K5: =IF(C5="Transcrito",I5-J5,"") -> 1 | L5: =IF(AND(C5="Transcrito",G5<>"Sí"),"Falta consentimiento",IF(AND(C5="Transcrito",J5=0),"Sin frases",IF(AND(C5="Transcrito",D5=""),"Falta rango de edad",""))) | M5: Dato sintético de prueba
A6: P03 | B6: C | C6: Transcrito | D6: 30–44 | E6: Sí | F6: Sí | G6: Sí | H6: 46298 | I6: =COUNTIF(Respuestas!$A$4:$A$283,A6) -> 11 | J6: =SUMPRODUCT((Respuestas!$A$4:$A$283=A6)*(LEN(TRIM(Respuestas!$D$4:$D$283))>0)) -> 10 | K6: =IF(C6="Transcrito",I6-J6,"") -> 1 | L6: =IF(AND(C6="Transcrito",G6<>"Sí"),"Falta consentimiento",IF(AND(C6="Transcrito",J6=0),"Sin frases",IF(AND(C6="Transcrito",D6=""),"Falta rango de edad",""))) | M6: Dato sintético de prueba
A7: P04 | B7: D | C7: Transcrito | D7: 18–29 | E7: Sí | F7: Sí | G7: Sí | H7: 46298 | I7: =COUNTIF(Respuestas!$A$4:$A$283,A7) -> 11 | J7: =SUMPRODUCT((Respuestas!$A$4:$A$283=A7)*(LEN(TRIM(Respuestas!$D$4:$D$283))>0)) -> 11 | K7: =IF(C7="Transcrito",I7-J7,"") -> 0 | L7: =IF(AND(C7="Transcrito",G7<>"Sí"),"Falta consentimiento",IF(AND(C7="Transcrito",J7=0),"Sin frases",IF(AND(C7="Transcrito",D7=""),"Falta rango de edad",""))) | M7: Dato sintético de prueba
A8: P05 | B8: E | C8: Transcrito | D8: 18–29 | E8: Sí | F8: Sí | G8: Sí | H8: 46298 | I8: =COUNTIF(Respuestas!$A$4:$A$283,A8) -> 11 | J8: =SUMPRODUCT((Respuestas!$A$4:$A$283=A8)*(LEN(TRIM(Respuestas!$D$4:$D$283))>0)) -> 11 | K8: =IF(C8="Transcrito",I8-J8,"") -> 0 | L8: =IF(AND(C8="Transcrito",G8<>"Sí"),"Falta consentimiento",IF(AND(C8="Transcrito",J8=0),"Sin frases",IF(AND(C8="Transcrito",D8=""),"Falta rango de edad",""))) | M8: Dato sintético de prueba
A9: P06 | B9: A | C9: Transcrito | D9: 18–29 | E9: Sí | F9: Sí | G9: Sí | H9: 46298 | I9: =COUNTIF(Respuestas!$A$4:$A$283,A9) -> 12 | J9: =SUMPRODUCT((Respuestas!$A$4:$A$283=A9)*(LEN(TRIM(Respuestas!$D$4:$D$283))>0)) -> 12 | K9: =IF(C9="Transcrito",I9-J9,"") -> 0 | L9: =IF(AND(C9="Transcrito",G9<>"Sí"),"Falta consentimiento",IF(AND(C9="Transcrito",J9=0),"Sin frases",IF(AND(C9="Transcrito",D9=""),"Falta rango de edad",""))) | M9: Dato sintético de prueba
A10: P07 | B10: B | C10: Transcrito | D10: 30–44 | E10: Sí | F10: No | G10: Sí | H10: 46298 | I10: =COUNTIF(Respuestas!$A$4:$A$283,A10) -> 11 | J10: =SUMPRODUCT((Respuestas!$A$4:$A$283=A10)*(LEN(TRIM(Respuestas!$D$4:$D$283))>0)) -> 11 | K10: =IF(C10="Transcrito",I10-J10,"") -> 0 | L10: =IF(AND(C10="Transcrito",G10<>"Sí"),"Falta consentimiento",IF(AND(C10="Transcrito",J10=0),"Sin frases",IF(AND(C10="Transcrito",D10=""),"Falta rango de edad",""))) | M10: Dato sintético de prueba
A11: P08 | B11: C | C11: Transcrito | D11: 18–29 | E11: Sí | F11: Sí | G11: Sí | H11: 46298 | I11: =COUNTIF(Respuestas!$A$4:$A$283,A11) -> 11 | J11: =SUMPRODUCT((Respuestas!$A$4:$A$283=A11)*(LEN(TRIM(Respuestas!$D$4:$D$283))>0)) -> 11 | K11: =IF(C11="Transcrito",I11-J11,"") -> 0 | L11: =IF(AND(C11="Transcrito",G11<>"Sí"),"Falta consentimiento",IF(AND(C11="Transcrito",J11=0),"Sin frases",IF(AND(C11="Transcrito",D11=""),"Falta rango de edad",""))) | M11: Dato sintético de prueba
A12: P09 | B12: D | C12: Transcrito | D12: 30–44 | E12: No | F12: No | G12: Sí | H12: 46298 | I12: =COUNTIF(Respuestas!$A$4:$A$283,A12) -> 11 | J12: =SUMPRODUCT((Respuestas!$A$4:$A$283=A12)*(LEN(TRIM(Respuestas!$D$4:$D$283))>0)) -> 11 | K12: =IF(C12="Transcrito",I12-J12,"") -> 0 | L12: =IF(AND(C12="Transcrito",G12<>"Sí"),"Falta consentimiento",IF(AND(C12="Transcrito",J12=0),"Sin frases",IF(AND(C12="Transcrito",D12=""),"Falta rango de edad",""))) | M12: Dato sintético de prueba
A13: P10 | B13: E | C13: Transcrito | D13: 30–44 | E13: Sí | F13: Sí | G13: Sí | H13: 46298 | I13: =COUNTIF(Respuestas!$A$4:$A$283,A13) -> 11 | J13: =SUMPRODUCT((Respuestas!$A$4:$A$283=A13)*(LEN(TRIM(Respuestas!$D$4:$D$283))>0)) -> 11 | K13: =IF(C13="Transcrito",I13-J13,"") -> 0 | L13: =IF(AND(C13="Transcrito",G13<>"Sí"),"Falta consentimiento",IF(AND(C13="Transcrito",J13=0),"Sin frases",IF(AND(C13="Transcrito",D13=""),"Falta rango de edad",""))) | M13: Dato sintético de prueba
A14: P11 | B14: A | C14: Transcrito | D14: 60 a más | E14: Sí | F14: Sí | G14: Sí | H14: 46298 | I14: =COUNTIF(Respuestas!$A$4:$A$283,A14) -> 12 | J14: =SUMPRODUCT((Respuestas!$A$4:$A$283=A14)*(LEN(TRIM(Respuestas!$D$4:$D$283))>0)) -> 12 | K14: =IF(C14="Transcrito",I14-J14,"") -> 0 | L14: =IF(AND(C14="Transcrito",G14<>"Sí"),"Falta consentimiento",IF(AND(C14="Transcrito",J14=0),"Sin frases",IF(AND(C14="Transcrito",D14=""),"Falta rango de edad",""))) | M14: Dato sintético de prueba
A15: P12 | B15: B | C15: Transcrito | D15: 45–59 | E15: Sí | F15: Sí | G15: Sí | H15: 46298 | I15: =COUNTIF(Respuestas!$A$4:$A$283,A15) -> 11 | J15: =SUMPRODUCT((Respuestas!$A$4:$A$283=A15)*(LEN(TRIM(Respuestas!$D$4:$D$283))>0)) -> 11 | K15: =IF(C15="Transcrito",I15-J15,"") -> 0 | L15: =IF(AND(C15="Transcrito",G15<>"Sí"),"Falta consentimiento",IF(AND(C15="Transcrito",J15=0),"Sin frases",IF(AND(C15="Transcrito",D15=""),"Falta rango de edad",""))) | M15: Dato sintético de prueba
... A28: P25 | B28: E | C28: Transcrito | D28: 45–59 | E28: Sí | F28: Sí | G28: Sí | H28: 46298 | I28: =COUNTIF(Respuestas!$A$4:$A$283,A28) -> 11 | J28: =SUMPRODUCT((Respuestas!$A$4:$A$283=A28)*(LEN(TRIM(Respuestas!$D$4:$D$283))>0)) -> 11 | K28: =IF(C28="Transcrito",I28-J28,"") -> 0 | L28: =IF(AND(C28="Transcrito",G28<>"Sí"),"Falta consentimiento",IF(AND(C28="Transcrito",J28=0),"Sin frases",IF(AND(C28="Transcrito",D28=""),"Falta rango de edad",""))) | M28: Dato sintético de prueba

Sheet Respuestas
A1: SIMULADO — Transcripción del lote 1 — respuestas (datos de prueba; no son personas reales)
A2: Escribe en la columna D (amarilla) la frase tal cual la escribió la persona, sin corregir ortografía ni abreviaturas (ejemplo: «cuanto cuesta la licencia pa mi tienda»). Déjala vacía si la persona no respondió esa situación. No escribas nombres, DNI ni teléfonos. Las columnas A–C ya están llenas: no las cambies.
A3: participant_code | B3: form | C3: scenario_id | D3: text | E3: Situación (referencia) | F3: Intención esperada (referencia) | G3: Largo | H3: Alerta
A4: P01 | B4: A | C4: S01 | D4: hola q papeles necesito para abrir mi tienda | E4: Vas a abrir una tiendita en tu barrio y no sabes qué papeles te van a pedir en la municipalidad para poder atender legalmente. | F4: licencia_funcionamiento_requisitos | G4: =LEN(TRIM(D4)) -> 44 | H4: =IF(LEN(TRIM(D4))=0,"",IF(AND(LEN(TRIM(D4))<3,ISNA(MATCH(F4,Parametros!$K$4:$K$8,0))),"Muy corta",IF(OR(ISNUMBER(SEARCH("@",D4)),ISNUMBER(SEARCH("http",D4)),ISNUMBER(SEARCH("www.",D4))),"Posible dato personal","")))
A5: P01 | B5: A | C5: S06 | D5: mi licencia ya vencio como la renuevo | E5: El permiso de funcionamiento de tu negocio ya se venció y quieres saber qué tienes que hacer para dejarlo vigente otra vez. | F5: renovacion_licencia | G5: =LEN(TRIM(D5)) -> 37 | H5: =IF(LEN(TRIM(D5))=0,"",IF(AND(LEN(TRIM(D5))<3,ISNA(MATCH(F5,Parametros!$K$4:$K$8,0))),"Muy corta",IF(OR(ISNUMBER(SEARCH("@",D5)),ISNUMBER(SEARCH("http",D5)),ISNUMBER(SEARCH("www.",D5))),"Posible dato personal","")))
A6: P01 | B6: A | C6: S11 | D6: puedo pagar mi deuda de impuestos en cuotas | E6: Debes varios años de impuestos municipales y no puedes pagar todo de golpe; quieres saber si puedes pagarlo poco a poco. | F6: fraccionamiento_deuda | G6: =LEN(TRIM(D6)) -> 43 | H6: =IF(LEN(TRIM(D6))=0,"",IF(AND(LEN(TRIM(D6))<3,ISNA(MATCH(F6,Parametros!$K$4:$K$8,0))),"Muy corta",IF(OR(ISNUMBER(SEARCH("@",D6)),ISNUMBER(SEARCH("http",D6)),ISNUMBER(SEARCH("www.",D6))),"Posible dato personal","")))
A7: P01 | B7: A | C7: S16 | D7: perdi la copia de mi documento q presente como la recupero | E7: Necesitas una copia sellada de un documento que presentaste antes y ya no la tienes. | F7: copia_documento | G7: =LEN(TRIM(D7)) -> 58 | H7: =IF(LEN(TRIM(D7))=0,"",IF(AND(LEN(TRIM(D7))<3,ISNA(MATCH(F7,Parametros!$K$4:$K$8,0))),"Muy corta",IF(OR(ISNUMBER(SEARCH("@",D7)),ISNUMBER(SEARCH("http",D7)),ISNUMBER(SEARCH("www.",D7))),"Posible dato personal","")))
A8: P01 | B8: A | C8: S21 | D8: q cosas debo tener listas para la revision de seguridad | E8: Vas a pedir la revisión de seguridad de tu local y quieres saber qué cosas debes tener listas (equipos, planos, etc.). | F8: requisitos_defensa_civil | G8: =LEN(TRIM(D8)) -> 55 | H8: =IF(LEN(TRIM(D8))=0,"",IF(AND(LEN(TRIM(D8))<3,ISNA(MATCH(F8,Parametros!$K$4:$K$8,0))),"Muy corta",IF(OR(ISNUMBER(SEARCH("@",D8)),ISNUMBER(SEARCH("http",D8)),ISNUMBER(SEARCH("www.",D8))),"Posible dato personal","")))
A9: P01 | B9: A | C9: S26 | D9: murio mi tio y necesito el acta de defuncion como se saca | E9: Falleció un familiar y necesitas el documento oficial que lo acredite para hacer trámites; quieres saber cómo se consigue. | F9: partida_defuncion | G9: =LEN(TRIM(D9)) -> 57 | H9: =IF(LEN(TRIM(D9))=0,"",IF(AND(LEN(TRIM(D9))<3,ISNA(MATCH(F9,Parametros!$K$4:$K$8,0))),"Muy corta",IF(OR(ISNUMBER(SEARCH("@",D9)),ISNUMBER(SEARCH("http",D9)),ISNUMBER(SEARCH("www.",D9))),"Posible dato personal","")))
A10: P01 | B10: A | C10: S31 | D10: el parque esta abandonado y los juegos malogrados quiero q lo arreglen | E10: El parque cerca de tu casa está descuidado y con los juegos malogrados; quieres pedir que lo arreglen. | F10: mantenimiento_parques | G10: =LEN(TRIM(D10)) -> 70 | H10: =IF(LEN(TRIM(D10))=0,"",IF(AND(LEN(TRIM(D10))<3,ISNA(MATCH(F10,Parametros!$K$4:$K$8,0))),"Muy corta",IF(OR(ISNUMBER(SEARCH("@",D10)),ISNUMBER(SEARCH("http",D10)),ISNUMBER(SEARCH("www.",D10))),"Posible dato personal","")))
A11: P01 | B11: A | C11: S36 | D11: donde esta el libro de reclamaciones | E11: Quieres dejar tu queja en el libro oficial de reclamos y no sabes dónde está ni cómo se usa. | F11: libro_reclamaciones | G11: =LEN(TRIM(D11)) -> 36 | H11: =IF(LEN(TRIM(D11))=0,"",IF(AND(LEN(TRIM(D11))<3,ISNA(MATCH(F11,Parametros!$K$4:$K$8,0))),"Muy corta",IF(OR(ISNUMBER(SEARCH("@",D11)),ISNUMBER(SEARCH("http",D11)),ISNUMBER(SEARCH("www.",D11))),"Posible dato personal","")))
A12: P01 | B12: A | C12: S41 | D12: basta con mi dni para hacer un tramite | E12: Quieres hacer un trámite y quieres saber si basta con llevar tu DNI o necesitas algo más. | F12: requisitos_generales | G12: =LEN(TRIM(D12)) -> 38 | H12: =IF(LEN(TRIM(D12))=0,"",IF(AND(LEN(TRIM(D12))<3,ISNA(MATCH(F12,Parametros!$K$4:$K$8,0))),"Muy corta",IF(OR(ISNUMBER(SEARCH("@",D12)),ISNUMBER(SEARCH("http",D12)),ISNUMBER(SEARCH("www.",D12))),"Posible dato personal","")))
A13: P01 | B13: A | C13: S46 | D13: gracias chau | E13: Ya conseguiste la información que necesitabas y quieres terminar la conversación. ¿Cómo te despedirías? | F13: despedida | G13: =LEN(TRIM(D13)) -> 12 | H13: =IF(LEN(TRIM(D13))=0,"",IF(AND(LEN(TRIM(D13))<3,ISNA(MATCH(F13,Parametros!$K$4:$K$8,0))),"Muy corta",IF(OR(ISNUMBER(SEARCH("@",D13)),ISNUMBER(SEARCH("http",D13)),ISNUMBER(SEARCH("www.",D13))),"Posible dato personal","")))
A14: P01 | B14: A | C14: S51 | D14: como pago mi recibo de luz | E14: Quieres preguntarle algo sobre otra entidad o servicio (por ejemplo, la luz, el agua, la SUNAT, RENIEC o la policía) y no sobre la municipalidad. | F14: fuera_de_alcance | G14: =LEN(TRIM(D14)) -> 26 | H14: =IF(LEN(TRIM(D14))=0,"",IF(AND(LEN(TRIM(D14))<3,ISNA(MATCH(F14,Parametros!$K$4:$K$8,0))),"Muy corta",IF(OR(ISNUMBER(SEARCH("@",D14)),ISNUMBER(SEARCH("http",D14)),ISNUMBER(SEARCH("www.",D14))),"Posible dato personal","")))
A15: P01 | B15: A | C15: S56 | D15: repite porfa no alcance a leer | E15: El asistente te dio una información pero no alcanzaste a leerla ni a anotarla. ¿Cómo le pedirías que te la repita? | F15: repetir_informacion | G15: =LEN(TRIM(D15)) -> 30 | H15: =IF(LEN(TRIM(D15))=0,"",IF(AND(LEN(TRIM(D15))<3,ISNA(MATCH(F15,Parametros!$K$4:$K$8,0))),"Muy corta",IF(OR(ISNUMBER(SEARCH("@",D15)),ISNUMBER(SEARCH("http",D15)),ISNUMBER(SEARCH("www.",D15))),"Posible dato personal","")))
... A20: P02 | B20: B | C20: S22 | D20: hay gente sospechosa en mi cuadra a quien aviso | E20: En tu cuadra hay gente sospechosa y quieres avisar a alguien de la municipalidad para que intervenga. | F20: denuncia_seguridad_ciudadana | G20: =LEN(TRIM(D20)) -> 47 | H20: =IF(LEN(TRIM(D20))=0,"",IF(AND(LEN(TRIM(D20))<3,ISNA(MATCH(F20,Parametros!$K$4:$K$8,0))),"Muy corta",IF(OR(ISNUMBER(SEARCH("@",D20)),ISNUMBER(SEARCH("http",D20)),ISNUMBER(SEARCH("www.",D20))),"Posible dato personal","")))
A21: P02 | B21: B | C21: S27 | E21: Tu documento de nacimiento tiene tu apellido mal escrito y quieres saber cómo se corrige. | F21: rectificacion_partida | G21: =LEN(TRIM(D21)) -> 0 | H21: =IF(LEN(TRIM(D21))=0,"",IF(AND(LEN(TRIM(D21))<3,ISNA(MATCH(F21,Parametros!$K$4:$K$8,0))),"Muy corta",IF(OR(ISNUMBER(SEARCH("@",D21)),ISNUMBER(SEARCH("http",D21)),ISNUMBER(SEARCH("www.",D21))),"Posible dato personal","")))
A22: P02 | B22: B | C22: S32 | D22: un arbol tapa la vereda quiero q lo corten | E22: Un árbol de la vereda está tapando el paso y quieres que lo corten o lo recorten. | F22: poda_arboles | G22: =LEN(TRIM(D22)) -> 42 | H22: =IF(LEN(TRIM(D22))=0,"",IF(AND(LEN(TRIM(D22))<3,ISNA(MATCH(F22,Parametros!$K$4:$K$8,0))),"Muy corta",IF(OR(ISNUMBER(SEARCH("@",D22)),ISNUMBER(SEARCH("http",D22)),ISNUMBER(SEARCH("www.",D22))),"Posible dato personal","")))
A23: P02 | B23: B | C23: S37 | D23: un trabajador me atendio mal quiero reportarlo | E23: Un trabajador te atendió de mala manera y quieres reportarlo. | F23: queja_atencion | G23: =LEN(TRIM(D23)) -> 46 | H23: =IF(LEN(TRIM(D23))=0,"",IF(AND(LEN(TRIM(D23))<3,ISNA(MATCH(F23,Parametros!$K$4:$K$8,0))),"Muy corta",IF(OR(ISNUMBER(SEARCH("@",D23)),ISNUMBER(SEARCH("http",D23)),ISNUMBER(SEARCH("www.",D23))),"Posible dato personal","")))
A24: P02 | B24: B | C24: S42 | D24: cuanto cuestan los tramites | E24: Quieres saber cuánto cuestan en general los trámites de la municipalidad y dónde puedes ver la lista de precios. | F24: costos_generales | G24: =LEN(TRIM(D24)) -> 27 | H24: =IF(LEN(TRIM(D24))=0,"",IF(AND(LEN(TRIM(D24))<3,ISNA(MATCH(F24,Parametros!$K$4:$K$8,0))),"Muy corta",IF(OR(ISNUMBER(SEARCH("@",D24)),ISNUMBER(SEARCH("http",D24)),ISNUMBER(SEARCH("www.",D24))),"Posible dato personal","")))
A25: P02 | B25: B | C25: S47 | D25: gracias | E25: El asistente te dio justo la información que necesitabas. ¿Cómo se lo agradecerías? | F25: agradecimiento | G25: =LEN(TRIM(D25)) -> 7 | H25: =IF(LEN(TRIM(D25))=0,"",IF(AND(LEN(TRIM(D25))<3,ISNA(MATCH(F25,Parametros!$K$4:$K$8,0))),"Muy corta",IF(OR(ISNUMBER(SEARCH("@",D25)),ISNUMBER(SEARCH("http",D25)),ISNUMBER(SEARCH("www.",D25))),"Posible dato personal","")))
A26: P02 | B26: B | C26: S52 | D26: cuentame un chiste | E26: Quieres pedirle al asistente algo personal o fuera de lo normal (que cuente un chiste, que dé su opinión o que te haga la tarea). | F26: fuera_de_alcance | G26: =LEN(TRIM(D26)) -> 18 | H26: =IF(LEN(TRIM(D26))=0,"",IF(AND(LEN(TRIM(D26))<3,ISNA(MATCH(F26,Parametros!$K$4:$K$8,0))),"Muy corta",IF(OR(ISNUMBER(SEARCH("@",D26)),ISNUMBER(SEARCH("http",D26)),ISNUMBER(SEARCH("www.",D26))),"Posible dato personal","")))
A27: P03 | B27: C | C27: S03 | D27: cuantos dias demora la licencia de funcionamiento | E27: Entregaste tus papeles para el permiso de tu negocio y quieres saber cuántos días demoran en dártelo. | F27: licencia_funcionamiento_plazo | G27: =LEN(TRIM(D27)) -> 49 | H27: =IF(LEN(TRIM(D27))=0,"",IF(AND(LEN(TRIM(D27))<3,ISNA(MATCH(F27,Parametros!$K$4:$K$8,0))),"Muy corta",IF(OR(ISNUMBER(SEARCH("@",D27)),ISNUMBER(SEARCH("http",D27)),ISNUMBER(SEARCH("www.",D27))),"Posible dato personal","")))
A28: P03 | B28: C | C28: S08 | D28: donde pago el impuesto predial | E28: Ya sabes que debes pagar el impuesto de tu casa y quieres saber dónde o de qué forma puedes hacerlo. | F28: pago_predial_como | G28: =LEN(TRIM(D28)) -> 30 | H28: =IF(LEN(TRIM(D28))=0,"",IF(AND(LEN(TRIM(D28))<3,ISNA(MATCH(F28,Parametros!$K$4:$K$8,0))),"Muy corta",IF(OR(ISNUMBER(SEARCH("@",D28)),ISNUMBER(SEARCH("http",D28)),ISNUMBER(SEARCH("www.",D28))),"Posible dato personal","")))
A29: P03 | B29: C | C29: S13 | D29: q tengo q llevar para presentar una solicitud | E29: Quieres entregar una solicitud por escrito en la municipalidad y no sabes qué tienes que llevar. | F29: requisitos_mesa_partes | G29: =LEN(TRIM(D29)) -> 45 | H29: =IF(LEN(TRIM(D29))=0,"",IF(AND(LEN(TRIM(D29))<3,ISNA(MATCH(F29,Parametros!$K$4:$K$8,0))),"Muy corta",IF(OR(ISNUMBER(SEARCH("@",D29)),ISNUMBER(SEARCH("http",D29)),ISNUMBER(SEARCH("www.",D29))),"Posible dato personal","")))
A30: P03 | B30: C | C30: S18 | D30: como saco mi constancia de domicilio | E30: Te piden un documento que pruebe en qué dirección vives y quieres saber cómo sacarlo en la municipalidad. | F30: constancia_domiciliaria | G30: =LEN(TRIM(D30)) -> 36 | H30: =IF(LEN(TRIM(D30))=0,"",IF(AND(LEN(TRIM(D30))<3,ISNA(MATCH(F30,Parametros!$K$4:$K$8,0))),"Muy corta",IF(OR(ISNUMBER(SEARCH("@",D30)),ISNUMBER(SEARCH("http",D30)),ISNUMBER(SEARCH("www.",D30))),"Posible dato personal","")))
A31: P03 | B31: C | C31: S23 | D31: como me comunico con serenazgo | E31: Necesitas comunicarte con el personal que patrulla el distrito y quieres saber cómo contactarlos. | F31: serenazgo_contacto | G31: =LEN(TRIM(D31)) -> 30 | H31: =IF(LEN(TRIM(D31))=0,"",IF(AND(LEN(TRIM(D31))<3,ISNA(MATCH(F31,Parametros!$K$4:$K$8,0))),"Muy corta",IF(OR(ISNUMBER(SEARCH("@",D31)),ISNUMBER(SEARCH("http",D31)),ISNUMBER(SEARCH("www.",D31))),"Posible dato personal","")))
A32: P03 | B32: C | C32: S28 | D32: q papeles piden para casarse por civil | E32: Tu pareja y tú quieren casarse por lo civil en la municipalidad y quieren saber qué papeles necesitan. | F32: requisitos_matrimonio_civil | G32: =LEN(TRIM(D32)) -> 38 | H32: =IF(LEN(TRIM(D32))=0,"",IF(AND(LEN(TRIM(D32))<3,ISNA(MATCH(F32,Parametros!$K$4:$K$8,0))),"Muy corta",IF(OR(ISNUMBER(SEARCH("@",D32)),ISNUMBER(SEARCH("http",D32)),ISNUMBER(SEARCH("www.",D32))),"Posible dato personal","")))
A33: P03 | B33: C | C33: S33 | E33: Tu cuadra tiene basura acumulada en la pista y quieres que la limpien. | F33: limpieza_via_publica | G33: =LEN(TRIM(D33)) -> 0 | H33: =IF(LEN(TRIM(D33))=0,"",IF(AND(LEN(TRIM(D33))<3,ISNA(MATCH(F33,Parametros!$K$4:$K$8,0))),"Muy corta",IF(OR(ISNUMBER(SEARCH("@",D33)),ISNUMBER(SEARCH("http",D33)),ISNUMBER(SEARCH("www.",D33))),"Posible dato personal","")))
A34: P03 | B34: C | C34: S38 | D34: tengo una idea para mejorar la atencion | E34: Se te ocurrió una idea para mejorar la atención de la municipalidad y quieres comunicarla. | F34: sugerencia | G34: =LEN(TRIM(D34)) -> 39 | H34: =IF(LEN(TRIM(D34))=0,"",IF(AND(LEN(TRIM(D34))<3,ISNA(MATCH(F34,Parametros!$K$4:$K$8,0))),"Muy corta",IF(OR(ISNUMBER(SEARCH("@",D34)),ISNUMBER(SEARCH("http",D34)),ISNUMBER(SEARCH("www.",D34))),"Posible dato personal","")))
A35: P03 | B35: C | C35: S43 | D35: a q numero puedo llamar a la municipalidad | E35: Prefieres llamar en vez de ir y quieres saber a qué número o por qué medio comunicarte con la municipalidad. | F35: contacto_telefonico | G35: =LEN(TRIM(D35)) -> 42 | H35: =IF(LEN(TRIM(D35))=0,"",IF(AND(LEN(TRIM(D35))<3,ISNA(MATCH(F35,Parametros!$K$4:$K$8,0))),"Muy corta",IF(OR(ISNUMBER(SEARCH("@",D35)),ISNUMBER(SEARCH("http",D35)),ISNUMBER(SEARCH("www.",D35))),"Posible dato personal","")))
A36: P03 | B36: C | C36: S48 | D36: si | E36: El asistente te pregunta si entendió bien tu consulta y la respuesta es sí. ¿Cómo responderías? | F36: afirmar | G36: =LEN(TRIM(D36)) -> 2 | H36: =IF(LEN(TRIM(D36))=0,"",IF(AND(LEN(TRIM(D36))<3,ISNA(MATCH(F36,Parametros!$K$4:$K$8,0))),"Muy corta",IF(OR(ISNUMBER(SEARCH("@",D36)),ISNUMBER(SEARCH("http",D36)),ISNUMBER(SEARCH("www.",D36))),"Posible dato personal","")))
A37: P03 | B37: C | C37: S53 | D37: quiero hablar con una persona | E37: Prefieres que te atienda una persona y no un programa. ¿Qué le dirías al asistente? | F37: hablar_con_persona | G37: =LEN(TRIM(D37)) -> 29 | H37: =IF(LEN(TRIM(D37))=0,"",IF(AND(LEN(TRIM(D37))<3,ISNA(MATCH(F37,Parametros!$K$4:$K$8,0))),"Muy corta",IF(OR(ISNUMBER(SEARCH("@",D37)),ISNUMBER(SEARCH("http",D37)),ISNUMBER(SEARCH("www.",D37))),"Posible dato personal","")))
A38: P04 | B38: D | C38: S04 | D38: q documentos necesito para construir un segundo piso | E38: Quieres construir un segundo piso en tu casa y quieres saber qué documentos tendrías que presentar antes de empezar la obra. | F38: licencia_edificacion_requisitos | G38: =LEN(TRIM(D38)) -> 52 | H38: =IF(LEN(TRIM(D38))=0,"",IF(AND(LEN(TRIM(D38))<3,ISNA(MATCH(F38,Parametros!$K$4:$K$8,0))),"Muy corta",IF(OR(ISNUMBER(SEARCH("@",D38)),ISNUMBER(SEARCH("http",D38)),ISNUMBER(SEARCH("www.",D38))),"Posible dato personal","")))
A39: P04 | B39: D | C39: S09 | D39: como pago los arbitrios | E39: Te llegó un cobro por el recojo de basura, la limpieza de calles y el serenazgo, y quieres saber cómo pagarlo. | F39: pago_arbitrios | G39: =LEN(TRIM(D39)) -> 23 | H39: =IF(LEN(TRIM(D39))=0,"",IF(AND(LEN(TRIM(D39))<3,ISNA(MATCH(F39,Parametros!$K$4:$K$8,0))),"Muy corta",IF(OR(ISNUMBER(SEARCH("@",D39)),ISNUMBER(SEARCH("http",D39)),ISNUMBER(SEARCH("www.",D39))),"Posible dato personal","")))
A40: P04 | B40: D | C40: S14 | D40: como va mi tramite q deje hace semanas | E40: Dejaste unos papeles en la municipalidad hace semanas y quieres saber cómo va tu trámite. | F40: estado_tramite | G40: =LEN(TRIM(D40)) -> 38 | H40: =IF(LEN(TRIM(D40))=0,"",IF(AND(LEN(TRIM(D40))<3,ISNA(MATCH(F40,Parametros!$K$4:$K$8,0))),"Muy corta",IF(OR(ISNUMBER(SEARCH("@",D40)),ISNUMBER(SEARCH("http",D40)),ISNUMBER(SEARCH("www.",D40))),"Posible dato personal","")))
A41: P04 | B41: D | C41: S19 | D41: como se saca el certificado de defensa civil | E41: Tu local necesita un certificado de seguridad para poder funcionar y quieres saber cómo se obtiene. | F41: certificado_defensa_civil | G41: =LEN(TRIM(D41)) -> 44 | H41: =IF(LEN(TRIM(D41))=0,"",IF(AND(LEN(TRIM(D41))<3,ISNA(MATCH(F41,Parametros!$K$4:$K$8,0))),"Muy corta",IF(OR(ISNUMBER(SEARCH("@",D41)),ISNUMBER(SEARCH("http",D41)),ISNUMBER(SEARCH("www.",D41))),"Posible dato personal","")))
A42: P04 | B42: D | C42: S24 | D42: como saco mi partida de nacimiento | E42: Te piden el documento que prueba tu fecha y lugar de nacimiento y no sabes cómo conseguirlo. | F42: partida_nacimiento | G42: =LEN(TRIM(D42)) -> 34 | H42: =IF(LEN(TRIM(D42))=0,"",IF(AND(LEN(TRIM(D42))<3,ISNA(MATCH(F42,Parametros!$K$4:$K$8,0))),"Muy corta",IF(OR(ISNUMBER(SEARCH("@",D42)),ISNUMBER(SEARCH("http",D42)),ISNUMBER(SEARCH("www.",D42))),"Posible dato personal","")))
A43: P04 | B43: D | C43: S29 | D43: a q hora pasa el camion de basura | E43: El camión de la basura no pasó hoy por tu calle y quieres saber a qué hora suele pasar. | F43: horario_recojo_basura | G43: =LEN(TRIM(D43)) -> 33 | H43: =IF(LEN(TRIM(D43))=0,"",IF(AND(LEN(TRIM(D43))<3,ISNA(MATCH(F43,Parametros!$K$4:$K$8,0))),"Muy corta",IF(OR(ISNUMBER(SEARCH("@",D43)),ISNUMBER(SEARCH("http",D43)),ISNUMBER(SEARCH("www.",D43))),"Posible dato personal","")))
A44: P04 | B44: D | C44: S34 | D44: quiero hacer un reclamo formal x mi tramite | E44: No estás conforme con cómo te resolvieron un trámite y quieres hacer un reclamo formal. | F44: presentar_reclamo | G44: =LEN(TRIM(D44)) -> 43 | H44: =IF(LEN(TRIM(D44))=0,"",IF(AND(LEN(TRIM(D44))<3,ISNA(MATCH(F44,Parametros!$K$4:$K$8,0))),"Muy corta",IF(OR(ISNUMBER(SEARCH("@",D44)),ISNUMBER(SEARCH("http",D44)),ISNUMBER(SEARCH("www.",D44))),"Posible dato personal","")))
...

Sheet Resumen
A1: SIMULADO — Resumen de la transcripción del lote 1 (datos de prueba)
A2: Todo son fórmulas sobre las demás pestañas. «Listo para la Parte B» exige el mínimo de participantes transcritos y que cada intención tenga al menos el mínimo de frases.
A4: Participantes
A5: Pendientes | B5: =COUNTIF(Participantes!$C$4:$C$28,"Pendiente") -> 0
A6: Aplicados (falta transcribir) | B6: =COUNTIF(Participantes!$C$4:$C$28,"Aplicado") -> 0
A7: Transcritos | B7: =COUNTIF(Participantes!$C$4:$C$28,"Transcrito") -> 25
A8: Transcritos sin consentimiento «Sí» | B8: =COUNTIFS(Participantes!$C$4:$C$28,"Transcrito",Participantes!$G$4:$G$28,"<>Sí") -> 0 | C8: Debe ser 0: sin consentimiento firmado no se usa la hoja.
A9: Mínimo de participantes transcritos | B9: =Parametros!$B$6 -> 15
A10: Faltan | B10: =MAX(0,B9-B7) -> 0
A12: Frases
A13: Frases transcritas | B13: =SUMPRODUCT(--(LEN(TRIM(Respuestas!$D$4:$D$283))>0)) -> 273
A14: Frases con alerta (muy cortas o posible dato personal) | B14: =COUNTIF(Respuestas!$H$4:$H$283,"?*") -> 0 | C14: Revísalas antes de pasarle el archivo a Claude Code.
A16: Cobertura por intención
A17: Intenciones con la meta cumplida | B17: =COUNTIF(Cobertura!$G$4:$G$57,"Meta cumplida") -> 54 | C17: ="de "&COUNTA(Cobertura!$A$4:$A$57)&" intenciones" -> de 54 intenciones
A18: Intenciones en el mínimo (por debajo de la meta) | B18: =COUNTIF(Cobertura!$G$4:$G$57,"Mínimo alcanzado") -> 0
A19: Intenciones por debajo del mínimo | B19: =COUNTIF(Cobertura!$G$4:$G$57,"Insuficiente") -> 0 | C19: La Parte B se detiene si este valor es mayor que 0.
A20: Frases en la intención con menos | B20: =MIN(Cobertura!$D$4:$D$57) -> 4
A21: Estado general | B21: =IF(AND(B7>=B9,B20>=Parametros!$B$5),"Listo para la Parte B","Aún no") -> Listo para la Parte B
A23: Transcritos por formulario
A24: Formulario A | B24: =COUNTIFS(Participantes!$B$4:$B$28,"A",Participantes!$C$4:$C$28,"Transcrito") -> 5 | C24: ="Aplicados sin transcribir: "&COUNTIFS(Participantes!$B$4:$B$28,"A",Participantes!$C$4:$C$28,"Aplicado") -> Aplicados sin transcribir: 0
A25: Formulario B | B25: =COUNTIFS(Participantes!$B$4:$B$28,"B",Participantes!$C$4:$C$28,"Transcrito") -> 5 | C25: ="Aplicados sin transcribir: "&COUNTIFS(Participantes!$B$4:$B$28,"B",Participantes!$C$4:$C$28,"Aplicado") -> Aplicados sin transcribir: 0
A26: Formulario C | B26: =COUNTIFS(Participantes!$B$4:$B$28,"C",Participantes!$C$4:$C$28,"Transcrito") -> 5 | C26: ="Aplicados sin transcribir: "&COUNTIFS(Participantes!$B$4:$B$28,"C",Participantes!$C$4:$C$28,"Aplicado") -> Aplicados sin transcribir: 0
A27: Formulario D | B27: =COUNTIFS(Participantes!$B$4:$B$28,"D",Participantes!$C$4:$C$28,"Transcrito") -> 5 | C27: ="Aplicados sin transcribir: "&COUNTIFS(Participantes!$B$4:$B$28,"D",Participantes!$C$4:$C$28,"Aplicado") -> Aplicados sin transcribir: 0
A28: Formulario E | B28: =COUNTIFS(Participantes!$B$4:$B$28,"E",Participantes!$C$4:$C$28,"Transcrito") -> 5 | C28: ="Aplicados sin transcribir: "&COUNTIFS(Participantes!$B$4:$B$28,"E",Participantes!$C$4:$C$28,"Aplicado") -> Aplicados sin transcribir: 0

Sheet Cobertura
A1: SIMULADO — Cobertura por intención (frases de prueba; no son reales)
A2: Frases ya transcritas por intención frente a la meta y al mínimo (hoja Parametros). Úsala para decidir a quién reclutar: las intenciones en rojo o ámbar son las que faltan. fuera_de_alcance tiene 3 situaciones, por eso suma más frases.
A3: Intención | B3: Categoría | C3: Situaciones | D3: Frases | E3: Meta | F3: Faltan para la meta | G3: Estado
A4: licencia_funcionamiento_requisitos | B4: Licencias y autorizaciones | C4: =COUNTIF(Situaciones!$C$4:$C$59,A4) -> 1 | D4: =SUMIF(Situaciones!$C$4:$C$59,A4,Situaciones!$F$4:$F$59) -> 5 | E4: =Parametros!$B$4 -> 4 | F4: =MAX(0,E4-D4) -> 0 | G4: =IF(D4>=E4,"Meta cumplida",IF(D4>=Parametros!$B$5,"Mínimo alcanzado","Insuficiente")) -> Meta cumplida
A5: licencia_funcionamiento_costo | B5: Licencias y autorizaciones | C5: =COUNTIF(Situaciones!$C$4:$C$59,A5) -> 1 | D5: =SUMIF(Situaciones!$C$4:$C$59,A5,Situaciones!$F$4:$F$59) -> 5 | E5: =Parametros!$B$4 -> 4 | F5: =MAX(0,E5-D5) -> 0 | G5: =IF(D5>=E5,"Meta cumplida",IF(D5>=Parametros!$B$5,"Mínimo alcanzado","Insuficiente")) -> Meta cumplida
A6: licencia_funcionamiento_plazo | B6: Licencias y autorizaciones | C6: =COUNTIF(Situaciones!$C$4:$C$59,A6) -> 1 | D6: =SUMIF(Situaciones!$C$4:$C$59,A6,Situaciones!$F$4:$F$59) -> 5 | E6: =Parametros!$B$4 -> 4 | F6: =MAX(0,E6-D6) -> 0 | G6: =IF(D6>=E6,"Meta cumplida",IF(D6>=Parametros!$B$5,"Mínimo alcanzado","Insuficiente")) -> Meta cumplida
A7: licencia_edificacion_requisitos | B7: Licencias y autorizaciones | C7: =COUNTIF(Situaciones!$C$4:$C$59,A7) -> 1 | D7: =SUMIF(Situaciones!$C$4:$C$59,A7,Situaciones!$F$4:$F$59) -> 5 | E7: =Parametros!$B$4 -> 4 | F7: =MAX(0,E7-D7) -> 0 | G7: =IF(D7>=E7,"Meta cumplida",IF(D7>=Parametros!$B$5,"Mínimo alcanzado","Insuficiente")) -> Meta cumplida
A8: licencia_edificacion_costo | B8: Licencias y autorizaciones | C8: =COUNTIF(Situaciones!$C$4:$C$59,A8) -> 1 | D8: =SUMIF(Situaciones!$C$4:$C$59,A8,Situaciones!$F$4:$F$59) -> 4 | E8: =Parametros!$B$4 -> 4 | F8: =MAX(0,E8-D8) -> 0 | G8: =IF(D8>=E8,"Meta cumplida",IF(D8>=Parametros!$B$5,"Mínimo alcanzado","Insuficiente")) -> Meta cumplida
A9: renovacion_licencia | B9: Licencias y autorizaciones | C9: =COUNTIF(Situaciones!$C$4:$C$59,A9) -> 1 | D9: =SUMIF(Situaciones!$C$4:$C$59,A9,Situaciones!$F$4:$F$59) -> 5 | E9: =Parametros!$B$4 -> 4 | F9: =MAX(0,E9-D9) -> 0 | G9: =IF(D9>=E9,"Meta cumplida",IF(D9>=Parametros!$B$5,"Mínimo alcanzado","Insuficiente")) -> Meta cumplida
A10: consulta_deuda_predial | B10: Tributos y pagos municipales | C10: =COUNTIF(Situaciones!$C$4:$C$59,A10) -> 1 | D10: =SUMIF(Situaciones!$C$4:$C$59,A10,Situaciones!$F$4:$F$59) -> 5 | E10: =Parametros!$B$4 -> 4 | F10: =MAX(0,E10-D10) -> 0 | G10: =IF(D10>=E10,"Meta cumplida",IF(D10>=Parametros!$B$5,"Mínimo alcanzado","Insuficiente")) -> Meta cumplida
A11: pago_predial_como | B11: Tributos y pagos municipales | C11: =COUNTIF(Situaciones!$C$4:$C$59,A11) -> 1 | D11: =SUMIF(Situaciones!$C$4:$C$59,A11,Situaciones!$F$4:$F$59) -> 4 | E11: =Parametros!$B$4 -> 4 | F11: =MAX(0,E11-D11) -> 0 | G11: =IF(D11>=E11,"Meta cumplida",IF(D11>=Parametros!$B$5,"Mínimo alcanzado","Insuficiente")) -> Meta cumplida
A12: pago_arbitrios | B12: Tributos y pagos municipales | C12: =COUNTIF(Situaciones!$C$4:$C$59,A12) -> 1 | D12: =SUMIF(Situaciones!$C$4:$C$59,A12,Situaciones!$F$4:$F$59) -> 5 | E12: =Parametros!$B$4 -> 4 | F12: =MAX(0,E12-D12) -> 0 | G12: =IF(D12>=E12,"Meta cumplida",IF(D12>=Parametros!$B$5,"Mínimo alcanzado","Insuficiente")) -> Meta cumplida
A13: impuesto_alcabala | B13: Tributos y pagos municipales | C13: =COUNTIF(Situaciones!$C$4:$C$59,A13) -> 1 | D13: =SUMIF(Situaciones!$C$4:$C$59,A13,Situaciones!$F$4:$F$59) -> 4 | E13: =Parametros!$B$4 -> 4 | F13: =MAX(0,E13-D13) -> 0 | G13: =IF(D13>=E13,"Meta cumplida",IF(D13>=Parametros!$B$5,"Mínimo alcanzado","Insuficiente")) -> Meta cumplida
A14: fraccionamiento_deuda | B14: Tributos y pagos municipales | C14: =COUNTIF(Situaciones!$C$4:$C$59,A14) -> 1 | D14: =SUMIF(Situaciones!$C$4:$C$59,A14,Situaciones!$F$4:$F$59) -> 4 | E14: =Parametros!$B$4 -> 4 | F14: =MAX(0,E14-D14) -> 0 | G14: =IF(D14>=E14,"Meta cumplida",IF(D14>=Parametros!$B$5,"Mínimo alcanzado","Insuficiente")) -> Meta cumplida
A15: constancia_no_adeudo | B15: Tributos y pagos municipales | C15: =COUNTIF(Situaciones!$C$4:$C$59,A15) -> 1 | D15: =SUMIF(Situaciones!$C$4:$C$59,A15,Situaciones!$F$4:$F$59) -> 5 | E15: =Parametros!$B$4 -> 4 | F15: =MAX(0,E15-D15) -> 0 | G15: =IF(D15>=E15,"Meta cumplida",IF(D15>=Parametros!$B$5,"Mínimo alcanzado","Insuficiente")) -> Meta cumplida
... A57: repetir_informacion | B57: Interacción conversacional | C57: =COUNTIF(Situaciones!$C$4:$C$59,A57) -> 1 | D57: =SUMIF(Situaciones!$C$4:$C$59,A57,Situaciones!$F$4:$F$59) -> 5 | E57: =Parametros!$B$4 -> 4 | F57: =MAX(0,E57-D57) -> 0 | G57: =IF(D57>=E57,"Meta cumplida",IF(D57>=Parametros!$B$5,"Mínimo alcanzado","Insuficiente")) -> Meta cumplida

Sheet Situaciones
A1: SIMULADO — Frases por situación (datos de prueba)
A2: Catálogo de las 56 situaciones (situaciones_lote1_v1.csv, valores fijos) y cuántas frases hay ya transcritas de cada una. Todo se calcula solo a partir de la pestaña Respuestas.
A3: scenario_id | B3: form | C3: Intención esperada | D3: Categoría | E3: Situación | F3: Frases transcritas | G3: Personas asignadas | H3: Pendientes
A4: S01 | B4: A | C4: licencia_funcionamiento_requisitos | D4: Licencias y autorizaciones | E4: Vas a abrir una tiendita en tu barrio y no sabes qué papeles te van a pedir en la municipalidad para poder atender legalmente. | F4: =SUMPRODUCT((Respuestas!$C$4:$C$283=A4)*(LEN(TRIM(Respuestas!$D$4:$D$283))>0)) -> 5 | G4: =COUNTIF(Respuestas!$C$4:$C$283,A4) -> 5 | H4: =G4-F4 -> 0
A5: S02 | B5: B | C5: licencia_funcionamiento_costo | D5: Licencias y autorizaciones | E5: Ya sabes que necesitas un permiso de la municipalidad para tu negocio y quieres saber cuánto tendrías que pagar por él. | F5: =SUMPRODUCT((Respuestas!$C$4:$C$283=A5)*(LEN(TRIM(Respuestas!$D$4:$D$283))>0)) -> 5 | G5: =COUNTIF(Respuestas!$C$4:$C$283,A5) -> 5 | H5: =G5-F5 -> 0
A6: S03 | B6: C | C6: licencia_funcionamiento_plazo | D6: Licencias y autorizaciones | E6: Entregaste tus papeles para el permiso de tu negocio y quieres saber cuántos días demoran en dártelo. | F6: =SUMPRODUCT((Respuestas!$C$4:$C$283=A6)*(LEN(TRIM(Respuestas!$D$4:$D$283))>0)) -> 5 | G6: =COUNTIF(Respuestas!$C$4:$C$283,A6) -> 5 | H6: =G6-F6 -> 0
A7: S04 | B7: D | C7: licencia_edificacion_requisitos | D7: Licencias y autorizaciones | E7: Quieres construir un segundo piso en tu casa y quieres saber qué documentos tendrías que presentar antes de empezar la obra. | F7: =SUMPRODUCT((Respuestas!$C$4:$C$283=A7)*(LEN(TRIM(Respuestas!$D$4:$D$283))>0)) -> 5 | G7: =COUNTIF(Respuestas!$C$4:$C$283,A7) -> 5 | H7: =G7-F7 -> 0
A8: S05 | B8: E | C8: licencia_edificacion_costo | D8: Licencias y autorizaciones | E8: Vas a construir en tu terreno y quieres saber cuánto cobra la municipalidad por autorizar la obra. | F8: =SUMPRODUCT((Respuestas!$C$4:$C$283=A8)*(LEN(TRIM(Respuestas!$D$4:$D$283))>0)) -> 4 | G8: =COUNTIF(Respuestas!$C$4:$C$283,A8) -> 5 | H8: =G8-F8 -> 1
A9: S06 | B9: A | C9: renovacion_licencia | D9: Licencias y autorizaciones | E9: El permiso de funcionamiento de tu negocio ya se venció y quieres saber qué tienes que hacer para dejarlo vigente otra vez. | F9: =SUMPRODUCT((Respuestas!$C$4:$C$283=A9)*(LEN(TRIM(Respuestas!$D$4:$D$283))>0)) -> 5 | G9: =COUNTIF(Respuestas!$C$4:$C$283,A9) -> 5 | H9: =G9-F9 -> 0
A10: S07 | B10: B | C10: consulta_deuda_predial | D10: Tributos y pagos municipales | E10: Quieres saber si debes impuestos por tu casa o terreno, y cuánto sería. | F10: =SUMPRODUCT((Respuestas!$C$4:$C$283=A10)*(LEN(TRIM(Respuestas!$D$4:$D$283))>0)) -> 5 | G10: =COUNTIF(Respuestas!$C$4:$C$283,A10) -> 5 | H10: =G10-F10 -> 0
A11: S08 | B11: C | C11: pago_predial_como | D11: Tributos y pagos municipales | E11: Ya sabes que debes pagar el impuesto de tu casa y quieres saber dónde o de qué forma puedes hacerlo. | F11: =SUMPRODUCT((Respuestas!$C$4:$C$283=A11)*(LEN(TRIM(Respuestas!$D$4:$D$283))>0)) -> 4 | G11: =COUNTIF(Respuestas!$C$4:$C$283,A11) -> 5 | H11: =G11-F11 -> 1
A12: S09 | B12: D | C12: pago_arbitrios | D12: Tributos y pagos municipales | E12: Te llegó un cobro por el recojo de basura, la limpieza de calles y el serenazgo, y quieres saber cómo pagarlo. | F12: =SUMPRODUCT((Respuestas!$C$4:$C$283=A12)*(LEN(TRIM(Respuestas!$D$4:$D$283))>0)) -> 5 | G12: =COUNTIF(Respuestas!$C$4:$C$283,A12) -> 5 | H12: =G12-F12 -> 0
A13: S10 | B13: E | C13: impuesto_alcabala | D13: Tributos y pagos municipales | E13: Acabas de comprar un terreno y te dijeron que hay un impuesto por esa compra; quieres saber de qué trata y cómo se paga. | F13: =SUMPRODUCT((Respuestas!$C$4:$C$283=A13)*(LEN(TRIM(Respuestas!$D$4:$D$283))>0)) -> 4 | G13: =COUNTIF(Respuestas!$C$4:$C$283,A13) -> 5 | H13: =G13-F13 -> 1
A14: S11 | B14: A | C14: fraccionamiento_deuda | D14: Tributos y pagos municipales | E14: Debes varios años de impuestos municipales y no puedes pagar todo de golpe; quieres saber si puedes pagarlo poco a poco. | F14: =SUMPRODUCT((Respuestas!$C$4:$C$283=A14)*(LEN(TRIM(Respuestas!$D$4:$D$283))>0)) -> 4 | G14: =COUNTIF(Respuestas!$C$4:$C$283,A14) -> 5 | H14: =G14-F14 -> 1
A15: S12 | B15: B | C15: constancia_no_adeudo | D15: Tributos y pagos municipales | E15: Te piden un papel que demuestre que no tienes deudas con la municipalidad y quieres saber cómo conseguirlo. | F15: =SUMPRODUCT((Respuestas!$C$4:$C$283=A15)*(LEN(TRIM(Respuestas!$D$4:$D$283))>0)) -> 5 | G15: =COUNTIF(Respuestas!$C$4:$C$283,A15) -> 5 | H15: =G15-F15 -> 0
... A59: S56 | B59: A | C59: repetir_informacion | D59: Interacción conversacional | E59: El asistente te dio una información pero no alcanzaste a leerla ni a anotarla. ¿Cómo le pedirías que te la repita? | F59: =SUMPRODUCT((Respuestas!$C$4:$C$283=A59)*(LEN(TRIM(Respuestas!$D$4:$D$283))>0)) -> 5 | G59: =COUNTIF(Respuestas!$C$4:$C$283,A59) -> 5 | H59: =G59-F59 -> 0

Sheet Parametros
A1: Parámetros y listas
A2: Celdas amarillas = valores editables.
A3: Parámetro | B3: Valor | C3: Fuente / criterio | F3: Rango de edad | G3: Sí / No | H3: Estado | K3: Intenciones cortas permitidas
A4: Meta de frases reales por intención | B4: 4 | C4: 20 personas ÷ 5 formularios = 4 respuestas por situación (guía de aplicación del lote 1). | F4: 18–29 | G4: Sí | H4: Pendiente | K4: saludo
A5: Mínimo de frases reales por intención | B5: 3 | C5: La Parte B se detiene si alguna intención queda con menos de 3 frases (Instrucciones_ClaudeCode_lote_real_v2.md, paso B1). | F5: 30–44 | G5: No | H5: Aplicado | K5: despedida
A6: Mínimo de participantes transcritos | B6: 15 | C6: Mínimo indicado en la guía de aplicación del lote 1 (ideal 20 a 25). | F6: 45–59 | H6: Transcrito | K6: agradecimiento
F7: 60 a más | K7: afirmar
K8: negar

Sheet Notas
A1: Notas de uso
A3: Cómo usar
A4: 1. Cada persona que responde un formulario recibe un código (P01 a P25). Anota en Participantes su rango de edad, si vive en Juliaca, si hizo un trámite en los últimos 12 meses, el consentimiento firmado y la fecha.
A5: 2. Pasa las respuestas a la pestaña Respuestas, fila por fila: cada persona tiene ya sus situaciones (las de su formulario) en el mismo orden en que aparecen impresas. Copia la frase tal cual; si la dejó en blanco, deja la celda vacía.
A6: 3. Cuando termines con una persona, cambia su Estado a «Transcrito». El Resumen y Cobertura se actualizan solos.
A7: 4. Mira Cobertura: las intenciones en rojo o ámbar necesitan más frases. Si faltan, aplica el formulario correspondiente a otra persona (P21 a P25 son la reserva).
A8: 5. Cuando el Resumen diga «Listo para la Parte B», guarda el archivo desde Excel y entrégaselo a Claude Code. No hace falta exportar a CSV: Claude Code lee las pestañas Participantes y Respuestas.
A10: Reglas
A11: • Las frases las escriben los participantes. Aquí solo se transcriben: sin corregir, sin completar y sin generarlas con IA.
A12: • No uses nombres, DNI ni teléfonos. Si aparecieran en la hoja original, bórralos al transcribir.
A13: • No cambies el formulario asignado ni las columnas A–C de Respuestas. Esas filas están ligadas a la rotación A–E.
A14: • El archivo lleno contiene respuestas de personas reales: se guarda fuera del repositorio (docs/lote_real_1/privado/). Al repositorio solo van los CSV validados.
... A19: • Colores: azul = valor escrito a mano o dato fijo; negro = fórmula; verde = vínculo a otra hoja.
