Workbook

Sheet Verificacion
A1: Verificación de las respuestas del chatbot contra el TUPA y otras fuentes oficiales
A2: Una fila por respuesta de trámite (44). Compara la respuesta actual con la fuente oficial y llena las celdas amarillas. Si no encuentras el dato, marca «No figura en la fuente» y explica dónde buscaste. No escribas datos de memoria: cada dato lleva su fuente.
A3: # | B3: Intención | C3: Categoría | D3: Prioridad | E3: Fuente probable | F3: Marcada [Verificar] en el repositorio | G3: Respuesta actual (texto base, sin la marca) | H3: Datos a comprobar | I3: Procedimiento o documento en la fuente (nombre, código y página) | J3: Requisitos según la fuente | K3: Costo según la fuente | L3: Plazo según la fuente | M3: Oficina y canal según la fuente | N3: Resultado | O3: Texto corregido para domain.yml | P3: Fecha de verificación | Q3: Observaciones | R3: Alerta | S3: Confirmado por el tesista
A4: 1 | B4: licencia_funcionamiento_requisitos | C4: Licencias y autorizaciones | D4: Alta | E4: TUPA | F4: Sí | G4: Para la licencia de funcionamiento necesitas: copia de tu DNI, el certificado de compatibilidad de uso, el certificado de Defensa Civil (ITSE) y el recibo de pago de la tasa correspondiente. | H4: Lista exacta de requisitos y documentos; si exige certificado de compatibilidad de uso e ITSE; cambia según nivel de riesgo. | I4: Nota de prensa (no oficial): https://pachamamaradio.org/san-roman-implementa-licencias-de-funcionamiento-digitales-a-partir-del-20-de-agosto/ | J4: Sin lista: la nota dice que los requisitos mantienen las mismas condiciones. Desde el 20 de agosto (2025) la licencia es digital, con código QR y firma electrónica. | M4: Subgerencia de Fomento a la Inversión Privada (según la nota). | N4: Pendiente | Q4: Búsqueda asistida (5/10/2026). Fuente de prensa. Falta la lista de requisitos en el TUPA 2025. Si se confirma, conviene mencionar que la licencia se entrega en formato digital. | R4: =IF(AND(N4="Corregir",LEN(TRIM(O4))=0),"Falta el texto corregido",IF(AND(OR(N4="Coincide",N4="Corregir"),LEN(TRIM(I4))=0),"Falta citar la fuente",IF(AND(N4="No figura en la fuente",LEN(TRIM(Q4))=0),"Explica dónde buscaste",IF(AND(N4<>"Pendiente",P4=""),"Falta la fecha",""))))
A5: 2 | B5: licencia_funcionamiento_costo | C5: Licencias y autorizaciones | D5: Alta | E5: TUPA | F5: Sí | G5: El costo de la licencia de funcionamiento depende del giro del negocio y del área del local. Puedes consultar el monto exacto en el TUPA de la MPSR o acercarte a la Plataforma de Atención. | H5: Derecho de tramitación (en soles o % de la UIT); si varía por giro, área o nivel de riesgo. | I5: Nota de prensa (no oficial): https://pachamamaradio.org/san-roman-implementa-licencias-de-funcionamiento-digitales-a-partir-del-20-de-agosto/ | K5: Sin monto: «los costos permanecen inalterados según el TUPA vigente». | M5: Subgerencia de Fomento a la Inversión Privada (según la nota). | N5: Pendiente | Q5: Búsqueda asistida (5/10/2026). Fuente de prensa. Falta el derecho de tramitación en el TUPA 2025 (buscar «licencia de funcionamiento»). | R5: =IF(AND(N5="Corregir",LEN(TRIM(O5))=0),"Falta el texto corregido",IF(AND(OR(N5="Coincide",N5="Corregir"),LEN(TRIM(I5))=0),"Falta citar la fuente",IF(AND(N5="No figura en la fuente",LEN(TRIM(Q5))=0),"Explica dónde buscaste",IF(AND(N5<>"Pendiente",P5=""),"Falta la fecha",""))))
A6: 3 | B6: licencia_funcionamiento_plazo | C6: Licencias y autorizaciones | D6: Alta | E6: TUPA | F6: Sí | G6: El trámite de licencia de funcionamiento suele atenderse en un plazo de 10 a 15 días hábiles, según la complejidad del giro del negocio. | H6: Plazo en días hábiles; tipo de silencio administrativo. | N6: Pendiente | R6: =IF(AND(N6="Corregir",LEN(TRIM(O6))=0),"Falta el texto corregido",IF(AND(OR(N6="Coincide",N6="Corregir"),LEN(TRIM(I6))=0),"Falta citar la fuente",IF(AND(N6="No figura en la fuente",LEN(TRIM(Q6))=0),"Explica dónde buscaste",IF(AND(N6<>"Pendiente",P6=""),"Falta la fecha",""))))
A7: 4 | B7: licencia_edificacion_requisitos | C7: Licencias y autorizaciones | D7: Alta | E7: TUPA | F7: Sí | G7: Para la licencia de edificación necesitas: título de propiedad o documento que acredite posesión, planos de arquitectura firmados por un profesional colegiado, y el pago de la tasa correspondiente. | H7: Requisitos por modalidad de aprobación (A, B, C, D); documentos técnicos; profesionales que firman. | N7: Pendiente | R7: =IF(AND(N7="Corregir",LEN(TRIM(O7))=0),"Falta el texto corregido",IF(AND(OR(N7="Coincide",N7="Corregir"),LEN(TRIM(I7))=0),"Falta citar la fuente",IF(AND(N7="No figura en la fuente",LEN(TRIM(Q7))=0),"Explica dónde buscaste",IF(AND(N7<>"Pendiente",P7=""),"Falta la fecha",""))))
A8: 5 | B8: licencia_edificacion_costo | C8: Licencias y autorizaciones | D8: Alta | E8: TUPA | F8: Sí | G8: El costo de la licencia de edificación varía según el tipo y tamaño de la obra. Puedes consultar el monto exacto en el TUPA de la MPSR. | H8: Derecho de tramitación por modalidad y por metraje o valor de la obra. | N8: Pendiente | R8: =IF(AND(N8="Corregir",LEN(TRIM(O8))=0),"Falta el texto corregido",IF(AND(OR(N8="Coincide",N8="Corregir"),LEN(TRIM(I8))=0),"Falta citar la fuente",IF(AND(N8="No figura en la fuente",LEN(TRIM(Q8))=0),"Explica dónde buscaste",IF(AND(N8<>"Pendiente",P8=""),"Falta la fecha",""))))
A9: 6 | B9: renovacion_licencia | C9: Licencias y autorizaciones | D9: Alta | E9: TUPA | F9: Sí | G9: Para renovar tu licencia de funcionamiento debes presentar tu licencia anterior, DNI vigente y el pago de la tasa de renovación. El trámite se realiza en la Plataforma de Atención. | H9: Si el TUPA contempla renovación o solo licencias indefinidas y temporales; requisitos, tasa y plazo. | I9: Nota de prensa (no oficial): https://pachamamaradio.org/san-roman-implementa-licencias-de-funcionamiento-digitales-a-partir-del-20-de-agosto/ ; licencia de 2023 en Studocu (no oficial) | L9: La nota dice que las licencias digitales tienen validez de un año; una licencia de 2023 dice «vigencia permanente». | N9: Pendiente | Q9: Búsqueda asistida (5/10/2026). Posible corrección importante: si la licencia dura un año, la renovación existe; si es permanente, la respuesta actual puede estar equivocada. Confirmar en el TUPA y con la Subgerencia de Fomento a la Inversión Privada. | R9: =IF(AND(N9="Corregir",LEN(TRIM(O9))=0),"Falta el texto corregido",IF(AND(OR(N9="Coincide",N9="Corregir"),LEN(TRIM(I9))=0),"Falta citar la fuente",IF(AND(N9="No figura en la fuente",LEN(TRIM(Q9))=0),"Explica dónde buscaste",IF(AND(N9<>"Pendiente",P9=""),"Falta la fecha",""))))
A10: 7 | B10: consulta_deuda_predial | C10: Tributos y pagos municipales | D10: Media | E10: TUPA o portal | F10: Sí | G10: Puedes consultar tu deuda de impuesto predial presentando tu DNI en la Plataforma de Atención, o a través del número de tu autoavalúo si lo tienes a la mano. | H10: Canal para consultar la deuda (ventanilla, web o sistema); documentos o datos que piden. | N10: Pendiente | R10: =IF(AND(N10="Corregir",LEN(TRIM(O10))=0),"Falta el texto corregido",IF(AND(OR(N10="Coincide",N10="Corregir"),LEN(TRIM(I10))=0),"Falta citar la fuente",IF(AND(N10="No figura en la fuente",LEN(TRIM(Q10))=0),"Explica dónde buscaste",IF(AND(N10<>"Pendiente",P10=""),"Falta la fecha",""))))
A11: 8 | B11: pago_predial_como | C11: Tributos y pagos municipales | D11: Media | E11: Norma tributaria u ordenanza | F11: Sí | G11: El impuesto predial se puede pagar en caja de la municipalidad o en los bancos autorizados que tengan convenio con la MPSR. | H11: Canales de pago (caja, bancos con convenio, web); fechas de vencimiento de las cuotas. | N11: Pendiente | R11: =IF(AND(N11="Corregir",LEN(TRIM(O11))=0),"Falta el texto corregido",IF(AND(OR(N11="Coincide",N11="Corregir"),LEN(TRIM(I11))=0),"Falta citar la fuente",IF(AND(N11="No figura en la fuente",LEN(TRIM(Q11))=0),"Explica dónde buscaste",IF(AND(N11<>"Pendiente",P11=""),"Falta la fecha",""))))
A12: 9 | B12: pago_arbitrios | C12: Tributos y pagos municipales | D12: Media | E12: Norma tributaria u ordenanza | F12: Sí | G12: Los arbitrios municipales (limpieza pública, parques y jardines, serenazgo) se pagan junto con el impuesto predial o de forma independiente en caja de la municipalidad. | H12: Si se cobran junto con el predial; periodicidad; canales de pago; ordenanza de arbitrios vigente. | N12: Pendiente | R12: =IF(AND(N12="Corregir",LEN(TRIM(O12))=0),"Falta el texto corregido",IF(AND(OR(N12="Coincide",N12="Corregir"),LEN(TRIM(I12))=0),"Falta citar la fuente",IF(AND(N12="No figura en la fuente",LEN(TRIM(Q12))=0),"Explica dónde buscaste",IF(AND(N12<>"Pendiente",P12=""),"Falta la fecha",""))))
A13: 10 | B13: impuesto_alcabala | C13: Tributos y pagos municipales | D13: Alta | E13: Norma tributaria u ordenanza | F13: Sí | G13: El impuesto de alcabala se paga cuando compras un inmueble, y corresponde al 3% del valor de transferencia (con un tramo inicial inafecto equivalente a 10 UIT). Se cancela dentro del mes siguiente a la compra. | H13: Tasa, monto inafecto (en UIT), plazo de pago y quién paga; documentos que se presentan. | N13: Pendiente | R13: =IF(AND(N13="Corregir",LEN(TRIM(O13))=0),"Falta el texto corregido",IF(AND(OR(N13="Coincide",N13="Corregir"),LEN(TRIM(I13))=0),"Falta citar la fuente",IF(AND(N13="No figura en la fuente",LEN(TRIM(Q13))=0),"Explica dónde buscaste",IF(AND(N13<>"Pendiente",P13=""),"Falta la fecha",""))))
A14: 11 | B14: fraccionamiento_deuda | C14: Tributos y pagos municipales | D14: Alta | E14: TUPA o portal | F14: Sí | G14: Para fraccionar una deuda tributaria debes presentar una solicitud en mesa de partes, adjuntando tu DNI y el detalle de la deuda. La municipalidad evaluará una cuota inicial y un cronograma de pagos. | H14: Si existe como procedimiento; requisitos, cuota inicial, plazo máximo e intereses. | N14: Pendiente | R14: =IF(AND(N14="Corregir",LEN(TRIM(O14))=0),"Falta el texto corregido",IF(AND(OR(N14="Coincide",N14="Corregir"),LEN(TRIM(I14))=0),"Falta citar la fuente",IF(AND(N14="No figura en la fuente",LEN(TRIM(Q14))=0),"Explica dónde buscaste",IF(AND(N14<>"Pendiente",P14=""),"Falta la fecha",""))))
A15: 12 | B15: constancia_no_adeudo | C15: Tributos y pagos municipales | D15: Alta | E15: TUPA | F15: Sí | G15: La constancia de no adeudo se tramita presentando tu DNI en la Plataforma de Atención; se emite una vez verificado que no tienes deudas pendientes por impuesto predial o arbitrios. | H15: Requisitos, costo, plazo y área que la emite. | N15: Pendiente | R15: =IF(AND(N15="Corregir",LEN(TRIM(O15))=0),"Falta el texto corregido",IF(AND(OR(N15="Coincide",N15="Corregir"),LEN(TRIM(I15))=0),"Falta citar la fuente",IF(AND(N15="No figura en la fuente",LEN(TRIM(Q15))=0),"Explica dónde buscaste",IF(AND(N15<>"Pendiente",P15=""),"Falta la fecha",""))))
A16: 13 | B16: requisitos_mesa_partes | C16: Trámites documentarios | D16: Alta | E16: TUPA o portal | F16: Sí | G16: Para presentar un documento en mesa de partes necesitas tu solicitud (puede ser un formato simple), copia de tu DNI, y los anexos que sustenten tu pedido. | H16: Requisitos para presentar documentos; formato de solicitud; si hay mesa de partes virtual. | I16: Mesa de partes virtual (aviso posiblemente desactualizado): https://www.mpv.mpsr.pe/ | J16: Según el aviso: documento redactado, firmado, escaneado y enviado en PDF. La mesa de partes virtual no atiende trámites de Registro Civil, Gerencia de Desarrollo Urbano ni Transportes. | M16: Correo sg_tramite_documentario@munisanroman.gob.pe (según el aviso). | N16: Pendiente | Q16: Búsqueda asistida (5/10/2026). El aviso cita el D.S. 044-2020-PCM (emergencia COVID): confirmar si sigue vigente. Los requisitos formales de mesa de partes están en el TUPA. | R16: =IF(AND(N16="Corregir",LEN(TRIM(O16))=0),"Falta el texto corregido",IF(AND(OR(N16="Coincide",N16="Corregir"),LEN(TRIM(I16))=0),"Falta citar la fuente",IF(AND(N16="No figura en la fuente",LEN(TRIM(Q16))=0),"Explica dónde buscaste",IF(AND(N16<>"Pendiente",P16=""),"Falta la fecha",""))))
A17: 14 | B17: estado_tramite | C17: Trámites documentarios | D17: Media | E17: Portal o directorio institucional | F17: Sí | G17: Puedes consultar el estado de tu trámite presentando tu número de expediente en mesa de partes o en la Plataforma de Atención. | H17: Cómo se consulta el estado (número de expediente, sistema de seguimiento en línea). | I17: Portal MPSR-J en gob.pe (enlace «Seguimiento de trámites»): https://www.gob.pe/munisanroman | M17: Seguimiento de trámites en línea en gob.pe/munisanroman; mesa de partes. | N17: Corregir | O17: Puedes consultar el estado de tu trámite con tu número de expediente en la opción «Seguimiento de trámites» del portal de la MPSR en gob.pe (gob.pe/munisanroman) o en mesa de partes. | P17: 46300 | Q17: Búsqueda asistida (5/10/2026). «Plataforma de Atención» no aparece en las fuentes oficiales vistas: confirmar si la MPSR usa ese nombre. | R17: =IF(AND(N17="Corregir",LEN(TRIM(O17))=0),"Falta el texto corregido",IF(AND(OR(N17="Coincide",N17="Corregir"),LEN(TRIM(I17))=0),"Falta citar la fuente",IF(AND(N17="No figura en la fuente",LEN(TRIM(Q17))=0),"Explica dónde buscaste",IF(AND(N17<>"Pendiente",P17=""),"Falta la fecha",""))))
A18: 15 | B18: horario_mesa_partes | C18: Trámites documentarios | D18: Media | E18: Portal o directorio institucional | F18: Sí | G18: Mesa de partes atiende de lunes a viernes en el horario de oficina de la municipalidad. | H18: Horario vigente exacto de atención de mesa de partes. | I18: Sedes de la MPSR-J en gob.pe: https://www.gob.pe/institucion/munisanroman/sedes | M18: Horario de mesa de partes: lunes a viernes, 8:00 a. m. a 4:00 p. m. (Sedes en gob.pe). El aviso de mpv.mpsr.pe indica 9:00 a. m.–5:00 p. m. y parece desactualizado (cita el D.S. 044-2020-PCM). | N18: Corregir | O18: La mesa de partes atiende de lunes a viernes, de 8:00 a. m. a 4:00 p. m. | P18: 46300 | Q18: Búsqueda asistida (5/10/2026). Confirmar aparte el horario de la mesa de partes virtual. | R18: =IF(AND(N18="Corregir",LEN(TRIM(O18))=0),"Falta el texto corregido",IF(AND(OR(N18="Coincide",N18="Corregir"),LEN(TRIM(I18))=0),"Falta citar la fuente",IF(AND(N18="No figura en la fuente",LEN(TRIM(Q18))=0),"Explica dónde buscaste",IF(AND(N18<>"Pendiente",P18=""),"Falta la fecha",""))))
A19: 16 | B19: copia_documento | C19: Trámites documentarios | D19: Alta | E19: TUPA | F19: Sí | G19: Para obtener una copia certificada de un documento presentado anteriormente, debes solicitarlo en mesa de partes indicando el número de expediente, y abonar la tasa correspondiente. | H19: Procedimiento de copia certificada o fedateada; requisitos, costo por folio y plazo. | N19: Pendiente | R19: =IF(AND(N19="Corregir",LEN(TRIM(O19))=0),"Falta el texto corregido",IF(AND(OR(N19="Coincide",N19="Corregir"),LEN(TRIM(I19))=0),"Falta citar la fuente",IF(AND(N19="No figura en la fuente",LEN(TRIM(Q19))=0),"Explica dónde buscaste",IF(AND(N19<>"Pendiente",P19=""),"Falta la fecha",""))))
A20: 17 | B20: certificado_posesion | C20: Trámites documentarios | D20: Alta | E20: TUPA | F20: Sí | G20: El certificado de posesión se tramita presentando una declaración jurada, croquis del predio y documentos que acrediten la posesión pacífica del terreno. | H20: Requisitos, costo, plazo y área responsable. | N20: Pendiente | R20: =IF(AND(N20="Corregir",LEN(TRIM(O20))=0),"Falta el texto corregido",IF(AND(OR(N20="Coincide",N20="Corregir"),LEN(TRIM(I20))=0),"Falta citar la fuente",IF(AND(N20="No figura en la fuente",LEN(TRIM(Q20))=0),"Explica dónde buscaste",IF(AND(N20<>"Pendiente",P20=""),"Falta la fecha",""))))
A21: 18 | B21: constancia_domiciliaria | C21: Trámites documentarios | D21: Alta | E21: TUPA | F21: Sí | G21: La constancia domiciliaria se tramita presentando tu DNI y un recibo de servicio (luz o agua) a tu nombre o de un familiar directo que viva contigo. | H21: Requisitos, costo y plazo; si la emite la MPSR u otra entidad. | N21: Pendiente | R21: =IF(AND(N21="Corregir",LEN(TRIM(O21))=0),"Falta el texto corregido",IF(AND(OR(N21="Coincide",N21="Corregir"),LEN(TRIM(I21))=0),"Falta citar la fuente",IF(AND(N21="No figura en la fuente",LEN(TRIM(Q21))=0),"Explica dónde buscaste",IF(AND(N21<>"Pendiente",P21=""),"Falta la fecha",""))))
A22: 19 | B22: certificado_defensa_civil | C22: Defensa civil y seguridad ciudadana | D22: Alta | E22: TUPA | F22: Sí | G22: El certificado de Defensa Civil (ITSE) se tramita presentando el plano de distribución del local, el certificado de medidas de seguridad y el pago de la tasa correspondiente. | H22: Tipos de inspección (básica o detallada), requisitos, costo y plazo. | I22: Resolución Gerencial N.° 013-2024-MPSR-J/GEMU (caso concreto): https://cdn.www.gob.pe/uploads/document/file/5763090/5119677-resolucion-gerencial-n-013-2024-mpsr-j-gemu.PDF | L22: La ITSE previa a la licencia tiene vigencia de 2 años desde su expedición (resolución citada). | M22: Subgerencia de Gestión del Riesgo de Desastres. | N22: Pendiente | Q22: Búsqueda asistida (5/10/2026). Es un caso concreto: confirmar la regla general, los requisitos y el costo en el TUPA. | R22: =IF(AND(N22="Corregir",LEN(TRIM(O22))=0),"Falta el texto corregido",IF(AND(OR(N22="Coincide",N22="Corregir"),LEN(TRIM(I22))=0),"Falta citar la fuente",IF(AND(N22="No figura en la fuente",LEN(TRIM(Q22))=0),"Explica dónde buscaste",IF(AND(N22<>"Pendiente",P22=""),"Falta la fecha",""))))
A23: 20 | B23: inspeccion_tecnica | C23: Defensa civil y seguridad ciudadana | D23: Alta | E23: TUPA | F23: Sí | G23: Para solicitar una inspección técnica de seguridad (ITSE) debes presentar tu solicitud en mesa de partes; un inspector de Defensa Civil coordinará una visita al local. | H23: Cómo se solicita la ITSE, quién inspecciona, costo y plazos. | I23: Resolución Gerencial N.° 013-2024-MPSR-J/GEMU (caso concreto): https://cdn.www.gob.pe/uploads/document/file/5763090/5119677-resolucion-gerencial-n-013-2024-mpsr-j-gemu.PDF | L23: La ITSE previa a la licencia tiene vigencia de 2 años desde su expedición (resolución citada, local de riesgo muy alto). | M23: Inspección acreditada por un inspector de INDECI y la Subgerencia de Gestión del Riesgo de Desastres. | N23: Pendiente | Q23: Búsqueda asistida (5/10/2026). Es un caso concreto: confirmar la regla general, los requisitos y el costo en el TUPA. | R23: =IF(AND(N23="Corregir",LEN(TRIM(O23))=0),"Falta el texto corregido",IF(AND(OR(N23="Coincide",N23="Corregir"),LEN(TRIM(I23))=0),"Falta citar la fuente",IF(AND(N23="No figura en la fuente",LEN(TRIM(Q23))=0),"Explica dónde buscaste",IF(AND(N23<>"Pendiente",P23=""),"Falta la fecha",""))))
A24: 21 | B24: requisitos_defensa_civil | C24: Defensa civil y seguridad ciudadana | D24: Alta | E24: TUPA | F24: Sí | G24: Los requisitos de Defensa Civil incluyen: plano de distribución, certificado de medición eléctrica, extintores vigentes y señalización de seguridad, entre otros, según el tipo de establecimiento. | H24: Lista de requisitos según el nivel de riesgo. | N24: Pendiente | R24: =IF(AND(N24="Corregir",LEN(TRIM(O24))=0),"Falta el texto corregido",IF(AND(OR(N24="Coincide",N24="Corregir"),LEN(TRIM(I24))=0),"Falta citar la fuente",IF(AND(N24="No figura en la fuente",LEN(TRIM(Q24))=0),"Explica dónde buscaste",IF(AND(N24<>"Pendiente",P24=""),"Falta la fecha",""))))
A25: 22 | B25: denuncia_seguridad_ciudadana | C25: Defensa civil y seguridad ciudadana | D25: Media | E25: Portal o directorio institucional | F25: No | G25: Para reportar un problema de seguridad ciudadana puedes comunicarte con serenazgo o acudir a la comisaría más cercana si se trata de una emergencia. | H25: Canal de denuncia (serenazgo, teléfono, aplicación) y número vigente. | I25: Página «Contactos» del portal: https://munisanroman.gob.pe/web/contactos/ | M25: Serenazgo: (051) 329001, (051) 329002 y (051) 329003. | N25: Corregir | O25: Para reportar un problema de seguridad ciudadana puedes comunicarte con serenazgo de la MPSR al (051) 329001, (051) 329002 o (051) 329003, o acudir a la comisaría más cercana si se trata de una emergencia. | P25: 46300 | Q25: Búsqueda asistida (5/10/2026). Esta respuesta no tenía marca [Verificar] en el repositorio. Confirmar que los números siguen activos. | R25: =IF(AND(N25="Corregir",LEN(TRIM(O25))=0),"Falta el texto corregido",IF(AND(OR(N25="Coincide",N25="Corregir"),LEN(TRIM(I25))=0),"Falta citar la fuente",IF(AND(N25="No figura en la fuente",LEN(TRIM(Q25))=0),"Explica dónde buscaste",IF(AND(N25<>"Pendiente",P25=""),"Falta la fecha",""))))
A26: 23 | B26: serenazgo_contacto | C26: Defensa civil y seguridad ciudadana | D26: Media | E26: Portal o directorio institucional | F26: Sí | G26: Puedes comunicarte con serenazgo de la MPSR a través de su línea de atención. | H26: Número telefónico vigente de serenazgo y horario. | I26: Página «Contactos» del portal: https://munisanroman.gob.pe/web/contactos/ | M26: Serenazgo: (051) 329001, (051) 329002 y (051) 329003. | N26: Corregir | O26: Puedes comunicarte con serenazgo de la MPSR a los teléfonos (051) 329001, (051) 329002 o (051) 329003. | P26: 46300 | Q26: Búsqueda asistida (5/10/2026). La página no muestra fecha: confirmar con una llamada de prueba que los números siguen activos. | R26: =IF(AND(N26="Corregir",LEN(TRIM(O26))=0),"Falta el texto corregido",IF(AND(OR(N26="Coincide",N26="Corregir"),LEN(TRIM(I26))=0),"Falta citar la fuente",IF(AND(N26="No figura en la fuente",LEN(TRIM(Q26))=0),"Explica dónde buscaste",IF(AND(N26<>"Pendiente",P26=""),"Falta la fecha",""))))
A27: 24 | B27: partida_nacimiento | C27: Registro civil | D27: Alta | E27: TUPA | F27: Sí | G27: Puedes solicitar una copia de tu partida de nacimiento en la oficina de Registro Civil, presentando tu DNI y abonando la tasa correspondiente. | H27: Requisitos, costo de la copia certificada y plazo; si se emite en la MPSR. | I27: gob.pe — «Solicitar partida de nacimiento en San Román - Juliaca»: https://www.gob.pe/17146-solicitar-partida-de-nacimiento-en-san-roman-juliaca ; variante con S/ 6.84: https://www.gob.pe/51225-solicitar-una-partida-de-nacimiento-en-la-municipalidad?child=80860 | J27: Fecha de nacimiento; DNI del padre o madre que hace el trámite (opcional). | K27: S/ 6.66 (página 17146, la más antigua) o S/ 6.84 por copia certificada (página 51225): los montos difieren. | L27: Entrega inmediata. | M27: Caja de la municipalidad y Subgerencia de Registro Civil, Jr. Jáuregui 321; lunes a viernes, 8:30 a. m. a 1:00 p. m. | N27: Pendiente | Q27: Búsqueda asistida (5/10/2026). Falta confirmar el monto en el TUPA 2025 (Anexo 01). Texto propuesto, sin monto: «Puedes solicitar la copia de tu partida de nacimiento en la Subgerencia de Registro Civil (Jr. Jáuregui 321), de lunes a viernes de 8:30 a. m. a 1:00 p. m. Indica la fecha de nacimiento y paga la tasa en caja; la entrega es inmediata.» | R27: =IF(AND(N27="Corregir",LEN(TRIM(O27))=0),"Falta el texto corregido",IF(AND(OR(N27="Coincide",N27="Corregir"),LEN(TRIM(I27))=0),"Falta citar la fuente",IF(AND(N27="No figura en la fuente",LEN(TRIM(Q27))=0),"Explica dónde buscaste",IF(AND(N27<>"Pendiente",P27=""),"Falta la fecha",""))))
A28: 25 | B28: partida_matrimonio | C28: Registro civil | D28: Alta | E28: TUPA | F28: Sí | G28: La partida de matrimonio se solicita en la oficina de Registro Civil, indicando los datos del matrimonio (fecha, nombres de los contrayentes) y presentando tu DNI. | H28: Requisitos, costo de la copia certificada y plazo. | I28: gob.pe lista el servicio «Solicitar copia de partida de matrimonio ante la Municipalidad Provincial de Juliaca» (https://www.gob.pe/institucion/munisanroman/tramites-y-servicios), pero no pude leer su contenido. | N28: Pendiente | Q28: Búsqueda asistida (5/10/2026). El monto de S/ 10.00 que apareció en una página genérica de gob.pe NO se pudo atribuir a la MPSR: no usarlo. Revisar el servicio de la MPSR y el TUPA. | R28: =IF(AND(N28="Corregir",LEN(TRIM(O28))=0),"Falta el texto corregido",IF(AND(OR(N28="Coincide",N28="Corregir"),LEN(TRIM(I28))=0),"Falta citar la fuente",IF(AND(N28="No figura en la fuente",LEN(TRIM(Q28))=0),"Explica dónde buscaste",IF(AND(N28<>"Pendiente",P28=""),"Falta la fecha",""))))
A29: 26 | B29: partida_defuncion | C29: Registro civil | D29: Alta | E29: TUPA | F29: Sí | G29: Para inscribir o solicitar una partida de defunción debes presentar el certificado médico de defunción y el DNI del fallecido, en la oficina de Registro Civil. | H29: Diferencia entre inscribir y pedir copia; requisitos, costo y plazo. | I29: gob.pe — «Registrar una defunción en la municipalidad», variante con la Subgerencia de Registro Civil en Jr. Jáuregui 321: https://www.gob.pe/21525-obtener-acta-de-defuncion?child=17256 | J29: Certificado de defunción emitido por un médico; DNI del fallecido y del declarante (si no hay DNI del fallecido, declaración jurada). Si la muerte fue violenta: parte policial. | K29: Gratuito (primera inscripción). | M29: Subgerencia de Registro Civil, Jr. Jáuregui 321; lunes a viernes, 8:30 a. m. a 1:00 p. m.; presencial. | N29: Corregir | O29: Para inscribir una defunción debes acudir a la Subgerencia de Registro Civil (Jr. Jáuregui 321), de lunes a viernes de 8:30 a. m. a 1:00 p. m., con el certificado de defunción emitido por un médico, tu DNI y el DNI del fallecido. Si la muerte fue violenta, lleva también el parte policial. La primera inscripción es gratuita. | P29: 46300 | Q29: Búsqueda asistida (5/10/2026). La página es genérica de gob.pe pero trae la dirección y el horario de la MPSR; confirmar en el TUPA. No apareció el costo de una copia de partida de defunción ya inscrita. | R29: =IF(AND(N29="Corregir",LEN(TRIM(O29))=0),"Falta el texto corregido",IF(AND(OR(N29="Coincide",N29="Corregir"),LEN(TRIM(I29))=0),"Falta citar la fuente",IF(AND(N29="No figura en la fuente",LEN(TRIM(Q29))=0),"Explica dónde buscaste",IF(AND(N29<>"Pendiente",P29=""),"Falta la fecha",""))))
A30: 27 | B30: rectificacion_partida | C30: Registro civil | D30: Alta | E30: TUPA | F30: Sí | G30: Para rectificar un dato en una partida debes presentar una solicitud en Registro Civil junto con los documentos que sustenten la corrección (DNI, partida original, entre otros). | H30: Si es administrativa o judicial; requisitos, costo y plazo. | N30: Pendiente | R30: =IF(AND(N30="Corregir",LEN(TRIM(O30))=0),"Falta el texto corregido",IF(AND(OR(N30="Coincide",N30="Corregir"),LEN(TRIM(I30))=0),"Falta citar la fuente",IF(AND(N30="No figura en la fuente",LEN(TRIM(Q30))=0),"Explica dónde buscaste",IF(AND(N30<>"Pendiente",P30=""),"Falta la fecha",""))))
A31: 28 | B31: requisitos_matrimonio_civil | C31: Registro civil | D31: Alta | E31: TUPA | F31: Sí | G31: Para matrimonio civil se requiere: DNI de ambos contrayentes, certificados de nacimiento actualizados, y en algunos casos certificado médico prenupcial. | H31: Requisitos, publicación de edictos, costo, plazo y fechas de celebración. | N31: Pendiente | R31: =IF(AND(N31="Corregir",LEN(TRIM(O31))=0),"Falta el texto corregido",IF(AND(OR(N31="Coincide",N31="Corregir"),LEN(TRIM(I31))=0),"Falta citar la fuente",IF(AND(N31="No figura en la fuente",LEN(TRIM(Q31))=0),"Explica dónde buscaste",IF(AND(N31<>"Pendiente",P31=""),"Falta la fecha",""))))
A32: 29 | B32: horario_recojo_basura | C32: Servicios públicos | D32: Media | E32: Portal o directorio institucional | F32: No | G32: El horario de recojo de basura varía según el sector de la ciudad. Puedes consultar el cronograma vigente en la municipalidad o en sus redes sociales. | H32: Cronograma por sector o ruta; canal oficial donde se publica. | N32: Pendiente | R32: =IF(AND(N32="Corregir",LEN(TRIM(O32))=0),"Falta el texto corregido",IF(AND(OR(N32="Coincide",N32="Corregir"),LEN(TRIM(I32))=0),"Falta citar la fuente",IF(AND(N32="No figura en la fuente",LEN(TRIM(Q32))=0),"Explica dónde buscaste",IF(AND(N32<>"Pendiente",P32=""),"Falta la fecha",""))))
A33: 30 | B33: reporte_alumbrado_publico | C33: Servicios públicos | D33: Media | E33: Portal o directorio institucional | F33: Sí | G33: Para reportar una falla de alumbrado público puedes comunicarte con el área de Servicios Públicos de la MPSR, indicando la ubicación exacta del poste o farola. | H33: Canal de reporte (teléfono, WhatsApp o mesa de partes) y área responsable. | N33: Pendiente | R33: =IF(AND(N33="Corregir",LEN(TRIM(O33))=0),"Falta el texto corregido",IF(AND(OR(N33="Coincide",N33="Corregir"),LEN(TRIM(I33))=0),"Falta citar la fuente",IF(AND(N33="No figura en la fuente",LEN(TRIM(Q33))=0),"Explica dónde buscaste",IF(AND(N33<>"Pendiente",P33=""),"Falta la fecha",""))))
A34: 31 | B34: mantenimiento_parques | C34: Servicios públicos | D34: Media | E34: TUPA o portal | F34: Sí | G34: Puedes solicitar el mantenimiento de un parque presentando tu pedido en mesa de partes o comunicándote con el área de Servicios Públicos, indicando la ubicación del parque. | H34: Procedimiento para pedirlo (si figura como servicio); área responsable. | N34: Pendiente | R34: =IF(AND(N34="Corregir",LEN(TRIM(O34))=0),"Falta el texto corregido",IF(AND(OR(N34="Coincide",N34="Corregir"),LEN(TRIM(I34))=0),"Falta citar la fuente",IF(AND(N34="No figura en la fuente",LEN(TRIM(Q34))=0),"Explica dónde buscaste",IF(AND(N34<>"Pendiente",P34=""),"Falta la fecha",""))))
A35: 32 | B35: poda_arboles | C35: Servicios públicos | D35: Media | E35: TUPA o portal | F35: Sí | G35: La poda de árboles públicos se solicita ante el área de Servicios Públicos de la MPSR, indicando la ubicación exacta del árbol. | H35: Procedimiento, requisitos y costo si aplica; área responsable. | N35: Pendiente | R35: =IF(AND(N35="Corregir",LEN(TRIM(O35))=0),"Falta el texto corregido",IF(AND(OR(N35="Coincide",N35="Corregir"),LEN(TRIM(I35))=0),"Falta citar la fuente",IF(AND(N35="No figura en la fuente",LEN(TRIM(Q35))=0),"Explica dónde buscaste",IF(AND(N35<>"Pendiente",P35=""),"Falta la fecha",""))))
A36: 33 | B36: limpieza_via_publica | C36: Servicios públicos | D36: Media | E36: Portal o directorio institucional | F36: Sí | G36: Para solicitar limpieza de una vía pública puedes comunicarte con el área de limpieza pública de la MPSR, indicando la calle y cuadra exacta. | H36: Canal y área responsable de limpieza pública. | N36: Pendiente | R36: =IF(AND(N36="Corregir",LEN(TRIM(O36))=0),"Falta el texto corregido",IF(AND(OR(N36="Coincide",N36="Corregir"),LEN(TRIM(I36))=0),"Falta citar la fuente",IF(AND(N36="No figura en la fuente",LEN(TRIM(Q36))=0),"Explica dónde buscaste",IF(AND(N36<>"Pendiente",P36=""),"Falta la fecha",""))))
A37: 34 | B37: presentar_reclamo | C37: Reclamos y quejas | D37: Alta | E37: TUPA o portal | F37: Sí | G37: Puedes presentar un reclamo en mesa de partes, mediante un escrito simple indicando los hechos y adjuntando tu DNI, o a través del libro de reclamaciones si corresponde. | H37: Procedimiento, formato, plazo de respuesta y canal virtual si existe. | N37: Pendiente | R37: =IF(AND(N37="Corregir",LEN(TRIM(O37))=0),"Falta el texto corregido",IF(AND(OR(N37="Coincide",N37="Corregir"),LEN(TRIM(I37))=0),"Falta citar la fuente",IF(AND(N37="No figura en la fuente",LEN(TRIM(Q37))=0),"Explica dónde buscaste",IF(AND(N37<>"Pendiente",P37=""),"Falta la fecha",""))))
A38: 35 | B38: estado_reclamo | C38: Reclamos y quejas | D38: Media | E38: Portal o directorio institucional | F38: Sí | G38: El estado de tu reclamo puede consultarse en mesa de partes indicando tu número de expediente. | H38: Cómo consultar el estado de un reclamo. | N38: Pendiente | R38: =IF(AND(N38="Corregir",LEN(TRIM(O38))=0),"Falta el texto corregido",IF(AND(OR(N38="Coincide",N38="Corregir"),LEN(TRIM(I38))=0),"Falta citar la fuente",IF(AND(N38="No figura en la fuente",LEN(TRIM(Q38))=0),"Explica dónde buscaste",IF(AND(N38<>"Pendiente",P38=""),"Falta la fecha",""))))
A39: 36 | B39: libro_reclamaciones | C39: Reclamos y quejas | D39: Media | E39: Portal o directorio institucional | F39: Sí | G39: El libro de reclamaciones está disponible en la Plataforma de Atención; también puede existir una versión virtual. | H39: Si existe libro de reclamaciones virtual, su enlace, y dónde está el físico. | I39: Portal MPSR-J en gob.pe (enlace «Libro de reclamaciones»): https://www.gob.pe/munisanroman ; portal https://munisanroman.gob.pe/web/ ; Resolución de Gerencia N.° 008-2023-MPSR-J/GSG, que menciona el Libro de Reclamaciones Digital: https://cdn.www.gob.pe/uploads/document/file/6752782/5855545-resolucion-de-gerencia-n-008-2023-mpsr-j-gsg.PDF | M39: Libro de reclamaciones digital, accesible desde el portal. | N39: Corregir | O39: La Municipalidad Provincial de San Román cuenta con un Libro de Reclamaciones virtual, al que puedes entrar desde su portal institucional o desde su página en gob.pe (gob.pe/munisanroman). | P39: 46300 | Q39: Búsqueda asistida (5/10/2026). No encontré si además existe libro físico ni en qué oficina. Se quitó la mención a la «Plataforma de Atención» porque no aparece en ninguna fuente vista. | R39: =IF(AND(N39="Corregir",LEN(TRIM(O39))=0),"Falta el texto corregido",IF(AND(OR(N39="Coincide",N39="Corregir"),LEN(TRIM(I39))=0),"Falta citar la fuente",IF(AND(N39="No figura en la fuente",LEN(TRIM(Q39))=0),"Explica dónde buscaste",IF(AND(N39<>"Pendiente",P39=""),"Falta la fecha",""))))
A40: 37 | B40: queja_atencion | C40: Reclamos y quejas | D40: Media | E40: TUPA o portal | F40: Sí | G40: Si tuviste un problema con la atención recibida, puedes presentar tu queja en mesa de partes o directamente en el libro de reclamaciones, detallando lo ocurrido. | H40: Procedimiento de queja y plazo de respuesta. | N40: Pendiente | R40: =IF(AND(N40="Corregir",LEN(TRIM(O40))=0),"Falta el texto corregido",IF(AND(OR(N40="Coincide",N40="Corregir"),LEN(TRIM(I40))=0),"Falta citar la fuente",IF(AND(N40="No figura en la fuente",LEN(TRIM(Q40))=0),"Explica dónde buscaste",IF(AND(N40<>"Pendiente",P40=""),"Falta la fecha",""))))
...

Sheet Resumen
A1: Resumen de la verificación
A2: Todo son fórmulas sobre la pestaña Verificacion.
A4: Avance
A5: Respuestas a verificar | B5: =COUNTA(Verificacion!$B$4:$B$47) -> 44
A6: Pendiente | B6: =COUNTIF(Verificacion!$N$4:$N$47,"Pendiente") -> 34
A7: Coincide | B7: =COUNTIF(Verificacion!$N$4:$N$47,"Coincide") -> 0
A8: Corregir | B8: =COUNTIF(Verificacion!$N$4:$N$47,"Corregir") -> 10
A9: No figura en la fuente | B9: =COUNTIF(Verificacion!$N$4:$N$47,"No figura en la fuente") -> 0
A10: Verificadas (todo menos Pendiente) | B10: =B5-B6 -> 10
A11: Avance | B11: =IF(B5=0,"",B10/B5) -> 0.22727273
A13: Pendientes por prioridad
A14: Prioridad Alta pendientes | B14: =COUNTIFS(Verificacion!$D$4:$D$47,"Alta",Verificacion!$N$4:$N$47,"Pendiente") -> 23 | C14: Costos, plazos, requisitos y tasas: lo que más daño hace si está mal.
A15: Prioridad Media pendientes | B15: =COUNTIFS(Verificacion!$D$4:$D$47,"Media",Verificacion!$N$4:$N$47,"Pendiente") -> 11 | C15: Canales, horarios, teléfonos y cronogramas.
A17: Calidad del llenado
A18: Filas con alerta | B18: =COUNTIF(Verificacion!$R$4:$R$47,"?*") -> 0 | C18: Debe ser 0 antes de entregar el archivo.
A19: Marcadas [Verificar] en el repositorio | B19: =COUNTIF(Verificacion!$F$4:$F$47,"Sí") -> 40 | C19: Según el reporte de Claude Code: 40 de 44.
A20: Corregir o Coincide sin confirmar por el tesista | B20: =COUNTIFS(Verificacion!$N$4:$N$47,"Corregir",Verificacion!$S$4:$S$47,"<>Sí")+COUNTIFS(Verificacion!$N$4:$N$47,"Coincide",Verificacion!$S$4:$S$47,"<>Sí") -> 10 | C20: Claude Code solo aplica las filas con «Confirmado por el tesista = Sí». Las filas llenadas por búsqueda asistida llegan sin confirmar.
A21: Estado general | B21: =IF(AND(B6=0,B18=0,B20=0),"Listo para actualizar domain.yml","Aún no") -> Aún no
A23: Por categoría (pendientes / total)
A24: Licencias y autorizaciones | B24: =COUNTIFS(Verificacion!$C$4:$C$47,A24,Verificacion!$N$4:$N$47,"Pendiente")&" / "&COUNTIF(Verificacion!$C$4:$C$47,A24) -> 6 / 6
A25: Tributos y pagos municipales | B25: =COUNTIFS(Verificacion!$C$4:$C$47,A25,Verificacion!$N$4:$N$47,"Pendiente")&" / "&COUNTIF(Verificacion!$C$4:$C$47,A25) -> 6 / 6
A26: Trámites documentarios | B26: =COUNTIFS(Verificacion!$C$4:$C$47,A26,Verificacion!$N$4:$N$47,"Pendiente")&" / "&COUNTIF(Verificacion!$C$4:$C$47,A26) -> 4 / 6
A27: Defensa civil y seguridad ciudadana | B27: =COUNTIFS(Verificacion!$C$4:$C$47,A27,Verificacion!$N$4:$N$47,"Pendiente")&" / "&COUNTIF(Verificacion!$C$4:$C$47,A27) -> 3 / 5
A28: Registro civil | B28: =COUNTIFS(Verificacion!$C$4:$C$47,A28,Verificacion!$N$4:$N$47,"Pendiente")&" / "&COUNTIF(Verificacion!$C$4:$C$47,A28) -> 4 / 5
A29: Servicios públicos | B29: =COUNTIFS(Verificacion!$C$4:$C$47,A29,Verificacion!$N$4:$N$47,"Pendiente")&" / "&COUNTIF(Verificacion!$C$4:$C$47,A29) -> 5 / 5
A30: Reclamos y quejas | B30: =COUNTIFS(Verificacion!$C$4:$C$47,A30,Verificacion!$N$4:$N$47,"Pendiente")&" / "&COUNTIF(Verificacion!$C$4:$C$47,A30) -> 4 / 5
A31: Información general | B31: =COUNTIFS(Verificacion!$C$4:$C$47,A31,Verificacion!$N$4:$N$47,"Pendiente")&" / "&COUNTIF(Verificacion!$C$4:$C$47,A31) -> 2 / 6

Sheet Fuentes
A1: Fuentes oficiales para verificar
A2: Encontradas en una búsqueda en octubre de 2026. No pude abrir las páginas desde aquí (la plataforma bloqueó la consulta), así que confirma que abren y que son las versiones vigentes antes de citarlas.
A3: Fuente | B3: Enlace | C3: Qué contiene o para qué sirve | D3: Nota
A4: TUPA vigente de la MPSR-J (Ordenanza Municipal N.° 022-2025-CMPSR-J, 29/09/2025) | B4: https://www.gob.pe/institucion/munisanroman/informes-publicaciones/7272473 | C4: Texto del TUPA (partes 01 a 05), «Anexo 01: resumen de los derechos de tramitación» y los reportes del SUT (25/08/2025 y 03/12/2025). | D4: Fuente principal. Usa el reporte SUT más reciente.
A5: Decreto de Alcaldía N.° 011-2025-MPSR-J/A (03/12/2025) | B5: https://www.gob.pe/institucion/munisanroman/normas-legales/7495467-011-2025-mpsr-j-a | C5: Modifica el TUPA reduciendo derechos de tramitación en 7 procedimientos. | D5: Por lo que se alcanza a leer, es en materia de transporte; confirma si alguno de los 7 es de los tuyos.
A6: Decreto de Alcaldía N.° 011-2025 (PDF) | B6: https://cdn.www.gob.pe/uploads/document/file/9134774/7495467-decreto-de-alcaldia-n-011-2025-mpsr-j-a.PDF | C6: Texto completo del decreto y su anexo.
A7: Normas y documentos legales de la MPSR-J | B7: https://www.gob.pe/institucion/munisanroman/normas-legales | C7: Para buscar modificaciones del TUPA posteriores a diciembre de 2025 y las ordenanzas tributarias (arbitrios, predial). | D7: Revisa si hay decretos u ordenanzas de 2026.
A8: Portal de la MPSR-J en gob.pe | B8: https://www.gob.pe/munisanroman | C8: Mesa de partes, seguimiento de trámites, libro de reclamaciones y enlaces del TUPA. | D8: Sirve para canales, horarios y direcciones.
A9: TUPA 2023 con procedimientos estandarizados (histórico) | B9: https://www.gob.pe/institucion/munisanroman/informes-publicaciones/4275606-texto-unico-de-procedimientos-administrativos-tupa-2023-con-procedimientos-estandarizados | C9: Versión anterior del TUPA (Ordenanza Municipal N.° 009-2023-CMPSRJ). | D9: NO usar como vigente; solo para comparar.
A10: Sedes de la MPSR-J en gob.pe | B10: https://www.gob.pe/institucion/munisanroman/sedes | C10: Dirección, central telefónica y horarios de atención y de mesa de partes (8:00 a. m.–4:00 p. m.). | D10: Oficial.
A11: Contactos del portal institucional | B11: https://munisanroman.gob.pe/web/contactos/ | C11: Central (051) 321201, serenazgo (051) 329001/329002/329003 y horario con pausa de 1:00 a 2:00 p. m. | D11: Oficial; sin fecha.
A12: gob.pe — Solicitar partida de nacimiento en San Román - Juliaca | B12: https://www.gob.pe/17146-solicitar-partida-de-nacimiento-en-san-roman-juliaca | C12: Requisitos, pago de S/ 6.66, entrega inmediata y horario 8:30–1:00. | D12: Página con varios años de antigüedad.
A13: gob.pe — Solicitar una partida de nacimiento (variante) | B13: https://www.gob.pe/51225-solicitar-una-partida-de-nacimiento-en-la-municipalidad?child=80860 | C13: Misma oficina y horario, pero con S/ 6.84 por copia certificada. | D13: Los dos montos difieren.
A14: gob.pe — Registrar una defunción en la municipalidad | B14: https://www.gob.pe/21525-obtener-acta-de-defuncion?child=17256 | C14: Requisitos, gratuidad de la primera inscripción, dirección y horario de Registro Civil. | D14: Página genérica con datos de la MPSR.
A15: Nota de prensa sobre licencias de funcionamiento digitales | B15: https://pachamamaradio.org/san-roman-implementa-licencias-de-funcionamiento-digitales-a-partir-del-20-de-agosto/ | C15: Licencias digitales con QR y firma electrónica desde el 20 de agosto (2025); costos y requisitos sin cambios. | D15: NO oficial.
A16: Resolución Gerencial N.° 013-2024-MPSR-J/GEMU | B16: https://cdn.www.gob.pe/uploads/document/file/5763090/5119677-resolucion-gerencial-n-013-2024-mpsr-j-gemu.PDF | C16: Caso concreto de ITSE previa a la licencia: vigencia de 2 años; inspección con INDECI y la Subgerencia de Gestión del Riesgo de Desastres. | D16: Oficial; caso particular.
A17: Mesa de partes virtual | B17: https://www.mpv.mpsr.pe/ | C17: Aviso de recepción de documentos escaneados y lista de trámites que no atiende. | D17: Posiblemente desactualizado (cita el D.S. 044-2020-PCM).

Sheet Parametros
A1: Listas
A3: Resultado | B3: Significado
A4: Pendiente | B4: Aún no se comparó con la fuente.
A5: Coincide | B5: La respuesta actual es correcta según la fuente.
A6: Corregir | B6: Hay que cambiar algo: escribe el texto corregido.
A7: No figura en la fuente | B7: No encontraste el dato en la fuente: explica dónde buscaste.

Sheet Notas
A1: Notas de uso
A3: Cómo usar
A4: 1. Abre el TUPA vigente (pestaña Fuentes) y busca cada trámite por su nombre. Empieza por las filas de prioridad Alta.
A5: 2. Anota en las celdas amarillas lo que dice la fuente: nombre y página del procedimiento, requisitos, costo, plazo, y oficina o canal. Copia los datos tal cual; no los completes de memoria.
A6: 3. Elige el Resultado: «Coincide» si la respuesta actual es correcta; «Corregir» si algo difiere (escribe el texto corregido); «No figura en la fuente» si no lo encuentras (explica dónde buscaste en Observaciones).
A7: 4. El texto corregido va en lenguaje claro, como si se lo dijeras a un ciudadano, y sin la marca [Verificar]. Indica la fecha de la verificación.
A8: 5. Marca «Confirmado por el tesista = Sí» solo en las filas que comprobaste tú contra la fuente. Claude Code aplicará a domain.yml únicamente las confirmadas; las filas llenadas por búsqueda asistida llegan sin confirmar.
A9: 6. Cuando el Resumen diga «Listo para actualizar domain.yml» (sin pendientes, alertas ni filas sin confirmar), guarda el archivo desde Excel y entrégaselo a Claude Code.
A11: Cosas a tener en cuenta
A12: • No todo está en el TUPA: impuestos y arbitrios se rigen por ordenanzas tributarias y la ley de tributación municipal; horarios, teléfonos y cronogramas están en el portal institucional. La columna «Fuente probable» orienta dónde mirar.
A13: • Los derechos de tramitación pueden venir en soles o como porcentaje de la UIT. Anota la unidad tal cual y, si es en UIT, el valor de la UIT que uses.
A14: • El TUPA se modifica por decreto de alcaldía u ordenanza. Revisa que tu fuente sea la versión más reciente.
... A28: • Colores: azul = valor escrito a mano o dato fijo; negro = fórmula; verde = vínculo a otra hoja.
