Workbook

Sheet Sesiones
A1: DATOS SIMULADOS — registro de sesiones piloto (ejemplo de prueba; no son sesiones reales)
A2: Código de sesión | B2: Fecha | C2: Aplicador | D2: Rango de edad | E2: ¿Vive en Juliaca? | F2: ¿Trámite presencial en la MPSR (12 meses)? | G2: Categoría del trámite | H2: Tiempo presencial (rango) | I2: Veces que volvió o hizo seguimiento | J2: Dif.: información no clara (1 = sí) | K2: Dif.: demora excesiva (1 = sí) | L2: Dif.: colas largas (1 = sí) | M2: Dif.: falta de orientación (1 = sí) | N2: Dif.: ninguna (1 = sí) | O2: Dif.: otra (1 = sí) | P2: Pre P7 atención presencial rápida | Q2: Pre P8 resolver dudas sin ir presencialmente | R2: Pre P9 requisitos claros | S2: Pre P10 satisfacción general | T2: Tarjeta 1 | U2: Tarjeta 2 | V2: Tarjeta 3 | W2: Consulta 1: texto escrito | X2: Consulta 1: tiempo hasta respuesta útil (s) | Y2: Consulta 1: mensajes enviados | Z2: Consulta 1: ¿la persona obtuvo lo que necesitaba? | AA2: Consulta 1: ¿respuesta correcta? (aplicador) | AB2: Consulta 1: ¿dijo «no entendí»? | AC2: Consulta 2: texto escrito | AD2: Consulta 2: tiempo hasta respuesta útil (s) | AE2: Consulta 2: mensajes enviados | AF2: Consulta 2: ¿la persona obtuvo lo que necesitaba? | AG2: Consulta 2: ¿respuesta correcta? (aplicador) | AH2: Consulta 2: ¿dijo «no entendí»? | AI2: Consulta 3: texto escrito | AJ2: Consulta 3: tiempo hasta respuesta útil (s) | AK2: Consulta 3: mensajes enviados | AL2: Consulta 3: ¿la persona obtuvo lo que necesitaba? | AM2: Consulta 3: ¿respuesta correcta? (aplicador) | AN2: Consulta 3: ¿dijo «no entendí»? | AO2: Post ítem 1: fácil de usar | AP2: Post ítem 2: tiempo adecuado | AQ2: Post ítem 3: respuestas claras | AR2: Post ítem 4: resolvió mi consulta | AS2: Post ítem 5: confío en la información | AT2: Post ítem 6: prefiero usarlo antes que ir presencialmente | AU2: Post ítem 7: lo usaría de nuevo | AV2: Post ítem 8: lo recomendaría | AW2: Post ítem 9: satisfacción general (pareada con P10) | AX2: Complementaria: tiempo presencial estimado para la consulta 1 | AY2: Incidencias técnicas | AZ2: Elegible y completa | BA2: Minutos pre (línea base) | BB2: Minutos post (promedio de 3 consultas) | BC2: Diferencia post − pre (min) | BD2: % de reducción | BE2: Satisfacción pre (P10) | BF2: Satisfacción post (ítem 9) | BG2: Diferencia de satisfacción | BH2: Consultas con respuesta útil (de 3) | BI2: Consultas correctas (de 3) | BJ2: Consultas con «no entendí» (de 3) | BK2: Total Likert ítems 1–8
A3: SA01 | B3: 46307.5 | C3: Aplicador DEMO | D3: 30–44 | E3: Sí | F3: Sí | G3: Licencias y autorizaciones | H3: 1–2 horas | I3: 1 vez | J3: 0 | K3: 0 | L3: 1 | M3: 1 | N3: 0 | O3: 0 | P3: 3 | Q3: 2 | R3: 3 | S3: 3 | T3: =INDEX(Tarjetas!$A$4:$A$59,MOD(3*(VALUE(MID(A3,3,2))-1)+0,ROWS(Tarjetas!$A$4:$A$59))+1) -> S01 | U3: =INDEX(Tarjetas!$A$4:$A$59,MOD(3*(VALUE(MID(A3,3,2))-1)+1,ROWS(Tarjetas!$A$4:$A$59))+1) -> S02 | V3: =INDEX(Tarjetas!$A$4:$A$59,MOD(3*(VALUE(MID(A3,3,2))-1)+2,ROWS(Tarjetas!$A$4:$A$59))+1) -> S03 | W3: [SIMULACIÓN — NO ES TRANSCRIPCIÓN] Vas a abrir una tiendita en tu barrio y no sabes qué papeles te van a pedir en la municipalidad para poder atender legalmente. | X3: 180 | Y3: 3 | Z3: No | AA3: No | AB3: No | AC3: [SIMULACIÓN — NO ES TRANSCRIPCIÓN] Ya sabes que necesitas un permiso de la municipalidad para tu negocio y quieres saber cuánto tendrías que pagar por él. | AD3: 44 | AE3: 2 | AF3: Sí | AG3: Sí | AH3: No | AI3: [SIMULACIÓN — NO ES TRANSCRIPCIÓN] Entregaste tus papeles para el permiso de tu negocio y quieres saber cuántos días demoran en dártelo. | AJ3: 65 | AK3: 1 | AL3: Sí | AM3: Parcial | AN3: No | AO3: 3 | AP3: 4 | AQ3: 3 | AR3: 3 | AS3: 4 | AT3: 4 | AU3: 4 | AV3: 4 | AW3: 4 | AX3: 1–2 horas | AY3: Ninguna | AZ3: =IF(COUNTA(B3,F3)=0,"",IF(AND(F3="Sí",H3<>"",S3<>"",COUNT(X3,AD3,AJ3)=3,COUNT(AO3:AV3)=8,AW3<>""),"Sí","No")) -> Sí | BA3: =IF(H3="","",IFERROR(INDEX(Parametros!$B$4:$B$9,MATCH(H3,Parametros!$A$4:$A$9,0)),"")) -> 90 | BB3: =IF(COUNT(X3,AD3,AJ3)=3,AVERAGE(X3,AD3,AJ3)/60,"") -> 1.6055556 | BC3: =IF(AND(ISNUMBER(BA3),ISNUMBER(BB3)),BB3-BA3,"") -> -88.394444 | BD3: =IF(AND(ISNUMBER(BA3),ISNUMBER(BB3)),IF(BA3>0,(BA3-BB3)/BA3,""),"") -> 0.98216049 | BE3: =IF(S3="","",S3) -> 3 | BF3: =IF(AW3="","",AW3) -> 4 | BG3: =IF(AND(ISNUMBER(BE3),ISNUMBER(BF3)),BF3-BE3,"") -> 1 | BH3: =IF(COUNTA(Z3,AF3,AL3)=0,"",(Z3="Sí")+(AF3="Sí")+(AL3="Sí")) -> 2 | BI3: =IF(COUNTA(AA3,AG3,AM3)=0,"",(AA3="Sí")+(AG3="Sí")+(AM3="Sí")) -> 1 | BJ3: =IF(COUNTA(AB3,AH3,AN3)=0,"",(AB3="Sí")+(AH3="Sí")+(AN3="Sí")) -> 0 | BK3: =IF(COUNT(AO3:AV3)=8,SUM(AO3:AV3),"") -> 29
A4: SA02 | B4: 46307.5 | C4: Aplicador DEMO | D4: 60 a más | E4: Sí | F4: Sí | G4: Licencias y autorizaciones | H4: 30–60 min | I4: Más de 3 veces | J4: 1 | K4: 0 | L4: 0 | M4: 1 | N4: 0 | O4: 0 | P4: 3 | Q4: 1 | R4: 2 | S4: 2 | T4: =INDEX(Tarjetas!$A$4:$A$59,MOD(3*(VALUE(MID(A4,3,2))-1)+0,ROWS(Tarjetas!$A$4:$A$59))+1) -> S04 | U4: =INDEX(Tarjetas!$A$4:$A$59,MOD(3*(VALUE(MID(A4,3,2))-1)+1,ROWS(Tarjetas!$A$4:$A$59))+1) -> S05 | V4: =INDEX(Tarjetas!$A$4:$A$59,MOD(3*(VALUE(MID(A4,3,2))-1)+2,ROWS(Tarjetas!$A$4:$A$59))+1) -> S06 | W4: [SIMULACIÓN — NO ES TRANSCRIPCIÓN] Quieres construir un segundo piso en tu casa y quieres saber qué documentos tendrías que presentar antes de empezar la obra. | X4: 26 | Y4: 1 | Z4: Sí | AA4: Sí | AB4: No | AC4: [SIMULACIÓN — NO ES TRANSCRIPCIÓN] Vas a construir en tu terreno y quieres saber cuánto cobra la municipalidad por autorizar la obra. | AD4: 33 | AE4: 2 | AF4: Sí | AG4: Parcial | AH4: No | AI4: [SIMULACIÓN — NO ES TRANSCRIPCIÓN] El permiso de funcionamiento de tu negocio ya se venció y quieres saber qué tienes que hacer para dejarlo vigente otra vez. | AJ4: 69 | AK4: 2 | AL4: Sí | AM4: Parcial | AN4: No | AO4: 3 | AP4: 3 | AQ4: 5 | AR4: 4 | AS4: 4 | AT4: 3 | AU4: 4 | AV4: 3 | AW4: 4 | AX4: 30–60 min | AY4: Ninguna | AZ4: =IF(COUNTA(B4,F4)=0,"",IF(AND(F4="Sí",H4<>"",S4<>"",COUNT(X4,AD4,AJ4)=3,COUNT(AO4:AV4)=8,AW4<>""),"Sí","No")) -> Sí | BA4: =IF(H4="","",IFERROR(INDEX(Parametros!$B$4:$B$9,MATCH(H4,Parametros!$A$4:$A$9,0)),"")) -> 45 | BB4: =IF(COUNT(X4,AD4,AJ4)=3,AVERAGE(X4,AD4,AJ4)/60,"") -> 0.71111111 | BC4: =IF(AND(ISNUMBER(BA4),ISNUMBER(BB4)),BB4-BA4,"") -> -44.288889 | BD4: =IF(AND(ISNUMBER(BA4),ISNUMBER(BB4)),IF(BA4>0,(BA4-BB4)/BA4,""),"") -> 0.98419753 | BE4: =IF(S4="","",S4) -> 2 | BF4: =IF(AW4="","",AW4) -> 4 | BG4: =IF(AND(ISNUMBER(BE4),ISNUMBER(BF4)),BF4-BE4,"") -> 2 | BH4: =IF(COUNTA(Z4,AF4,AL4)=0,"",(Z4="Sí")+(AF4="Sí")+(AL4="Sí")) -> 3 | BI4: =IF(COUNTA(AA4,AG4,AM4)=0,"",(AA4="Sí")+(AG4="Sí")+(AM4="Sí")) -> 1 | BJ4: =IF(COUNTA(AB4,AH4,AN4)=0,"",(AB4="Sí")+(AH4="Sí")+(AN4="Sí")) -> 0 | BK4: =IF(COUNT(AO4:AV4)=8,SUM(AO4:AV4),"") -> 29
A5: SA03 | B5: 46307.5 | C5: Aplicador DEMO | D5: 45–59 | E5: Sí | F5: Sí | G5: Tributos y pagos municipales | H5: 1–2 horas | I5: 2 a 3 veces | J5: 0 | K5: 0 | L5: 0 | M5: 1 | N5: 0 | O5: 0 | P5: 2 | Q5: 1 | R5: 2 | S5: 1 | T5: =INDEX(Tarjetas!$A$4:$A$59,MOD(3*(VALUE(MID(A5,3,2))-1)+0,ROWS(Tarjetas!$A$4:$A$59))+1) -> S07 | U5: =INDEX(Tarjetas!$A$4:$A$59,MOD(3*(VALUE(MID(A5,3,2))-1)+1,ROWS(Tarjetas!$A$4:$A$59))+1) -> S08 | V5: =INDEX(Tarjetas!$A$4:$A$59,MOD(3*(VALUE(MID(A5,3,2))-1)+2,ROWS(Tarjetas!$A$4:$A$59))+1) -> S09 | W5: [SIMULACIÓN — NO ES TRANSCRIPCIÓN] Quieres saber si debes impuestos por tu casa o terreno, y cuánto sería. | X5: 180 | Y5: 3 | Z5: No | AA5: Parcial | AB5: No | AC5: [SIMULACIÓN — NO ES TRANSCRIPCIÓN] Ya sabes que debes pagar el impuesto de tu casa y quieres saber dónde o de qué forma puedes hacerlo. | AD5: 69 | AE5: 1 | AF5: Sí | AG5: Sí | AH5: No | AI5: [SIMULACIÓN — NO ES TRANSCRIPCIÓN] Te llegó un cobro por el recojo de basura, la limpieza de calles y el serenazgo, y quieres saber cómo pagarlo. | AJ5: 180 | AK5: 3 | AL5: No | AM5: Parcial | AN5: No | AO5: 1 | AP5: 4 | AQ5: 3 | AR5: 1 | AS5: 2 | AT5: 3 | AU5: 2 | AV5: 2 | AW5: 3 | AX5: 1–2 horas | AY5: Ninguna | AZ5: =IF(COUNTA(B5,F5)=0,"",IF(AND(F5="Sí",H5<>"",S5<>"",COUNT(X5,AD5,AJ5)=3,COUNT(AO5:AV5)=8,AW5<>""),"Sí","No")) -> Sí | BA5: =IF(H5="","",IFERROR(INDEX(Parametros!$B$4:$B$9,MATCH(H5,Parametros!$A$4:$A$9,0)),"")) -> 90 | BB5: =IF(COUNT(X5,AD5,AJ5)=3,AVERAGE(X5,AD5,AJ5)/60,"") -> 2.3833333 | BC5: =IF(AND(ISNUMBER(BA5),ISNUMBER(BB5)),BB5-BA5,"") -> -87.616667 | BD5: =IF(AND(ISNUMBER(BA5),ISNUMBER(BB5)),IF(BA5>0,(BA5-BB5)/BA5,""),"") -> 0.97351852 | BE5: =IF(S5="","",S5) -> 1 | BF5: =IF(AW5="","",AW5) -> 3 | BG5: =IF(AND(ISNUMBER(BE5),ISNUMBER(BF5)),BF5-BE5,"") -> 2 | BH5: =IF(COUNTA(Z5,AF5,AL5)=0,"",(Z5="Sí")+(AF5="Sí")+(AL5="Sí")) -> 1 | BI5: =IF(COUNTA(AA5,AG5,AM5)=0,"",(AA5="Sí")+(AG5="Sí")+(AM5="Sí")) -> 1 | BJ5: =IF(COUNTA(AB5,AH5,AN5)=0,"",(AB5="Sí")+(AH5="Sí")+(AN5="Sí")) -> 0 | BK5: =IF(COUNT(AO5:AV5)=8,SUM(AO5:AV5),"") -> 18
A6: SA04 | B6: 46307.5 | C6: Aplicador DEMO | D6: 60 a más | E6: Sí | F6: Sí | G6: Trámites documentarios | H6: 1–2 horas | I6: 1 vez | J6: 1 | K6: 1 | L6: 1 | M6: 0 | N6: 0 | O6: 0 | P6: 1 | Q6: 1 | R6: 2 | S6: 1 | T6: =INDEX(Tarjetas!$A$4:$A$59,MOD(3*(VALUE(MID(A6,3,2))-1)+0,ROWS(Tarjetas!$A$4:$A$59))+1) -> S10 | U6: =INDEX(Tarjetas!$A$4:$A$59,MOD(3*(VALUE(MID(A6,3,2))-1)+1,ROWS(Tarjetas!$A$4:$A$59))+1) -> S11 | V6: =INDEX(Tarjetas!$A$4:$A$59,MOD(3*(VALUE(MID(A6,3,2))-1)+2,ROWS(Tarjetas!$A$4:$A$59))+1) -> S12 | W6: [SIMULACIÓN — NO ES TRANSCRIPCIÓN] Acabas de comprar un terreno y te dijeron que hay un impuesto por esa compra; quieres saber de qué trata y cómo se paga. | X6: 180 | Y6: 3 | Z6: No | AA6: Parcial | AB6: No | AC6: [SIMULACIÓN — NO ES TRANSCRIPCIÓN] Debes varios años de impuestos municipales y no puedes pagar todo de golpe; quieres saber si puedes pagarlo poco a poco. | AD6: 180 | AE6: 3 | AF6: No | AG6: Parcial | AH6: No | AI6: [SIMULACIÓN — NO ES TRANSCRIPCIÓN] Te piden un papel que demuestre que no tienes deudas con la municipalidad y quieres saber cómo conseguirlo. | AJ6: 43 | AK6: 3 | AL6: Sí | AM6: Parcial | AN6: No | AO6: 3 | AP6: 2 | AQ6: 3 | AR6: 3 | AS6: 4 | AT6: 4 | AU6: 4 | AV6: 2 | AW6: 4 | AX6: 1–2 horas | AY6: Ninguna | AZ6: =IF(COUNTA(B6,F6)=0,"",IF(AND(F6="Sí",H6<>"",S6<>"",COUNT(X6,AD6,AJ6)=3,COUNT(AO6:AV6)=8,AW6<>""),"Sí","No")) -> Sí | BA6: =IF(H6="","",IFERROR(INDEX(Parametros!$B$4:$B$9,MATCH(H6,Parametros!$A$4:$A$9,0)),"")) -> 90 | BB6: =IF(COUNT(X6,AD6,AJ6)=3,AVERAGE(X6,AD6,AJ6)/60,"") -> 2.2388889 | BC6: =IF(AND(ISNUMBER(BA6),ISNUMBER(BB6)),BB6-BA6,"") -> -87.761111 | BD6: =IF(AND(ISNUMBER(BA6),ISNUMBER(BB6)),IF(BA6>0,(BA6-BB6)/BA6,""),"") -> 0.97512346 | BE6: =IF(S6="","",S6) -> 1 | BF6: =IF(AW6="","",AW6) -> 4 | BG6: =IF(AND(ISNUMBER(BE6),ISNUMBER(BF6)),BF6-BE6,"") -> 3 | BH6: =IF(COUNTA(Z6,AF6,AL6)=0,"",(Z6="Sí")+(AF6="Sí")+(AL6="Sí")) -> 1 | BI6: =IF(COUNTA(AA6,AG6,AM6)=0,"",(AA6="Sí")+(AG6="Sí")+(AM6="Sí")) -> 0 | BJ6: =IF(COUNTA(AB6,AH6,AN6)=0,"",(AB6="Sí")+(AH6="Sí")+(AN6="Sí")) -> 0 | BK6: =IF(COUNT(AO6:AV6)=8,SUM(AO6:AV6),"") -> 25
A7: SA05 | B7: 46307.5 | C7: Aplicador DEMO | D7: 45–59 | E7: Sí | F7: Sí | G7: Tributos y pagos municipales | H7: 30–60 min | I7: 2 a 3 veces | J7: 0 | K7: 0 | L7: 1 | M7: 0 | N7: 0 | O7: 0 | P7: 3 | Q7: 2 | R7: 4 | S7: 3 | T7: =INDEX(Tarjetas!$A$4:$A$59,MOD(3*(VALUE(MID(A7,3,2))-1)+0,ROWS(Tarjetas!$A$4:$A$59))+1) -> S13 | U7: =INDEX(Tarjetas!$A$4:$A$59,MOD(3*(VALUE(MID(A7,3,2))-1)+1,ROWS(Tarjetas!$A$4:$A$59))+1) -> S14 | V7: =INDEX(Tarjetas!$A$4:$A$59,MOD(3*(VALUE(MID(A7,3,2))-1)+2,ROWS(Tarjetas!$A$4:$A$59))+1) -> S15 | W7: [SIMULACIÓN — NO ES TRANSCRIPCIÓN] Quieres entregar una solicitud por escrito en la municipalidad y no sabes qué tienes que llevar. | X7: 180 | Y7: 3 | Z7: No | AA7: Parcial | AB7: No | AC7: [SIMULACIÓN — NO ES TRANSCRIPCIÓN] Dejaste unos papeles en la municipalidad hace semanas y quieres saber cómo va tu trámite. | AD7: 103 | AE7: 2 | AF7: Sí | AG7: Sí | AH7: No | AI7: [SIMULACIÓN — NO ES TRANSCRIPCIÓN] Quieres ir a dejar un documento a la municipalidad y necesitas saber a qué hora y qué días puedes hacerlo. | AJ7: 117 | AK7: 1 | AL7: Sí | AM7: Parcial | AN7: No | AO7: 3 | AP7: 3 | AQ7: 2 | AR7: 4 | AS7: 4 | AT7: 3 | AU7: 4 | AV7: 4 | AW7: 3 | AX7: 30–60 min | AY7: Ninguna | AZ7: =IF(COUNTA(B7,F7)=0,"",IF(AND(F7="Sí",H7<>"",S7<>"",COUNT(X7,AD7,AJ7)=3,COUNT(AO7:AV7)=8,AW7<>""),"Sí","No")) -> Sí | BA7: =IF(H7="","",IFERROR(INDEX(Parametros!$B$4:$B$9,MATCH(H7,Parametros!$A$4:$A$9,0)),"")) -> 45 | BB7: =IF(COUNT(X7,AD7,AJ7)=3,AVERAGE(X7,AD7,AJ7)/60,"") -> 2.2222222 | BC7: =IF(AND(ISNUMBER(BA7),ISNUMBER(BB7)),BB7-BA7,"") -> -42.777778 | BD7: =IF(AND(ISNUMBER(BA7),ISNUMBER(BB7)),IF(BA7>0,(BA7-BB7)/BA7,""),"") -> 0.95061728 | BE7: =IF(S7="","",S7) -> 3 | BF7: =IF(AW7="","",AW7) -> 3 | BG7: =IF(AND(ISNUMBER(BE7),ISNUMBER(BF7)),BF7-BE7,"") -> 0 | BH7: =IF(COUNTA(Z7,AF7,AL7)=0,"",(Z7="Sí")+(AF7="Sí")+(AL7="Sí")) -> 2 | BI7: =IF(COUNTA(AA7,AG7,AM7)=0,"",(AA7="Sí")+(AG7="Sí")+(AM7="Sí")) -> 1 | BJ7: =IF(COUNTA(AB7,AH7,AN7)=0,"",(AB7="Sí")+(AH7="Sí")+(AN7="Sí")) -> 0 | BK7: =IF(COUNT(AO7:AV7)=8,SUM(AO7:AV7),"") -> 27
A8: SA06 | B8: 46307.5 | C8: Aplicador DEMO | D8: 18–29 | E8: Sí | F8: Sí | G8: Registro civil | H8: 15–30 min | I8: 1 vez | J8: 1 | K8: 0 | L8: 0 | M8: 0 | N8: 0 | O8: 0 | P8: 3 | Q8: 2 | R8: 2 | S8: 2 | T8: =INDEX(Tarjetas!$A$4:$A$59,MOD(3*(VALUE(MID(A8,3,2))-1)+0,ROWS(Tarjetas!$A$4:$A$59))+1) -> S16 | U8: =INDEX(Tarjetas!$A$4:$A$59,MOD(3*(VALUE(MID(A8,3,2))-1)+1,ROWS(Tarjetas!$A$4:$A$59))+1) -> S17 | V8: =INDEX(Tarjetas!$A$4:$A$59,MOD(3*(VALUE(MID(A8,3,2))-1)+2,ROWS(Tarjetas!$A$4:$A$59))+1) -> S18 | W8: [SIMULACIÓN — NO ES TRANSCRIPCIÓN] Necesitas una copia sellada de un documento que presentaste antes y ya no la tienes. | X8: 68 | Y8: 3 | Z8: Sí | AA8: Sí | AB8: No | AC8: [SIMULACIÓN — NO ES TRANSCRIPCIÓN] Vives en un terreno que no tiene título y te piden un papel de la municipalidad que diga que tú lo ocupas; quieres saber cómo se consigue. | AD8: 77 | AE8: 2 | AF8: Sí | AG8: Sí | AH8: No | AI8: [SIMULACIÓN — NO ES TRANSCRIPCIÓN] Te piden un documento que pruebe en qué dirección vives y quieres saber cómo sacarlo en la municipalidad. | AJ8: 180 | AK8: 3 | AL8: Sí | AM8: Parcial | AN8: Sí | AO8: 3 | AP8: 2 | AQ8: 4 | AR8: 3 | AS8: 2 | AT8: 4 | AU8: 3 | AV8: 2 | AW8: 3 | AX8: 15–30 min | AY8: Ninguna | AZ8: =IF(COUNTA(B8,F8)=0,"",IF(AND(F8="Sí",H8<>"",S8<>"",COUNT(X8,AD8,AJ8)=3,COUNT(AO8:AV8)=8,AW8<>""),"Sí","No")) -> Sí | BA8: =IF(H8="","",IFERROR(INDEX(Parametros!$B$4:$B$9,MATCH(H8,Parametros!$A$4:$A$9,0)),"")) -> 22.5 | BB8: =IF(COUNT(X8,AD8,AJ8)=3,AVERAGE(X8,AD8,AJ8)/60,"") -> 1.8055556 | BC8: =IF(AND(ISNUMBER(BA8),ISNUMBER(BB8)),BB8-BA8,"") -> -20.694444 | BD8: =IF(AND(ISNUMBER(BA8),ISNUMBER(BB8)),IF(BA8>0,(BA8-BB8)/BA8,""),"") -> 0.91975309 | BE8: =IF(S8="","",S8) -> 2 | BF8: =IF(AW8="","",AW8) -> 3 | BG8: =IF(AND(ISNUMBER(BE8),ISNUMBER(BF8)),BF8-BE8,"") -> 1 | BH8: =IF(COUNTA(Z8,AF8,AL8)=0,"",(Z8="Sí")+(AF8="Sí")+(AL8="Sí")) -> 3 | BI8: =IF(COUNTA(AA8,AG8,AM8)=0,"",(AA8="Sí")+(AG8="Sí")+(AM8="Sí")) -> 2 | BJ8: =IF(COUNTA(AB8,AH8,AN8)=0,"",(AB8="Sí")+(AH8="Sí")+(AN8="Sí")) -> 1 | BK8: =IF(COUNT(AO8:AV8)=8,SUM(AO8:AV8),"") -> 23
A9: SA07 | B9: 46307.5 | C9: Aplicador DEMO | D9: 60 a más | E9: Sí | F9: Sí | G9: Licencias y autorizaciones | H9: Más de 4 horas / varios días | I9: Más de 3 veces | J9: 0 | K9: 0 | L9: 1 | M9: 0 | N9: 0 | O9: 0 | P9: 2 | Q9: 2 | R9: 4 | S9: 3 | T9: =INDEX(Tarjetas!$A$4:$A$59,MOD(3*(VALUE(MID(A9,3,2))-1)+0,ROWS(Tarjetas!$A$4:$A$59))+1) -> S19 | U9: =INDEX(Tarjetas!$A$4:$A$59,MOD(3*(VALUE(MID(A9,3,2))-1)+1,ROWS(Tarjetas!$A$4:$A$59))+1) -> S20 | V9: =INDEX(Tarjetas!$A$4:$A$59,MOD(3*(VALUE(MID(A9,3,2))-1)+2,ROWS(Tarjetas!$A$4:$A$59))+1) -> S21 | W9: [SIMULACIÓN — NO ES TRANSCRIPCIÓN] Tu local necesita un certificado de seguridad para poder funcionar y quieres saber cómo se obtiene. | X9: 62 | Y9: 2 | Z9: Sí | AA9: Sí | AB9: No | AC9: [SIMULACIÓN — NO ES TRANSCRIPCIÓN] Quieres que un inspector vaya a revisar si tu local cumple las medidas de seguridad y quieres saber cómo se pide esa visita. | AD9: 121 | AE9: 1 | AF9: Sí | AG9: Parcial | AH9: No | AI9: [SIMULACIÓN — NO ES TRANSCRIPCIÓN] Vas a pedir la revisión de seguridad de tu local y quieres saber qué cosas debes tener listas (equipos, planos, etc.). | AJ9: 180 | AK9: 3 | AL9: No | AM9: Parcial | AN9: No | AO9: 4 | AP9: 2 | AQ9: 3 | AR9: 2 | AS9: 3 | AT9: 5 | AU9: 3 | AV9: 2 | AW9: 4 | AX9: Más de 4 horas / varios días | AY9: Respuesta lenta (simulada) | AZ9: =IF(COUNTA(B9,F9)=0,"",IF(AND(F9="Sí",H9<>"",S9<>"",COUNT(X9,AD9,AJ9)=3,COUNT(AO9:AV9)=8,AW9<>""),"Sí","No")) -> Sí | BA9: =IF(H9="","",IFERROR(INDEX(Parametros!$B$4:$B$9,MATCH(H9,Parametros!$A$4:$A$9,0)),"")) -> 300 | BB9: =IF(COUNT(X9,AD9,AJ9)=3,AVERAGE(X9,AD9,AJ9)/60,"") -> 2.0166667 | BC9: =IF(AND(ISNUMBER(BA9),ISNUMBER(BB9)),BB9-BA9,"") -> -297.98333 | BD9: =IF(AND(ISNUMBER(BA9),ISNUMBER(BB9)),IF(BA9>0,(BA9-BB9)/BA9,""),"") -> 0.99327778 | BE9: =IF(S9="","",S9) -> 3 | BF9: =IF(AW9="","",AW9) -> 4 | BG9: =IF(AND(ISNUMBER(BE9),ISNUMBER(BF9)),BF9-BE9,"") -> 1 | BH9: =IF(COUNTA(Z9,AF9,AL9)=0,"",(Z9="Sí")+(AF9="Sí")+(AL9="Sí")) -> 2 | BI9: =IF(COUNTA(AA9,AG9,AM9)=0,"",(AA9="Sí")+(AG9="Sí")+(AM9="Sí")) -> 1 | BJ9: =IF(COUNTA(AB9,AH9,AN9)=0,"",(AB9="Sí")+(AH9="Sí")+(AN9="Sí")) -> 0 | BK9: =IF(COUNT(AO9:AV9)=8,SUM(AO9:AV9),"") -> 24
A10: SA08 | B10: 46307.5 | C10: Aplicador DEMO | D10: 30–44 | E10: Sí | F10: Sí | G10: Registro civil | H10: 1–2 horas | I10: 1 vez | J10: 1 | K10: 0 | L10: 1 | M10: 1 | N10: 0 | O10: 0 | P10: 2 | Q10: 3 | R10: 2 | S10: 3 | T10: =INDEX(Tarjetas!$A$4:$A$59,MOD(3*(VALUE(MID(A10,3,2))-1)+0,ROWS(Tarjetas!$A$4:$A$59))+1) -> S22 | U10: =INDEX(Tarjetas!$A$4:$A$59,MOD(3*(VALUE(MID(A10,3,2))-1)+1,ROWS(Tarjetas!$A$4:$A$59))+1) -> S23 | V10: =INDEX(Tarjetas!$A$4:$A$59,MOD(3*(VALUE(MID(A10,3,2))-1)+2,ROWS(Tarjetas!$A$4:$A$59))+1) -> S24 | W10: [SIMULACIÓN — NO ES TRANSCRIPCIÓN] En tu cuadra hay gente sospechosa y quieres avisar a alguien de la municipalidad para que intervenga. | X10: 135 | Y10: 1 | Z10: Sí | AA10: Sí | AB10: No | AC10: [SIMULACIÓN — NO ES TRANSCRIPCIÓN] Necesitas comunicarte con el personal que patrulla el distrito y quieres saber cómo contactarlos. | AD10: 180 | AE10: 3 | AF10: No | AG10: Parcial | AH10: No | AI10: [SIMULACIÓN — NO ES TRANSCRIPCIÓN] Te piden el documento que prueba tu fecha y lugar de nacimiento y no sabes cómo conseguirlo. | AJ10: 103 | AK10: 1 | AL10: Sí | AM10: Parcial | AN10: No | AO10: 5 | AP10: 5 | AQ10: 5 | AR10: 3 | AS10: 4 | AT10: 3 | AU10: 3 | AV10: 4 | AW10: 4 | AX10: 1–2 horas | AY10: Ninguna | AZ10: =IF(COUNTA(B10,F10)=0,"",IF(AND(F10="Sí",H10<>"",S10<>"",COUNT(X10,AD10,AJ10)=3,COUNT(AO10:AV10)=8,AW10<>""),"Sí","No")) -> Sí | BA10: =IF(H10="","",IFERROR(INDEX(Parametros!$B$4:$B$9,MATCH(H10,Parametros!$A$4:$A$9,0)),"")) -> 90 | BB10: =IF(COUNT(X10,AD10,AJ10)=3,AVERAGE(X10,AD10,AJ10)/60,"") -> 2.3222222 | BC10: =IF(AND(ISNUMBER(BA10),ISNUMBER(BB10)),BB10-BA10,"") -> -87.677778 | BD10: =IF(AND(ISNUMBER(BA10),ISNUMBER(BB10)),IF(BA10>0,(BA10-BB10)/BA10,""),"") -> 0.97419753 | BE10: =IF(S10="","",S10) -> 3 | BF10: =IF(AW10="","",AW10) -> 4 | BG10: =IF(AND(ISNUMBER(BE10),ISNUMBER(BF10)),BF10-BE10,"") -> 1 | BH10: =IF(COUNTA(Z10,AF10,AL10)=0,"",(Z10="Sí")+(AF10="Sí")+(AL10="Sí")) -> 2 | BI10: =IF(COUNTA(AA10,AG10,AM10)=0,"",(AA10="Sí")+(AG10="Sí")+(AM10="Sí")) -> 1 | BJ10: =IF(COUNTA(AB10,AH10,AN10)=0,"",(AB10="Sí")+(AH10="Sí")+(AN10="Sí")) -> 0 | BK10: =IF(COUNT(AO10:AV10)=8,SUM(AO10:AV10),"") -> 32
A11: SA09 | B11: 46307.5 | C11: Aplicador DEMO | D11: 18–29 | E11: Sí | F11: Sí | G11: Defensa civil y seguridad ciudadana | H11: 30–60 min | I11: 2 a 3 veces | J11: 1 | K11: 0 | L11: 0 | M11: 0 | N11: 0 | O11: 0 | P11: 4 | Q11: 5 | R11: 4 | S11: 4 | T11: =INDEX(Tarjetas!$A$4:$A$59,MOD(3*(VALUE(MID(A11,3,2))-1)+0,ROWS(Tarjetas!$A$4:$A$59))+1) -> S25 | U11: =INDEX(Tarjetas!$A$4:$A$59,MOD(3*(VALUE(MID(A11,3,2))-1)+1,ROWS(Tarjetas!$A$4:$A$59))+1) -> S26 | V11: =INDEX(Tarjetas!$A$4:$A$59,MOD(3*(VALUE(MID(A11,3,2))-1)+2,ROWS(Tarjetas!$A$4:$A$59))+1) -> S27 | W11: [SIMULACIÓN — NO ES TRANSCRIPCIÓN] Te piden un documento que pruebe que estás casado(a) y no encuentras el original. | X11: 180 | Y11: 3 | Z11: No | AA11: Parcial | AB11: No | AC11: [SIMULACIÓN — NO ES TRANSCRIPCIÓN] Falleció un familiar y necesitas el documento oficial que lo acredite para hacer trámites; quieres saber cómo se consigue. | AD11: 115 | AE11: 2 | AF11: Sí | AG11: Sí | AH11: No | AI11: [SIMULACIÓN — NO ES TRANSCRIPCIÓN] Tu documento de nacimiento tiene tu apellido mal escrito y quieres saber cómo se corrige. | AJ11: 25 | AK11: 1 | AL11: Sí | AM11: Sí | AN11: No | AO11: 4 | AP11: 4 | AQ11: 4 | AR11: 2 | AS11: 3 | AT11: 4 | AU11: 2 | AV11: 3 | AW11: 4 | AX11: 30–60 min | AY11: Error de conexión (simulado) | AZ11: =IF(COUNTA(B11,F11)=0,"",IF(AND(F11="Sí",H11<>"",S11<>"",COUNT(X11,AD11,AJ11)=3,COUNT(AO11:AV11)=8,AW11<>""),"Sí","No")) -> Sí | BA11: =IF(H11="","",IFERROR(INDEX(Parametros!$B$4:$B$9,MATCH(H11,Parametros!$A$4:$A$9,0)),"")) -> 45 | BB11: =IF(COUNT(X11,AD11,AJ11)=3,AVERAGE(X11,AD11,AJ11)/60,"") -> 1.7777778 | BC11: =IF(AND(ISNUMBER(BA11),ISNUMBER(BB11)),BB11-BA11,"") -> -43.222222 | BD11: =IF(AND(ISNUMBER(BA11),ISNUMBER(BB11)),IF(BA11>0,(BA11-BB11)/BA11,""),"") -> 0.96049383 | BE11: =IF(S11="","",S11) -> 4 | BF11: =IF(AW11="","",AW11) -> 4 | BG11: =IF(AND(ISNUMBER(BE11),ISNUMBER(BF11)),BF11-BE11,"") -> 0 | BH11: =IF(COUNTA(Z11,AF11,AL11)=0,"",(Z11="Sí")+(AF11="Sí")+(AL11="Sí")) -> 2 | BI11: =IF(COUNTA(AA11,AG11,AM11)=0,"",(AA11="Sí")+(AG11="Sí")+(AM11="Sí")) -> 2 | BJ11: =IF(COUNTA(AB11,AH11,AN11)=0,"",(AB11="Sí")+(AH11="Sí")+(AN11="Sí")) -> 0 | BK11: =IF(COUNT(AO11:AV11)=8,SUM(AO11:AV11),"") -> 26
A12: SA10 | B12: 46307.5 | C12: Aplicador DEMO | D12: 30–44 | E12: Sí | F12: Sí | G12: Servicios públicos | H12: 1–2 horas | I12: 1 vez | J12: 0 | K12: 0 | L12: 0 | M12: 0 | N12: 1 | O12: 0 | P12: 3 | Q12: 5 | R12: 4 | S12: 3 | T12: =INDEX(Tarjetas!$A$4:$A$59,MOD(3*(VALUE(MID(A12,3,2))-1)+0,ROWS(Tarjetas!$A$4:$A$59))+1) -> S28 | U12: =INDEX(Tarjetas!$A$4:$A$59,MOD(3*(VALUE(MID(A12,3,2))-1)+1,ROWS(Tarjetas!$A$4:$A$59))+1) -> S29 | V12: =INDEX(Tarjetas!$A$4:$A$59,MOD(3*(VALUE(MID(A12,3,2))-1)+2,ROWS(Tarjetas!$A$4:$A$59))+1) -> S30 | W12: [SIMULACIÓN — NO ES TRANSCRIPCIÓN] Tu pareja y tú quieren casarse por lo civil en la municipalidad y quieren saber qué papeles necesitan. | X12: 180 | Y12: 3 | Z12: No | AA12: Parcial | AB12: No | AC12: [SIMULACIÓN — NO ES TRANSCRIPCIÓN] El camión de la basura no pasó hoy por tu calle y quieres saber a qué hora suele pasar. | AD12: 82 | AE12: 1 | AF12: Sí | AG12: Sí | AH12: No | AI12: [SIMULACIÓN — NO ES TRANSCRIPCIÓN] En tu calle un poste no prende de noche y quieres avisar a la municipalidad. | AJ12: 180 | AK12: 3 | AL12: No | AM12: Parcial | AN12: No | AO12: 2 | AP12: 4 | AQ12: 4 | AR12: 2 | AS12: 4 | AT12: 4 | AU12: 3 | AV12: 2 | AW12: 3 | AX12: 1–2 horas | AY12: Ninguna | AZ12: =IF(COUNTA(B12,F12)=0,"",IF(AND(F12="Sí",H12<>"",S12<>"",COUNT(X12,AD12,AJ12)=3,COUNT(AO12:AV12)=8,AW12<>""),"Sí","No")) -> Sí | BA12: =IF(H12="","",IFERROR(INDEX(Parametros!$B$4:$B$9,MATCH(H12,Parametros!$A$4:$A$9,0)),"")) -> 90 | BB12: =IF(COUNT(X12,AD12,AJ12)=3,AVERAGE(X12,AD12,AJ12)/60,"") -> 2.4555556 | BC12: =IF(AND(ISNUMBER(BA12),ISNUMBER(BB12)),BB12-BA12,"") -> -87.544444 | BD12: =IF(AND(ISNUMBER(BA12),ISNUMBER(BB12)),IF(BA12>0,(BA12-BB12)/BA12,""),"") -> 0.97271605 | BE12: =IF(S12="","",S12) -> 3 | BF12: =IF(AW12="","",AW12) -> 3 | BG12: =IF(AND(ISNUMBER(BE12),ISNUMBER(BF12)),BF12-BE12,"") -> 0 | BH12: =IF(COUNTA(Z12,AF12,AL12)=0,"",(Z12="Sí")+(AF12="Sí")+(AL12="Sí")) -> 1 | BI12: =IF(COUNTA(AA12,AG12,AM12)=0,"",(AA12="Sí")+(AG12="Sí")+(AM12="Sí")) -> 1 | BJ12: =IF(COUNTA(AB12,AH12,AN12)=0,"",(AB12="Sí")+(AH12="Sí")+(AN12="Sí")) -> 0 | BK12: =IF(COUNT(AO12:AV12)=8,SUM(AO12:AV12),"") -> 25
A13: SA11 | B13: 46307.5 | C13: Aplicador DEMO | D13: 18–29 | E13: Sí | F13: Sí | G13: Información general / otro | H13: 30–60 min | I13: Ninguna, se resolvió a la primera | J13: 0 | K13: 0 | L13: 0 | M13: 0 | N13: 1 | O13: 0 | P13: 4 | Q13: 4 | R13: 3 | S13: 4 | T13: =INDEX(Tarjetas!$A$4:$A$59,MOD(3*(VALUE(MID(A13,3,2))-1)+0,ROWS(Tarjetas!$A$4:$A$59))+1) -> S31 | U13: =INDEX(Tarjetas!$A$4:$A$59,MOD(3*(VALUE(MID(A13,3,2))-1)+1,ROWS(Tarjetas!$A$4:$A$59))+1) -> S32 | V13: =INDEX(Tarjetas!$A$4:$A$59,MOD(3*(VALUE(MID(A13,3,2))-1)+2,ROWS(Tarjetas!$A$4:$A$59))+1) -> S33 | W13: [SIMULACIÓN — NO ES TRANSCRIPCIÓN] El parque cerca de tu casa está descuidado y con los juegos malogrados; quieres pedir que lo arreglen. | X13: 180 | Y13: 3 | Z13: Sí | AA13: Sí | AB13: Sí | AC13: [SIMULACIÓN — NO ES TRANSCRIPCIÓN] Un árbol de la vereda está tapando el paso y quieres que lo corten o lo recorten. | AD13: 54 | AE13: 2 | AF13: Sí | AG13: Sí | AH13: No | AI13: [SIMULACIÓN — NO ES TRANSCRIPCIÓN] Tu cuadra tiene basura acumulada en la pista y quieres que la limpien. | AJ13: 104 | AK13: 1 | AL13: Sí | AM13: Sí | AN13: No | AO13: 3 | AP13: 4 | AQ13: 3 | AR13: 4 | AS13: 4 | AT13: 4 | AU13: 4 | AV13: 3 | AW13: 4 | AX13: 30–60 min | AY13: Ninguna | AZ13: =IF(COUNTA(B13,F13)=0,"",IF(AND(F13="Sí",H13<>"",S13<>"",COUNT(X13,AD13,AJ13)=3,COUNT(AO13:AV13)=8,AW13<>""),"Sí","No")) -> Sí | BA13: =IF(H13="","",IFERROR(INDEX(Parametros!$B$4:$B$9,MATCH(H13,Parametros!$A$4:$A$9,0)),"")) -> 45 | BB13: =IF(COUNT(X13,AD13,AJ13)=3,AVERAGE(X13,AD13,AJ13)/60,"") -> 1.8777778 | BC13: =IF(AND(ISNUMBER(BA13),ISNUMBER(BB13)),BB13-BA13,"") -> -43.122222 | BD13: =IF(AND(ISNUMBER(BA13),ISNUMBER(BB13)),IF(BA13>0,(BA13-BB13)/BA13,""),"") -> 0.9582716 | BE13: =IF(S13="","",S13) -> 4 | BF13: =IF(AW13="","",AW13) -> 4 | BG13: =IF(AND(ISNUMBER(BE13),ISNUMBER(BF13)),BF13-BE13,"") -> 0 | BH13: =IF(COUNTA(Z13,AF13,AL13)=0,"",(Z13="Sí")+(AF13="Sí")+(AL13="Sí")) -> 3 | BI13: =IF(COUNTA(AA13,AG13,AM13)=0,"",(AA13="Sí")+(AG13="Sí")+(AM13="Sí")) -> 3 | BJ13: =IF(COUNTA(AB13,AH13,AN13)=0,"",(AB13="Sí")+(AH13="Sí")+(AN13="Sí")) -> 1 | BK13: =IF(COUNT(AO13:AV13)=8,SUM(AO13:AV13),"") -> 29
A14: SA12 | B14: 46307.5 | C14: Aplicador DEMO | D14: 18–29 | E14: Sí | F14: Sí | G14: Trámites documentarios | H14: 1–2 horas | I14: 2 a 3 veces | J14: 0 | K14: 1 | L14: 1 | M14: 1 | N14: 0 | O14: 0 | P14: 2 | Q14: 3 | R14: 4 | S14: 2 | T14: =INDEX(Tarjetas!$A$4:$A$59,MOD(3*(VALUE(MID(A14,3,2))-1)+0,ROWS(Tarjetas!$A$4:$A$59))+1) -> S34 | U14: =INDEX(Tarjetas!$A$4:$A$59,MOD(3*(VALUE(MID(A14,3,2))-1)+1,ROWS(Tarjetas!$A$4:$A$59))+1) -> S35 | V14: =INDEX(Tarjetas!$A$4:$A$59,MOD(3*(VALUE(MID(A14,3,2))-1)+2,ROWS(Tarjetas!$A$4:$A$59))+1) -> S36 | W14: [SIMULACIÓN — NO ES TRANSCRIPCIÓN] No estás conforme con cómo te resolvieron un trámite y quieres hacer un reclamo formal. | X14: 107 | Y14: 3 | Z14: Sí | AA14: Parcial | AB14: No | AC14: [SIMULACIÓN — NO ES TRANSCRIPCIÓN] Hiciste un reclamo hace unos días y quieres saber si ya lo respondieron. | AD14: 180 | AE14: 3 | AF14: No | AG14: Parcial | AH14: No | AI14: [SIMULACIÓN — NO ES TRANSCRIPCIÓN] Quieres dejar tu queja en el libro oficial de reclamos y no sabes dónde está ni cómo se usa. | AJ14: 180 | AK14: 3 | AL14: No | AM14: Parcial | AN14: No | AO14: 3 | AP14: 3 | AQ14: 2 | AR14: 4 | AS14: 3 | AT14: 1 | AU14: 2 | AV14: 4 | AW14: 3 | AX14: 1–2 horas | AY14: Ninguna | AZ14: =IF(COUNTA(B14,F14)=0,"",IF(AND(F14="Sí",H14<>"",S14<>"",COUNT(X14,AD14,AJ14)=3,COUNT(AO14:AV14)=8,AW14<>""),"Sí","No")) -> Sí | BA14: =IF(H14="","",IFERROR(INDEX(Parametros!$B$4:$B$9,MATCH(H14,Parametros!$A$4:$A$9,0)),"")) -> 90 | BB14: =IF(COUNT(X14,AD14,AJ14)=3,AVERAGE(X14,AD14,AJ14)/60,"") -> 2.5944444 | BC14: =IF(AND(ISNUMBER(BA14),ISNUMBER(BB14)),BB14-BA14,"") -> -87.405556 | BD14: =IF(AND(ISNUMBER(BA14),ISNUMBER(BB14)),IF(BA14>0,(BA14-BB14)/BA14,""),"") -> 0.97117284 | BE14: =IF(S14="","",S14) -> 2 | BF14: =IF(AW14="","",AW14) -> 3 | BG14: =IF(AND(ISNUMBER(BE14),ISNUMBER(BF14)),BF14-BE14,"") -> 1 | BH14: =IF(COUNTA(Z14,AF14,AL14)=0,"",(Z14="Sí")+(AF14="Sí")+(AL14="Sí")) -> 1 | BI14: =IF(COUNTA(AA14,AG14,AM14)=0,"",(AA14="Sí")+(AG14="Sí")+(AM14="Sí")) -> 0 | BJ14: =IF(COUNTA(AB14,AH14,AN14)=0,"",(AB14="Sí")+(AH14="Sí")+(AN14="Sí")) -> 0 | BK14: =IF(COUNT(AO14:AV14)=8,SUM(AO14:AV14),"") -> 22
... A62: SA60 | B62: 46311.5 | C62: Aplicador DEMO | D62: 18–29 | E62: Sí | F62: Sí | G62: Información general / otro | H62: Menos de 15 min | I62: Ninguna, se resolvió a la primera | J62: 0 | K62: 0 | L62: 0 | M62: 0 | N62: 1 | O62: 0 | P62: 3 | Q62: 3 | R62: 4 | S62: 4 | T62: =INDEX(Tarjetas!$A$4:$A$59,MOD(3*(VALUE(MID(A62,3,2))-1)+0,ROWS(Tarjetas!$A$4:$A$59))+1) -> S10 | U62: =INDEX(Tarjetas!$A$4:$A$59,MOD(3*(VALUE(MID(A62,3,2))-1)+1,ROWS(Tarjetas!$A$4:$A$59))+1) -> S11 | V62: =INDEX(Tarjetas!$A$4:$A$59,MOD(3*(VALUE(MID(A62,3,2))-1)+2,ROWS(Tarjetas!$A$4:$A$59))+1) -> S12 | W62: [SIMULACIÓN — NO ES TRANSCRIPCIÓN] Acabas de comprar un terreno y te dijeron que hay un impuesto por esa compra; quieres saber de qué trata y cómo se paga. | X62: 180 | Y62: 3 | Z62: No | AA62: No | AB62: No | AC62: [SIMULACIÓN — NO ES TRANSCRIPCIÓN] Debes varios años de impuestos municipales y no puedes pagar todo de golpe; quieres saber si puedes pagarlo poco a poco. | AD62: 180 | AE62: 3 | AF62: No | AG62: Parcial | AH62: No | AI62: [SIMULACIÓN — NO ES TRANSCRIPCIÓN] Te piden un papel que demuestre que no tienes deudas con la municipalidad y quieres saber cómo conseguirlo. | AJ62: 51 | AK62: 1 | AL62: Sí | AM62: Sí | AN62: No | AO62: 2 | AP62: 3 | AQ62: 2 | AR62: 4 | AS62: 3 | AT62: 3 | AU62: 4 | AV62: 3 | AW62: 2 | AX62: Menos de 15 min | AY62: Ninguna | AZ62: =IF(COUNTA(B62,F62)=0,"",IF(AND(F62="Sí",H62<>"",S62<>"",COUNT(X62,AD62,AJ62)=3,COUNT(AO62:AV62)=8,AW62<>""),"Sí","No")) -> Sí | BA62: =IF(H62="","",IFERROR(INDEX(Parametros!$B$4:$B$9,MATCH(H62,Parametros!$A$4:$A$9,0)),"")) -> 7.5 | BB62: =IF(COUNT(X62,AD62,AJ62)=3,AVERAGE(X62,AD62,AJ62)/60,"") -> 2.2833333 | BC62: =IF(AND(ISNUMBER(BA62),ISNUMBER(BB62)),BB62-BA62,"") -> -5.2166667 | BD62: =IF(AND(ISNUMBER(BA62),ISNUMBER(BB62)),IF(BA62>0,(BA62-BB62)/BA62,""),"") -> 0.69555556 | BE62: =IF(S62="","",S62) -> 4 | BF62: =IF(AW62="","",AW62) -> 2 | BG62: =IF(AND(ISNUMBER(BE62),ISNUMBER(BF62)),BF62-BE62,"") -> -2 | BH62: =IF(COUNTA(Z62,AF62,AL62)=0,"",(Z62="Sí")+(AF62="Sí")+(AL62="Sí")) -> 1 | BI62: =IF(COUNTA(AA62,AG62,AM62)=0,"",(AA62="Sí")+(AG62="Sí")+(AM62="Sí")) -> 1 | BJ62: =IF(COUNTA(AB62,AH62,AN62)=0,"",(AB62="Sí")+(AH62="Sí")+(AN62="Sí")) -> 0 | BK62: =IF(COUNT(AO62:AV62)=8,SUM(AO62:AV62),"") -> 24
A63: SA61 | T63: =INDEX(Tarjetas!$A$4:$A$59,MOD(3*(VALUE(MID(A63,3,2))-1)+0,ROWS(Tarjetas!$A$4:$A$59))+1) -> S13 | U63: =INDEX(Tarjetas!$A$4:$A$59,MOD(3*(VALUE(MID(A63,3,2))-1)+1,ROWS(Tarjetas!$A$4:$A$59))+1) -> S14 | V63: =INDEX(Tarjetas!$A$4:$A$59,MOD(3*(VALUE(MID(A63,3,2))-1)+2,ROWS(Tarjetas!$A$4:$A$59))+1) -> S15 | AZ63: =IF(COUNTA(B63,F63)=0,"",IF(AND(F63="Sí",H63<>"",S63<>"",COUNT(X63,AD63,AJ63)=3,COUNT(AO63:AV63)=8,AW63<>""),"Sí","No")) | BA63: =IF(H63="","",IFERROR(INDEX(Parametros!$B$4:$B$9,MATCH(H63,Parametros!$A$4:$A$9,0)),"")) | BB63: =IF(COUNT(X63,AD63,AJ63)=3,AVERAGE(X63,AD63,AJ63)/60,"") | BC63: =IF(AND(ISNUMBER(BA63),ISNUMBER(BB63)),BB63-BA63,"") | BD63: =IF(AND(ISNUMBER(BA63),ISNUMBER(BB63)),IF(BA63>0,(BA63-BB63)/BA63,""),"") | BE63: =IF(S63="","",S63) | BF63: =IF(AW63="","",AW63) | BG63: =IF(AND(ISNUMBER(BE63),ISNUMBER(BF63)),BF63-BE63,"") | BH63: =IF(COUNTA(Z63,AF63,AL63)=0,"",(Z63="Sí")+(AF63="Sí")+(AL63="Sí")) | BI63: =IF(COUNTA(AA63,AG63,AM63)=0,"",(AA63="Sí")+(AG63="Sí")+(AM63="Sí")) | BJ63: =IF(COUNTA(AB63,AH63,AN63)=0,"",(AB63="Sí")+(AH63="Sí")+(AN63="Sí")) | BK63: =IF(COUNT(AO63:AV63)=8,SUM(AO63:AV63),"")
A64: SA62 | T64: =INDEX(Tarjetas!$A$4:$A$59,MOD(3*(VALUE(MID(A64,3,2))-1)+0,ROWS(Tarjetas!$A$4:$A$59))+1) -> S16 | U64: =INDEX(Tarjetas!$A$4:$A$59,MOD(3*(VALUE(MID(A64,3,2))-1)+1,ROWS(Tarjetas!$A$4:$A$59))+1) -> S17 | V64: =INDEX(Tarjetas!$A$4:$A$59,MOD(3*(VALUE(MID(A64,3,2))-1)+2,ROWS(Tarjetas!$A$4:$A$59))+1) -> S18 | AZ64: =IF(COUNTA(B64,F64)=0,"",IF(AND(F64="Sí",H64<>"",S64<>"",COUNT(X64,AD64,AJ64)=3,COUNT(AO64:AV64)=8,AW64<>""),"Sí","No")) | BA64: =IF(H64="","",IFERROR(INDEX(Parametros!$B$4:$B$9,MATCH(H64,Parametros!$A$4:$A$9,0)),"")) | BB64: =IF(COUNT(X64,AD64,AJ64)=3,AVERAGE(X64,AD64,AJ64)/60,"") | BC64: =IF(AND(ISNUMBER(BA64),ISNUMBER(BB64)),BB64-BA64,"") | BD64: =IF(AND(ISNUMBER(BA64),ISNUMBER(BB64)),IF(BA64>0,(BA64-BB64)/BA64,""),"") | BE64: =IF(S64="","",S64) | BF64: =IF(AW64="","",AW64) | BG64: =IF(AND(ISNUMBER(BE64),ISNUMBER(BF64)),BF64-BE64,"") | BH64: =IF(COUNTA(Z64,AF64,AL64)=0,"",(Z64="Sí")+(AF64="Sí")+(AL64="Sí")) | BI64: =IF(COUNTA(AA64,AG64,AM64)=0,"",(AA64="Sí")+(AG64="Sí")+(AM64="Sí")) | BJ64: =IF(COUNTA(AB64,AH64,AN64)=0,"",(AB64="Sí")+(AH64="Sí")+(AN64="Sí")) | BK64: =IF(COUNT(AO64:AV64)=8,SUM(AO64:AV64),"")
A65: SA63 | T65: =INDEX(Tarjetas!$A$4:$A$59,MOD(3*(VALUE(MID(A65,3,2))-1)+0,ROWS(Tarjetas!$A$4:$A$59))+1) -> S19 | U65: =INDEX(Tarjetas!$A$4:$A$59,MOD(3*(VALUE(MID(A65,3,2))-1)+1,ROWS(Tarjetas!$A$4:$A$59))+1) -> S20 | V65: =INDEX(Tarjetas!$A$4:$A$59,MOD(3*(VALUE(MID(A65,3,2))-1)+2,ROWS(Tarjetas!$A$4:$A$59))+1) -> S21 | AZ65: =IF(COUNTA(B65,F65)=0,"",IF(AND(F65="Sí",H65<>"",S65<>"",COUNT(X65,AD65,AJ65)=3,COUNT(AO65:AV65)=8,AW65<>""),"Sí","No")) | BA65: =IF(H65="","",IFERROR(INDEX(Parametros!$B$4:$B$9,MATCH(H65,Parametros!$A$4:$A$9,0)),"")) | BB65: =IF(COUNT(X65,AD65,AJ65)=3,AVERAGE(X65,AD65,AJ65)/60,"") | BC65: =IF(AND(ISNUMBER(BA65),ISNUMBER(BB65)),BB65-BA65,"") | BD65: =IF(AND(ISNUMBER(BA65),ISNUMBER(BB65)),IF(BA65>0,(BA65-BB65)/BA65,""),"") | BE65: =IF(S65="","",S65) | BF65: =IF(AW65="","",AW65) | BG65: =IF(AND(ISNUMBER(BE65),ISNUMBER(BF65)),BF65-BE65,"") | BH65: =IF(COUNTA(Z65,AF65,AL65)=0,"",(Z65="Sí")+(AF65="Sí")+(AL65="Sí")) | BI65: =IF(COUNTA(AA65,AG65,AM65)=0,"",(AA65="Sí")+(AG65="Sí")+(AM65="Sí")) | BJ65: =IF(COUNTA(AB65,AH65,AN65)=0,"",(AB65="Sí")+(AH65="Sí")+(AN65="Sí")) | BK65: =IF(COUNT(AO65:AV65)=8,SUM(AO65:AV65),"")
A66: SA64 | T66: =INDEX(Tarjetas!$A$4:$A$59,MOD(3*(VALUE(MID(A66,3,2))-1)+0,ROWS(Tarjetas!$A$4:$A$59))+1) -> S22 | U66: =INDEX(Tarjetas!$A$4:$A$59,MOD(3*(VALUE(MID(A66,3,2))-1)+1,ROWS(Tarjetas!$A$4:$A$59))+1) -> S23 | V66: =INDEX(Tarjetas!$A$4:$A$59,MOD(3*(VALUE(MID(A66,3,2))-1)+2,ROWS(Tarjetas!$A$4:$A$59))+1) -> S24 | AZ66: =IF(COUNTA(B66,F66)=0,"",IF(AND(F66="Sí",H66<>"",S66<>"",COUNT(X66,AD66,AJ66)=3,COUNT(AO66:AV66)=8,AW66<>""),"Sí","No")) | BA66: =IF(H66="","",IFERROR(INDEX(Parametros!$B$4:$B$9,MATCH(H66,Parametros!$A$4:$A$9,0)),"")) | BB66: =IF(COUNT(X66,AD66,AJ66)=3,AVERAGE(X66,AD66,AJ66)/60,"") | BC66: =IF(AND(ISNUMBER(BA66),ISNUMBER(BB66)),BB66-BA66,"") | BD66: =IF(AND(ISNUMBER(BA66),ISNUMBER(BB66)),IF(BA66>0,(BA66-BB66)/BA66,""),"") | BE66: =IF(S66="","",S66) | BF66: =IF(AW66="","",AW66) | BG66: =IF(AND(ISNUMBER(BE66),ISNUMBER(BF66)),BF66-BE66,"") | BH66: =IF(COUNTA(Z66,AF66,AL66)=0,"",(Z66="Sí")+(AF66="Sí")+(AL66="Sí")) | BI66: =IF(COUNTA(AA66,AG66,AM66)=0,"",(AA66="Sí")+(AG66="Sí")+(AM66="Sí")) | BJ66: =IF(COUNTA(AB66,AH66,AN66)=0,"",(AB66="Sí")+(AH66="Sí")+(AN66="Sí")) | BK66: =IF(COUNT(AO66:AV66)=8,SUM(AO66:AV66),"")
A67: SA65 | T67: =INDEX(Tarjetas!$A$4:$A$59,MOD(3*(VALUE(MID(A67,3,2))-1)+0,ROWS(Tarjetas!$A$4:$A$59))+1) -> S25 | U67: =INDEX(Tarjetas!$A$4:$A$59,MOD(3*(VALUE(MID(A67,3,2))-1)+1,ROWS(Tarjetas!$A$4:$A$59))+1) -> S26 | V67: =INDEX(Tarjetas!$A$4:$A$59,MOD(3*(VALUE(MID(A67,3,2))-1)+2,ROWS(Tarjetas!$A$4:$A$59))+1) -> S27 | AZ67: =IF(COUNTA(B67,F67)=0,"",IF(AND(F67="Sí",H67<>"",S67<>"",COUNT(X67,AD67,AJ67)=3,COUNT(AO67:AV67)=8,AW67<>""),"Sí","No")) | BA67: =IF(H67="","",IFERROR(INDEX(Parametros!$B$4:$B$9,MATCH(H67,Parametros!$A$4:$A$9,0)),"")) | BB67: =IF(COUNT(X67,AD67,AJ67)=3,AVERAGE(X67,AD67,AJ67)/60,"") | BC67: =IF(AND(ISNUMBER(BA67),ISNUMBER(BB67)),BB67-BA67,"") | BD67: =IF(AND(ISNUMBER(BA67),ISNUMBER(BB67)),IF(BA67>0,(BA67-BB67)/BA67,""),"") | BE67: =IF(S67="","",S67) | BF67: =IF(AW67="","",AW67) | BG67: =IF(AND(ISNUMBER(BE67),ISNUMBER(BF67)),BF67-BE67,"") | BH67: =IF(COUNTA(Z67,AF67,AL67)=0,"",(Z67="Sí")+(AF67="Sí")+(AL67="Sí")) | BI67: =IF(COUNTA(AA67,AG67,AM67)=0,"",(AA67="Sí")+(AG67="Sí")+(AM67="Sí")) | BJ67: =IF(COUNTA(AB67,AH67,AN67)=0,"",(AB67="Sí")+(AH67="Sí")+(AN67="Sí")) | BK67: =IF(COUNT(AO67:AV67)=8,SUM(AO67:AV67),"")
A68: SA66 | T68: =INDEX(Tarjetas!$A$4:$A$59,MOD(3*(VALUE(MID(A68,3,2))-1)+0,ROWS(Tarjetas!$A$4:$A$59))+1) -> S28 | U68: =INDEX(Tarjetas!$A$4:$A$59,MOD(3*(VALUE(MID(A68,3,2))-1)+1,ROWS(Tarjetas!$A$4:$A$59))+1) -> S29 | V68: =INDEX(Tarjetas!$A$4:$A$59,MOD(3*(VALUE(MID(A68,3,2))-1)+2,ROWS(Tarjetas!$A$4:$A$59))+1) -> S30 | AZ68: =IF(COUNTA(B68,F68)=0,"",IF(AND(F68="Sí",H68<>"",S68<>"",COUNT(X68,AD68,AJ68)=3,COUNT(AO68:AV68)=8,AW68<>""),"Sí","No")) | BA68: =IF(H68="","",IFERROR(INDEX(Parametros!$B$4:$B$9,MATCH(H68,Parametros!$A$4:$A$9,0)),"")) | BB68: =IF(COUNT(X68,AD68,AJ68)=3,AVERAGE(X68,AD68,AJ68)/60,"") | BC68: =IF(AND(ISNUMBER(BA68),ISNUMBER(BB68)),BB68-BA68,"") | BD68: =IF(AND(ISNUMBER(BA68),ISNUMBER(BB68)),IF(BA68>0,(BA68-BB68)/BA68,""),"") | BE68: =IF(S68="","",S68) | BF68: =IF(AW68="","",AW68) | BG68: =IF(AND(ISNUMBER(BE68),ISNUMBER(BF68)),BF68-BE68,"") | BH68: =IF(COUNTA(Z68,AF68,AL68)=0,"",(Z68="Sí")+(AF68="Sí")+(AL68="Sí")) | BI68: =IF(COUNTA(AA68,AG68,AM68)=0,"",(AA68="Sí")+(AG68="Sí")+(AM68="Sí")) | BJ68: =IF(COUNTA(AB68,AH68,AN68)=0,"",(AB68="Sí")+(AH68="Sí")+(AN68="Sí")) | BK68: =IF(COUNT(AO68:AV68)=8,SUM(AO68:AV68),"")
A69: SA67 | T69: =INDEX(Tarjetas!$A$4:$A$59,MOD(3*(VALUE(MID(A69,3,2))-1)+0,ROWS(Tarjetas!$A$4:$A$59))+1) -> S31 | U69: =INDEX(Tarjetas!$A$4:$A$59,MOD(3*(VALUE(MID(A69,3,2))-1)+1,ROWS(Tarjetas!$A$4:$A$59))+1) -> S32 | V69: =INDEX(Tarjetas!$A$4:$A$59,MOD(3*(VALUE(MID(A69,3,2))-1)+2,ROWS(Tarjetas!$A$4:$A$59))+1) -> S33 | AZ69: =IF(COUNTA(B69,F69)=0,"",IF(AND(F69="Sí",H69<>"",S69<>"",COUNT(X69,AD69,AJ69)=3,COUNT(AO69:AV69)=8,AW69<>""),"Sí","No")) | BA69: =IF(H69="","",IFERROR(INDEX(Parametros!$B$4:$B$9,MATCH(H69,Parametros!$A$4:$A$9,0)),"")) | BB69: =IF(COUNT(X69,AD69,AJ69)=3,AVERAGE(X69,AD69,AJ69)/60,"") | BC69: =IF(AND(ISNUMBER(BA69),ISNUMBER(BB69)),BB69-BA69,"") | BD69: =IF(AND(ISNUMBER(BA69),ISNUMBER(BB69)),IF(BA69>0,(BA69-BB69)/BA69,""),"") | BE69: =IF(S69="","",S69) | BF69: =IF(AW69="","",AW69) | BG69: =IF(AND(ISNUMBER(BE69),ISNUMBER(BF69)),BF69-BE69,"") | BH69: =IF(COUNTA(Z69,AF69,AL69)=0,"",(Z69="Sí")+(AF69="Sí")+(AL69="Sí")) | BI69: =IF(COUNTA(AA69,AG69,AM69)=0,"",(AA69="Sí")+(AG69="Sí")+(AM69="Sí")) | BJ69: =IF(COUNTA(AB69,AH69,AN69)=0,"",(AB69="Sí")+(AH69="Sí")+(AN69="Sí")) | BK69: =IF(COUNT(AO69:AV69)=8,SUM(AO69:AV69),"")
A70: SA68 | T70: =INDEX(Tarjetas!$A$4:$A$59,MOD(3*(VALUE(MID(A70,3,2))-1)+0,ROWS(Tarjetas!$A$4:$A$59))+1) -> S34 | U70: =INDEX(Tarjetas!$A$4:$A$59,MOD(3*(VALUE(MID(A70,3,2))-1)+1,ROWS(Tarjetas!$A$4:$A$59))+1) -> S35 | V70: =INDEX(Tarjetas!$A$4:$A$59,MOD(3*(VALUE(MID(A70,3,2))-1)+2,ROWS(Tarjetas!$A$4:$A$59))+1) -> S36 | AZ70: =IF(COUNTA(B70,F70)=0,"",IF(AND(F70="Sí",H70<>"",S70<>"",COUNT(X70,AD70,AJ70)=3,COUNT(AO70:AV70)=8,AW70<>""),"Sí","No")) | BA70: =IF(H70="","",IFERROR(INDEX(Parametros!$B$4:$B$9,MATCH(H70,Parametros!$A$4:$A$9,0)),"")) | BB70: =IF(COUNT(X70,AD70,AJ70)=3,AVERAGE(X70,AD70,AJ70)/60,"") | BC70: =IF(AND(ISNUMBER(BA70),ISNUMBER(BB70)),BB70-BA70,"") | BD70: =IF(AND(ISNUMBER(BA70),ISNUMBER(BB70)),IF(BA70>0,(BA70-BB70)/BA70,""),"") | BE70: =IF(S70="","",S70) | BF70: =IF(AW70="","",AW70) | BG70: =IF(AND(ISNUMBER(BE70),ISNUMBER(BF70)),BF70-BE70,"") | BH70: =IF(COUNTA(Z70,AF70,AL70)=0,"",(Z70="Sí")+(AF70="Sí")+(AL70="Sí")) | BI70: =IF(COUNTA(AA70,AG70,AM70)=0,"",(AA70="Sí")+(AG70="Sí")+(AM70="Sí")) | BJ70: =IF(COUNTA(AB70,AH70,AN70)=0,"",(AB70="Sí")+(AH70="Sí")+(AN70="Sí")) | BK70: =IF(COUNT(AO70:AV70)=8,SUM(AO70:AV70),"")
A71: SA69 | T71: =INDEX(Tarjetas!$A$4:$A$59,MOD(3*(VALUE(MID(A71,3,2))-1)+0,ROWS(Tarjetas!$A$4:$A$59))+1) -> S37 | U71: =INDEX(Tarjetas!$A$4:$A$59,MOD(3*(VALUE(MID(A71,3,2))-1)+1,ROWS(Tarjetas!$A$4:$A$59))+1) -> S38 | V71: =INDEX(Tarjetas!$A$4:$A$59,MOD(3*(VALUE(MID(A71,3,2))-1)+2,ROWS(Tarjetas!$A$4:$A$59))+1) -> S39 | AZ71: =IF(COUNTA(B71,F71)=0,"",IF(AND(F71="Sí",H71<>"",S71<>"",COUNT(X71,AD71,AJ71)=3,COUNT(AO71:AV71)=8,AW71<>""),"Sí","No")) | BA71: =IF(H71="","",IFERROR(INDEX(Parametros!$B$4:$B$9,MATCH(H71,Parametros!$A$4:$A$9,0)),"")) | BB71: =IF(COUNT(X71,AD71,AJ71)=3,AVERAGE(X71,AD71,AJ71)/60,"") | BC71: =IF(AND(ISNUMBER(BA71),ISNUMBER(BB71)),BB71-BA71,"") | BD71: =IF(AND(ISNUMBER(BA71),ISNUMBER(BB71)),IF(BA71>0,(BA71-BB71)/BA71,""),"") | BE71: =IF(S71="","",S71) | BF71: =IF(AW71="","",AW71) | BG71: =IF(AND(ISNUMBER(BE71),ISNUMBER(BF71)),BF71-BE71,"") | BH71: =IF(COUNTA(Z71,AF71,AL71)=0,"",(Z71="Sí")+(AF71="Sí")+(AL71="Sí")) | BI71: =IF(COUNTA(AA71,AG71,AM71)=0,"",(AA71="Sí")+(AG71="Sí")+(AM71="Sí")) | BJ71: =IF(COUNTA(AB71,AH71,AN71)=0,"",(AB71="Sí")+(AH71="Sí")+(AN71="Sí")) | BK71: =IF(COUNT(AO71:AV71)=8,SUM(AO71:AV71),"")
A72: SA70 | T72: =INDEX(Tarjetas!$A$4:$A$59,MOD(3*(VALUE(MID(A72,3,2))-1)+0,ROWS(Tarjetas!$A$4:$A$59))+1) -> S40 | U72: =INDEX(Tarjetas!$A$4:$A$59,MOD(3*(VALUE(MID(A72,3,2))-1)+1,ROWS(Tarjetas!$A$4:$A$59))+1) -> S41 | V72: =INDEX(Tarjetas!$A$4:$A$59,MOD(3*(VALUE(MID(A72,3,2))-1)+2,ROWS(Tarjetas!$A$4:$A$59))+1) -> S42 | AZ72: =IF(COUNTA(B72,F72)=0,"",IF(AND(F72="Sí",H72<>"",S72<>"",COUNT(X72,AD72,AJ72)=3,COUNT(AO72:AV72)=8,AW72<>""),"Sí","No")) | BA72: =IF(H72="","",IFERROR(INDEX(Parametros!$B$4:$B$9,MATCH(H72,Parametros!$A$4:$A$9,0)),"")) | BB72: =IF(COUNT(X72,AD72,AJ72)=3,AVERAGE(X72,AD72,AJ72)/60,"") | BC72: =IF(AND(ISNUMBER(BA72),ISNUMBER(BB72)),BB72-BA72,"") | BD72: =IF(AND(ISNUMBER(BA72),ISNUMBER(BB72)),IF(BA72>0,(BA72-BB72)/BA72,""),"") | BE72: =IF(S72="","",S72) | BF72: =IF(AW72="","",AW72) | BG72: =IF(AND(ISNUMBER(BE72),ISNUMBER(BF72)),BF72-BE72,"") | BH72: =IF(COUNTA(Z72,AF72,AL72)=0,"",(Z72="Sí")+(AF72="Sí")+(AL72="Sí")) | BI72: =IF(COUNTA(AA72,AG72,AM72)=0,"",(AA72="Sí")+(AG72="Sí")+(AM72="Sí")) | BJ72: =IF(COUNTA(AB72,AH72,AN72)=0,"",(AB72="Sí")+(AH72="Sí")+(AN72="Sí")) | BK72: =IF(COUNT(AO72:AV72)=8,SUM(AO72:AV72),"")
A73: SA71 | T73: =INDEX(Tarjetas!$A$4:$A$59,MOD(3*(VALUE(MID(A73,3,2))-1)+0,ROWS(Tarjetas!$A$4:$A$59))+1) -> S43 | U73: =INDEX(Tarjetas!$A$4:$A$59,MOD(3*(VALUE(MID(A73,3,2))-1)+1,ROWS(Tarjetas!$A$4:$A$59))+1) -> S44 | V73: =INDEX(Tarjetas!$A$4:$A$59,MOD(3*(VALUE(MID(A73,3,2))-1)+2,ROWS(Tarjetas!$A$4:$A$59))+1) -> S45 | AZ73: =IF(COUNTA(B73,F73)=0,"",IF(AND(F73="Sí",H73<>"",S73<>"",COUNT(X73,AD73,AJ73)=3,COUNT(AO73:AV73)=8,AW73<>""),"Sí","No")) | BA73: =IF(H73="","",IFERROR(INDEX(Parametros!$B$4:$B$9,MATCH(H73,Parametros!$A$4:$A$9,0)),"")) | BB73: =IF(COUNT(X73,AD73,AJ73)=3,AVERAGE(X73,AD73,AJ73)/60,"") | BC73: =IF(AND(ISNUMBER(BA73),ISNUMBER(BB73)),BB73-BA73,"") | BD73: =IF(AND(ISNUMBER(BA73),ISNUMBER(BB73)),IF(BA73>0,(BA73-BB73)/BA73,""),"") | BE73: =IF(S73="","",S73) | BF73: =IF(AW73="","",AW73) | BG73: =IF(AND(ISNUMBER(BE73),ISNUMBER(BF73)),BF73-BE73,"") | BH73: =IF(COUNTA(Z73,AF73,AL73)=0,"",(Z73="Sí")+(AF73="Sí")+(AL73="Sí")) | BI73: =IF(COUNTA(AA73,AG73,AM73)=0,"",(AA73="Sí")+(AG73="Sí")+(AM73="Sí")) | BJ73: =IF(COUNTA(AB73,AH73,AN73)=0,"",(AB73="Sí")+(AH73="Sí")+(AN73="Sí")) | BK73: =IF(COUNT(AO73:AV73)=8,SUM(AO73:AV73),"")
A74: SA72 | T74: =INDEX(Tarjetas!$A$4:$A$59,MOD(3*(VALUE(MID(A74,3,2))-1)+0,ROWS(Tarjetas!$A$4:$A$59))+1) -> S46 | U74: =INDEX(Tarjetas!$A$4:$A$59,MOD(3*(VALUE(MID(A74,3,2))-1)+1,ROWS(Tarjetas!$A$4:$A$59))+1) -> S47 | V74: =INDEX(Tarjetas!$A$4:$A$59,MOD(3*(VALUE(MID(A74,3,2))-1)+2,ROWS(Tarjetas!$A$4:$A$59))+1) -> S48 | AZ74: =IF(COUNTA(B74,F74)=0,"",IF(AND(F74="Sí",H74<>"",S74<>"",COUNT(X74,AD74,AJ74)=3,COUNT(AO74:AV74)=8,AW74<>""),"Sí","No")) | BA74: =IF(H74="","",IFERROR(INDEX(Parametros!$B$4:$B$9,MATCH(H74,Parametros!$A$4:$A$9,0)),"")) | BB74: =IF(COUNT(X74,AD74,AJ74)=3,AVERAGE(X74,AD74,AJ74)/60,"") | BC74: =IF(AND(ISNUMBER(BA74),ISNUMBER(BB74)),BB74-BA74,"") | BD74: =IF(AND(ISNUMBER(BA74),ISNUMBER(BB74)),IF(BA74>0,(BA74-BB74)/BA74,""),"") | BE74: =IF(S74="","",S74) | BF74: =IF(AW74="","",AW74) | BG74: =IF(AND(ISNUMBER(BE74),ISNUMBER(BF74)),BF74-BE74,"") | BH74: =IF(COUNTA(Z74,AF74,AL74)=0,"",(Z74="Sí")+(AF74="Sí")+(AL74="Sí")) | BI74: =IF(COUNTA(AA74,AG74,AM74)=0,"",(AA74="Sí")+(AG74="Sí")+(AM74="Sí")) | BJ74: =IF(COUNTA(AB74,AH74,AN74)=0,"",(AB74="Sí")+(AH74="Sí")+(AN74="Sí")) | BK74: =IF(COUNT(AO74:AV74)=8,SUM(AO74:AV74),"")
... A77: SA75 | T77: =INDEX(Tarjetas!$A$4:$A$59,MOD(3*(VALUE(MID(A77,3,2))-1)+0,ROWS(Tarjetas!$A$4:$A$59))+1) -> S55 | U77: =INDEX(Tarjetas!$A$4:$A$59,MOD(3*(VALUE(MID(A77,3,2))-1)+1,ROWS(Tarjetas!$A$4:$A$59))+1) -> S56 | V77: =INDEX(Tarjetas!$A$4:$A$59,MOD(3*(VALUE(MID(A77,3,2))-1)+2,ROWS(Tarjetas!$A$4:$A$59))+1) -> S01 | AZ77: =IF(COUNTA(B77,F77)=0,"",IF(AND(F77="Sí",H77<>"",S77<>"",COUNT(X77,AD77,AJ77)=3,COUNT(AO77:AV77)=8,AW77<>""),"Sí","No")) | BA77: =IF(H77="","",IFERROR(INDEX(Parametros!$B$4:$B$9,MATCH(H77,Parametros!$A$4:$A$9,0)),"")) | BB77: =IF(COUNT(X77,AD77,AJ77)=3,AVERAGE(X77,AD77,AJ77)/60,"") | BC77: =IF(AND(ISNUMBER(BA77),ISNUMBER(BB77)),BB77-BA77,"") | BD77: =IF(AND(ISNUMBER(BA77),ISNUMBER(BB77)),IF(BA77>0,(BA77-BB77)/BA77,""),"") | BE77: =IF(S77="","",S77) | BF77: =IF(AW77="","",AW77) | BG77: =IF(AND(ISNUMBER(BE77),ISNUMBER(BF77)),BF77-BE77,"") | BH77: =IF(COUNTA(Z77,AF77,AL77)=0,"",(Z77="Sí")+(AF77="Sí")+(AL77="Sí")) | BI77: =IF(COUNTA(AA77,AG77,AM77)=0,"",(AA77="Sí")+(AG77="Sí")+(AM77="Sí")) | BJ77: =IF(COUNTA(AB77,AH77,AN77)=0,"",(AB77="Sí")+(AH77="Sí")+(AN77="Sí")) | BK77: =IF(COUNT(AO77:AV77)=8,SUM(AO77:AV77),"")
A79: Ejemplo de fila completada (solo muestra el formato; no cuenta en ningún cálculo):
A80: EJ01 | B80: 46307 | C80: Tesista | D80: 30–44 | E80: Sí | F80: Sí | G80: Licencias y autorizaciones | H80: 1–2 horas | I80: 1 vez | J80: 1 | K80: 1 | L80: 0 | M80: 0 | N80: 0 | O80: 0 | P80: 2 | Q80: 2 | R80: 3 | S80: 3 | T80: S01 | U80: S02 | V80: S03 | W80: Qué papeles piden para abrir una tienda | X80: 42 | Y80: 1 | Z80: Sí | AA80: Sí | AB80: No | AC80: Cuánto cuesta el permiso | AD80: 65 | AE80: 2 | AF80: Sí | AG80: Parcial | AH80: No | AI80: En cuánto tiempo me lo dan | AJ80: 180 | AK80: 3 | AL80: No | AM80: No | AN80: Sí | AO80: 4 | AP80: 5 | AQ80: 4 | AR80: 3 | AS80: 4 | AT80: 3 | AU80: 4 | AV80: 4 | AW80: 4 | AX80: 1–2 horas | AY80: Ninguna | AZ80: Sí | BA80: 90 | BB80: 1.6 | BC80: -88.4 | BD80: 0.98228395 | BE80: 3 | BF80: 4 | BG80: 1 | BH80: 2 | BI80: 1 | BJ80: 1 | BK80: 31

Sheet Resumen
A1: Resumen del piloto exploratorio (sesión asistida)
A2: Todo son fórmulas sobre la hoja Sesiones, solo con sesiones elegibles y completas. La prueba de hipótesis (Shapiro-Wilk, luego t pareada o Wilcoxon) se corre con el script de análisis; esta hoja solo resume.
A4: Avance
A5: Sesiones registradas | B5: =COUNTA(Sesiones!$B$3:$B$77) -> 60
A6: Sesiones elegibles y completas | B6: =COUNTIF(Sesiones!$AZ$3:$AZ$77,"Sí") -> 60
A7: No elegibles (sin trámite presencial en 12 meses) | B7: =COUNTIF(Sesiones!$F$3:$F$77,"No") -> 0
A8: Incompletas (elegibles con datos faltantes) | B8: =COUNTIFS(Sesiones!$F$3:$F$77,"Sí",Sesiones!$AZ$3:$AZ$77,"No") -> 0 | C8: Completa los datos faltantes o reemplaza la sesión.
A9: Meta de sesiones | B9: =Parametros!$B$14 -> 60
A10: Faltan | B10: =MAX(0,B9-B6) -> 0
A11: Estado | B11: =IF(B6>=B9,"Meta alcanzada",IF(B6>0,"Parcial (n = "&B6&")","Sin datos")) -> Meta alcanzada | C11: Si no se llega a la meta, el piloto se presenta con el n real y se declara.
A13: Tiempo (OE3) — línea base recordada frente a prueba con el asistente
A14: Tiempo medio presencial (línea base recordada), minutos | B14: =IFERROR(AVERAGEIFS(Sesiones!$BA$3:$BA$77,Sesiones!$AZ$3:$AZ$77,"Sí"),"") -> 100.25 | C14: Punto medio de cada rango (hoja Parametros).
A15: Tiempo medio con el asistente, minutos | B15: =IFERROR(AVERAGEIFS(Sesiones!$BB$3:$BB$77,Sesiones!$AZ$3:$AZ$77,"Sí"),"") -> 1.8719444 | C15: Promedio de las 3 consultas por persona, en minutos.
A16: Reducción del tiempo medio | B16: =IFERROR((B14-B15)/B14,"") -> 0.98132724 | C16: =IF(B16="","","Meta ≥ "&TEXT(Parametros!$B$15,"0%")&": "&IF(B16>=Parametros!$B$15,"cumple","no cumple")) -> Meta ≥ 60%: cumple
A17: Reducción media individual | B17: =IFERROR(AVERAGEIFS(Sesiones!$BD$3:$BD$77,Sesiones!$AZ$3:$AZ$77,"Sí"),"") -> 0.94805833 | C17: Promedio de los porcentajes de cada persona.
A19: Satisfacción (OE4)
A20: Satisfacción previa con la atención presencial (P10), media | B20: =IFERROR(AVERAGEIFS(Sesiones!$BE$3:$BE$77,Sesiones!$AZ$3:$AZ$77,"Sí"),"") -> 2.7833333
A21: Satisfacción con el asistente (ítem 9), media | B21: =IFERROR(AVERAGEIFS(Sesiones!$BF$3:$BF$77,Sesiones!$AZ$3:$AZ$77,"Sí"),"") -> 3.35
A22: Diferencia media (post − pre) | B22: =IFERROR(B21-B20,"") -> 0.56666667
A23: Media de los ítems 1–8 del asistente | B23: =IFERROR(AVERAGEIFS(Sesiones!$BK$3:$BK$77,Sesiones!$AZ$3:$AZ$77,"Sí")/COLUMNS(Calc!$B$3:$I$3),"") -> 3.25 | C23: =IF(B23="","","Meta ≥ "&Parametros!$B$16&": "&IF(B23>=Parametros!$B$16,"cumple","no cumple")) -> Meta ≥ 4: no cumple
A24: Alfa de Cronbach (ítems 1–8) | B24: =IFERROR((COLUMNS(Calc!$B$3:$I$3)/(COLUMNS(Calc!$B$3:$I$3)-1))*(1-(VAR(Calc!B4:B78)+VAR(Calc!C4:C78)+VAR(Calc!D4:D78)+VAR(Calc!E4:E78)+VAR(Calc!F4:F78)+VAR(Calc!G4:G78)+VAR(Calc!H4:H78)+VAR(Calc!I4:I78))/VAR(Calc!$J$4:$J$78)),"") -> 0.54878254 | C24: =IF(B24="","","Mínimo "&Parametros!$B$17&": "&IF(B24>=Parametros!$B$17,"cumple","no cumple")) -> Mínimo 0,7: no cumple
A26: Desempeño del asistente en las consultas
A27: Consultas registradas (sesiones elegibles) | B27: =3*B6 -> 180
A28: Respuesta útil según la persona | B28: =IFERROR(SUMIFS(Sesiones!$BH$3:$BH$77,Sesiones!$AZ$3:$AZ$77,"Sí")/B27,"") -> 0.67777778
A29: Respuesta correcta según el aplicador | B29: =IFERROR(SUMIFS(Sesiones!$BI$3:$BI$77,Sesiones!$AZ$3:$AZ$77,"Sí")/B27,"") -> 0.51666667 | C29: «Sí» solamente; las «Parcial» no se cuentan.
A30: Consultas con «no entendí» | B30: =IFERROR(SUMIFS(Sesiones!$BJ$3:$BJ$77,Sesiones!$AZ$3:$AZ$77,"Sí")/B27,"") -> 0.15555556
A31: Mensajes promedio por consulta | B31: =IFERROR((SUMIFS(Sesiones!$Y$3:$Y$77,Sesiones!$AZ$3:$AZ$77,"Sí")+SUMIFS(Sesiones!$AE$3:$AE$77,Sesiones!$AZ$3:$AZ$77,"Sí")+SUMIFS(Sesiones!$AK$3:$AK$77,Sesiones!$AZ$3:$AZ$77,"Sí"))/B27,"") -> 2.1555556
A32: Mínimo de consultas por tarjeta | B32: =MIN(Tarjetas!$D$4:$D$59) -> 3 | C32: Con 60 sesiones elegibles cada tarjeta debería tener 3 o más.

Sheet Tarjetas
A1: Tarjetas de situación (catálogo)
A2: Las 56 situaciones del catálogo situaciones_lote1_v1.csv y la intención esperada de cada una. Cada código de sesión recibe 3 tarjetas fijas (hoja Sesiones, columnas Tarjeta 1–3). La columna D cuenta las consultas ya registradas de sesiones elegibles.
A3: Tarjeta | B3: Intención esperada | C3: Texto de la situación | D3: Consultas registradas (sesiones elegibles)
A4: S01 | B4: licencia_funcionamiento_requisitos | C4: Vas a abrir una tiendita en tu barrio y no sabes qué papeles te van a pedir en la municipalidad para poder atender legalmente. | D4: =COUNTIFS(Sesiones!$T$3:$T$77,A4,Sesiones!$AZ$3:$AZ$77,"Sí")+COUNTIFS(Sesiones!$U$3:$U$77,A4,Sesiones!$AZ$3:$AZ$77,"Sí")+COUNTIFS(Sesiones!$V$3:$V$77,A4,Sesiones!$AZ$3:$AZ$77,"Sí") -> 4
A5: S02 | B5: licencia_funcionamiento_costo | C5: Ya sabes que necesitas un permiso de la municipalidad para tu negocio y quieres saber cuánto tendrías que pagar por él. | D5: =COUNTIFS(Sesiones!$T$3:$T$77,A5,Sesiones!$AZ$3:$AZ$77,"Sí")+COUNTIFS(Sesiones!$U$3:$U$77,A5,Sesiones!$AZ$3:$AZ$77,"Sí")+COUNTIFS(Sesiones!$V$3:$V$77,A5,Sesiones!$AZ$3:$AZ$77,"Sí") -> 4
A6: S03 | B6: licencia_funcionamiento_plazo | C6: Entregaste tus papeles para el permiso de tu negocio y quieres saber cuántos días demoran en dártelo. | D6: =COUNTIFS(Sesiones!$T$3:$T$77,A6,Sesiones!$AZ$3:$AZ$77,"Sí")+COUNTIFS(Sesiones!$U$3:$U$77,A6,Sesiones!$AZ$3:$AZ$77,"Sí")+COUNTIFS(Sesiones!$V$3:$V$77,A6,Sesiones!$AZ$3:$AZ$77,"Sí") -> 4
A7: S04 | B7: licencia_edificacion_requisitos | C7: Quieres construir un segundo piso en tu casa y quieres saber qué documentos tendrías que presentar antes de empezar la obra. | D7: =COUNTIFS(Sesiones!$T$3:$T$77,A7,Sesiones!$AZ$3:$AZ$77,"Sí")+COUNTIFS(Sesiones!$U$3:$U$77,A7,Sesiones!$AZ$3:$AZ$77,"Sí")+COUNTIFS(Sesiones!$V$3:$V$77,A7,Sesiones!$AZ$3:$AZ$77,"Sí") -> 4
A8: S05 | B8: licencia_edificacion_costo | C8: Vas a construir en tu terreno y quieres saber cuánto cobra la municipalidad por autorizar la obra. | D8: =COUNTIFS(Sesiones!$T$3:$T$77,A8,Sesiones!$AZ$3:$AZ$77,"Sí")+COUNTIFS(Sesiones!$U$3:$U$77,A8,Sesiones!$AZ$3:$AZ$77,"Sí")+COUNTIFS(Sesiones!$V$3:$V$77,A8,Sesiones!$AZ$3:$AZ$77,"Sí") -> 4
A9: S06 | B9: renovacion_licencia | C9: El permiso de funcionamiento de tu negocio ya se venció y quieres saber qué tienes que hacer para dejarlo vigente otra vez. | D9: =COUNTIFS(Sesiones!$T$3:$T$77,A9,Sesiones!$AZ$3:$AZ$77,"Sí")+COUNTIFS(Sesiones!$U$3:$U$77,A9,Sesiones!$AZ$3:$AZ$77,"Sí")+COUNTIFS(Sesiones!$V$3:$V$77,A9,Sesiones!$AZ$3:$AZ$77,"Sí") -> 4
A10: S07 | B10: consulta_deuda_predial | C10: Quieres saber si debes impuestos por tu casa o terreno, y cuánto sería. | D10: =COUNTIFS(Sesiones!$T$3:$T$77,A10,Sesiones!$AZ$3:$AZ$77,"Sí")+COUNTIFS(Sesiones!$U$3:$U$77,A10,Sesiones!$AZ$3:$AZ$77,"Sí")+COUNTIFS(Sesiones!$V$3:$V$77,A10,Sesiones!$AZ$3:$AZ$77,"Sí") -> 4
A11: S08 | B11: pago_predial_como | C11: Ya sabes que debes pagar el impuesto de tu casa y quieres saber dónde o de qué forma puedes hacerlo. | D11: =COUNTIFS(Sesiones!$T$3:$T$77,A11,Sesiones!$AZ$3:$AZ$77,"Sí")+COUNTIFS(Sesiones!$U$3:$U$77,A11,Sesiones!$AZ$3:$AZ$77,"Sí")+COUNTIFS(Sesiones!$V$3:$V$77,A11,Sesiones!$AZ$3:$AZ$77,"Sí") -> 4
A12: S09 | B12: pago_arbitrios | C12: Te llegó un cobro por el recojo de basura, la limpieza de calles y el serenazgo, y quieres saber cómo pagarlo. | D12: =COUNTIFS(Sesiones!$T$3:$T$77,A12,Sesiones!$AZ$3:$AZ$77,"Sí")+COUNTIFS(Sesiones!$U$3:$U$77,A12,Sesiones!$AZ$3:$AZ$77,"Sí")+COUNTIFS(Sesiones!$V$3:$V$77,A12,Sesiones!$AZ$3:$AZ$77,"Sí") -> 4
A13: S10 | B13: impuesto_alcabala | C13: Acabas de comprar un terreno y te dijeron que hay un impuesto por esa compra; quieres saber de qué trata y cómo se paga. | D13: =COUNTIFS(Sesiones!$T$3:$T$77,A13,Sesiones!$AZ$3:$AZ$77,"Sí")+COUNTIFS(Sesiones!$U$3:$U$77,A13,Sesiones!$AZ$3:$AZ$77,"Sí")+COUNTIFS(Sesiones!$V$3:$V$77,A13,Sesiones!$AZ$3:$AZ$77,"Sí") -> 4
A14: S11 | B14: fraccionamiento_deuda | C14: Debes varios años de impuestos municipales y no puedes pagar todo de golpe; quieres saber si puedes pagarlo poco a poco. | D14: =COUNTIFS(Sesiones!$T$3:$T$77,A14,Sesiones!$AZ$3:$AZ$77,"Sí")+COUNTIFS(Sesiones!$U$3:$U$77,A14,Sesiones!$AZ$3:$AZ$77,"Sí")+COUNTIFS(Sesiones!$V$3:$V$77,A14,Sesiones!$AZ$3:$AZ$77,"Sí") -> 4
A15: S12 | B15: constancia_no_adeudo | C15: Te piden un papel que demuestre que no tienes deudas con la municipalidad y quieres saber cómo conseguirlo. | D15: =COUNTIFS(Sesiones!$T$3:$T$77,A15,Sesiones!$AZ$3:$AZ$77,"Sí")+COUNTIFS(Sesiones!$U$3:$U$77,A15,Sesiones!$AZ$3:$AZ$77,"Sí")+COUNTIFS(Sesiones!$V$3:$V$77,A15,Sesiones!$AZ$3:$AZ$77,"Sí") -> 4
... A59: S56 | B59: repetir_informacion | C59: El asistente te dio una información pero no alcanzaste a leerla ni a anotarla. ¿Cómo le pedirías que te la repita? | D59: =COUNTIFS(Sesiones!$T$3:$T$77,A59,Sesiones!$AZ$3:$AZ$77,"Sí")+COUNTIFS(Sesiones!$U$3:$U$77,A59,Sesiones!$AZ$3:$AZ$77,"Sí")+COUNTIFS(Sesiones!$V$3:$V$77,A59,Sesiones!$AZ$3:$AZ$77,"Sí") -> 3

Sheet Parametros
A1: Parámetros y listas
A2: Celdas amarillas = valores editables. Las listas alimentan los menús desplegables de Sesiones.
A3: Rango de tiempo (línea base) | B3: Minutos (punto medio) | F3: Rango de edad | G3: Sí / No | H3: Categoría del trámite | I3: Veces que volvió | J3: ¿Correcta?
A4: Menos de 15 min | B4: 7.5 | F4: 18–29 | G4: Sí | H4: Licencias y autorizaciones | I4: Ninguna, se resolvió a la primera | J4: Sí
A5: 15–30 min | B5: 22.5 | F5: 30–44 | G5: No | H5: Tributos y pagos municipales | I5: 1 vez | J5: Parcial
A6: 30–60 min | B6: 45 | F6: 45–59 | H6: Trámites documentarios | I6: 2 a 3 veces | J6: No
A7: 1–2 horas | B7: 90 | F7: 60 a más | H7: Defensa civil y seguridad ciudadana | I7: Más de 3 veces
A8: 2–4 horas | B8: 180 | H8: Registro civil
A9: Más de 4 horas / varios días | B9: 300 | H9: Servicios públicos
A10: Supuesto: se usa el punto medio de cada rango; para «Más de 4 horas / varios días» se asume 300 min (5 h). Es un supuesto editable. | H10: Reclamos y quejas
H11: Información general / otro
A13: Parámetro | B13: Valor | C13: Fuente / criterio
A14: Meta de sesiones elegibles y completas | B14: 60 | C14: Decisión del tesista: piloto exploratorio de n = 60 (reduce los 120 del protocolo V1.2).
A15: Meta de reducción del tiempo | B15: 0.6 | C15: Hipótesis de la tesis: reducción ≥ 60 %.
A16: Meta de satisfacción (Likert 1–5) | B16: 4 | C16: Hipótesis de la tesis: Likert ≥ 4.0 sobre 5.
A17: Alfa de Cronbach mínimo | B17: 0.7 | C17: Criterio del pre-piloto formal del protocolo V1.2.
A18: Tope de tiempo por consulta (segundos) | B18: 180 | C18: Regla de la guía de aplicación: se corta a los 180 s sin respuesta útil. Solo informativo.
A19: Máximo de mensajes por consulta | B19: 3 | C19: Regla de la guía de aplicación. Solo informativo.
A20: Modelo congelado (nombre / versión) | C20: Anótalo antes de la primera sesión; no se cambia durante las sesiones.
A21: Fecha de congelamiento del modelo | C21: Anótala junto con la versión.

Sheet Calc
A1: Cálculo auxiliar del alfa de Cronbach
A2: Solo fórmulas. Copia los ítems 1–8 de las sesiones elegibles y completas; las demás filas quedan vacías para no distorsionar la varianza.
A3: Código | B3: Ítem 1 | C3: Ítem 2 | D3: Ítem 3 | E3: Ítem 4 | F3: Ítem 5 | G3: Ítem 6 | H3: Ítem 7 | I3: Ítem 8 | J3: Total
A4: =Sesiones!A3 -> SA01 | B4: =IF(Sesiones!AZ3="Sí",Sesiones!AO3,"") -> 3 | C4: =IF(Sesiones!AZ3="Sí",Sesiones!AP3,"") -> 4 | D4: =IF(Sesiones!AZ3="Sí",Sesiones!AQ3,"") -> 3 | E4: =IF(Sesiones!AZ3="Sí",Sesiones!AR3,"") -> 3 | F4: =IF(Sesiones!AZ3="Sí",Sesiones!AS3,"") -> 4 | G4: =IF(Sesiones!AZ3="Sí",Sesiones!AT3,"") -> 4 | H4: =IF(Sesiones!AZ3="Sí",Sesiones!AU3,"") -> 4 | I4: =IF(Sesiones!AZ3="Sí",Sesiones!AV3,"") -> 4 | J4: =IF(Sesiones!AZ3="Sí",Sesiones!BK3,"") -> 29
A5: =Sesiones!A4 -> SA02 | B5: =IF(Sesiones!AZ4="Sí",Sesiones!AO4,"") -> 3 | C5: =IF(Sesiones!AZ4="Sí",Sesiones!AP4,"") -> 3 | D5: =IF(Sesiones!AZ4="Sí",Sesiones!AQ4,"") -> 5 | E5: =IF(Sesiones!AZ4="Sí",Sesiones!AR4,"") -> 4 | F5: =IF(Sesiones!AZ4="Sí",Sesiones!AS4,"") -> 4 | G5: =IF(Sesiones!AZ4="Sí",Sesiones!AT4,"") -> 3 | H5: =IF(Sesiones!AZ4="Sí",Sesiones!AU4,"") -> 4 | I5: =IF(Sesiones!AZ4="Sí",Sesiones!AV4,"") -> 3 | J5: =IF(Sesiones!AZ4="Sí",Sesiones!BK4,"") -> 29
A6: =Sesiones!A5 -> SA03 | B6: =IF(Sesiones!AZ5="Sí",Sesiones!AO5,"") -> 1 | C6: =IF(Sesiones!AZ5="Sí",Sesiones!AP5,"") -> 4 | D6: =IF(Sesiones!AZ5="Sí",Sesiones!AQ5,"") -> 3 | E6: =IF(Sesiones!AZ5="Sí",Sesiones!AR5,"") -> 1 | F6: =IF(Sesiones!AZ5="Sí",Sesiones!AS5,"") -> 2 | G6: =IF(Sesiones!AZ5="Sí",Sesiones!AT5,"") -> 3 | H6: =IF(Sesiones!AZ5="Sí",Sesiones!AU5,"") -> 2 | I6: =IF(Sesiones!AZ5="Sí",Sesiones!AV5,"") -> 2 | J6: =IF(Sesiones!AZ5="Sí",Sesiones!BK5,"") -> 18
A7: =Sesiones!A6 -> SA04 | B7: =IF(Sesiones!AZ6="Sí",Sesiones!AO6,"") -> 3 | C7: =IF(Sesiones!AZ6="Sí",Sesiones!AP6,"") -> 2 | D7: =IF(Sesiones!AZ6="Sí",Sesiones!AQ6,"") -> 3 | E7: =IF(Sesiones!AZ6="Sí",Sesiones!AR6,"") -> 3 | F7: =IF(Sesiones!AZ6="Sí",Sesiones!AS6,"") -> 4 | G7: =IF(Sesiones!AZ6="Sí",Sesiones!AT6,"") -> 4 | H7: =IF(Sesiones!AZ6="Sí",Sesiones!AU6,"") -> 4 | I7: =IF(Sesiones!AZ6="Sí",Sesiones!AV6,"") -> 2 | J7: =IF(Sesiones!AZ6="Sí",Sesiones!BK6,"") -> 25
A8: =Sesiones!A7 -> SA05 | B8: =IF(Sesiones!AZ7="Sí",Sesiones!AO7,"") -> 3 | C8: =IF(Sesiones!AZ7="Sí",Sesiones!AP7,"") -> 3 | D8: =IF(Sesiones!AZ7="Sí",Sesiones!AQ7,"") -> 2 | E8: =IF(Sesiones!AZ7="Sí",Sesiones!AR7,"") -> 4 | F8: =IF(Sesiones!AZ7="Sí",Sesiones!AS7,"") -> 4 | G8: =IF(Sesiones!AZ7="Sí",Sesiones!AT7,"") -> 3 | H8: =IF(Sesiones!AZ7="Sí",Sesiones!AU7,"") -> 4 | I8: =IF(Sesiones!AZ7="Sí",Sesiones!AV7,"") -> 4 | J8: =IF(Sesiones!AZ7="Sí",Sesiones!BK7,"") -> 27
